ts_recv,ts_event,rtype,publisher_id,instrument_id,action,side,depth,price,size,flags,ts_in_delta,sequence,bid_px_00,ask_px_00,bid_sz_00,ask_sz_00,bid_ct_00,ask_ct_00,bid_px_01,ask_px_01,bid_sz_01,ask_sz_01,bid_ct_01,ask_ct_01,bid_px_02,ask_px_02,bid_sz_02,ask_sz_02,bid_ct_02,ask_ct_02,bid_px_03,ask_px_03,bid_sz_03,ask_sz_03,bid_ct_03,ask_ct_03,bid_px_04,ask_px_04,bid_sz_04,ask_sz_04,bid_ct_04,ask_ct_04,bid_px_05,ask_px_05,bid_sz_05,ask_sz_05,bid_ct_05,ask_ct_05,bid_px_06,ask_px_06,bid_sz_06,ask_sz_06,bid_ct_06,ask_ct_06,bid_px_07,ask_px_07,bid_sz_07,ask_sz_07,bid_ct_07,ask_ct_07,bid_px_08,ask_px_08,bid_sz_08,ask_sz_08,bid_ct_08,ask_ct_08,bid_px_09,ask_px_09,bid_sz_09,ask_sz_09,bid_ct_09,ask_ct_09,symbol
2024-10-21T12:26:32.717638955Z,2024-10-21T12:26:32.717472823Z,10,2,38,C,B,3,233.78,200,130,166132,13137150,233.86,233.95,100,131,1,2,233.81,234,2,17,2,2,233.8,234.01,105,200,2,1,233.7,234.1,1200,100,1,1,233.66,234.13,1,400,1,1,233.58,234.17,505,1,2,1,233.53,234.25,10,100,1,1,233.5,234.41,100,500,1,1,233.45,234.43,15,105,1,2,233.4,234.5,110,63,2,4,GOOG
2024-10-21T12:26:32.721694410Z,2024-10-21T12:26:32.721528057Z,10,2,38,C,A,0,233.95,10,130,166353,13137153,233.86,233.95,100,121,1,1,233.81,234,2,17,2,2,233.8,234.01,105,200,2,1,233.7,234.1,1200,100,1,1,233.66,234.13,1,400,1,1,233.58,234.17,505,1,2,1,233.53,234.25,10,100,1,1,233.5,234.41,100,500,1,1,233.45,234.43,15,105,1,2,233.4,234.5,110,63,2,4,GOOG
2024-10-21T12:26:32.820850700Z,2024-10-21T12:26:32.820683999Z,10,2,38,A,B,3,233.78,200,130,166701,13137257,233.86,233.95,100,121,1,1,233.81,234,2,17,2,2,233.8,234.01,105,200,2,1,233.78,234.1,200,100,1,1,233.7,234.13,1200,400,1,1,233.66,234.17,1,1,1,1,233.58,234.25,505,100,2,1,233.53,234.41,10,500,1,1,233.5,234.43,100,105,1,2,233.45,234.5,15,63,1,4,GOOG
2024-10-21T12:26:33.596226968Z,2024-10-21T12:26:33.596060481Z,10,2,38,A,A,7,234.41,7,130,166487,13137944,233.86,233.95,100,121,1,1,233.81,234,2,17,2,2,233.8,234.01,105,200,2,1,233.78,234.1,200,100,1,1,233.7,234.13,1200,400,1,1,233.66,234.17,1,1,1,1,233.58,234.25,505,100,2,1,233.53,234.41,10,507,1,2,233.5,234.43,100,105,1,2,233.45,234.5,15,63,1,4,GOOG
2024-10-21T12:26:33.705462618Z,2024-10-21T12:26:33.705296257Z,10,2,38,C,B,3,233.78,200,130,166361,13138040,233.86,233.95,100,121,1,1,233.81,234,2,17,2,2,233.8,234.01,105,200,2,1,233.7,234.1,1200,100,1,1,233.66,234.13,1,400,1,1,233.58,234.17,505,1,2,1,233.53,234.25,10,100,1,1,233.5,234.41,100,507,1,2,233.45,234.43,15,105,1,2,233.4,234.5,110,63,2,4,GOOG
2024-10-21T12:26:33.705475821Z,2024-10-21T12:26:33.705309399Z,10,2,38,A,B,3,233.73,400,130,166422,13138041,233.86,233.95,100,121,1,1,233.81,234,2,17,2,2,233.8,234.01,105,200,2,1,233.73,234.1,400,100,1,1,233.7,234.13,1200,400,1,1,233.66,234.17,1,1,1,1,233.58,234.25,505,100,2,1,233.53,234.41,10,507,1,2,233.5,234.43,100,105,1,2,233.45,234.5,15,63,1,4,GOOG
2024-10-21T12:26:40.656300037Z,2024-10-21T12:26:40.656134264Z,10,2,38,C,A,2,234.01,200,130,165773,13145962,233.86,233.95,100,121,1,1,233.81,234,2,17,2,2,233.8,234.1,105,100,2,1,233.73,234.13,400,400,1,1,233.7,234.17,1200,1,1,1,233.66,234.25,1,100,1,1,233.58,234.41,505,507,2,2,233.53,234.43,10,105,1,2,233.5,234.5,100,63,1,4,233.45,234.59,15,60,1,1,GOOG
2024-10-21T12:26:40.656313085Z,2024-10-21T12:26:40.656147028Z,10,2,38,A,A,2,234.03,400,130,166057,13145963,233.86,233.95,100,121,1,1,233.81,234,2,17,2,2,233.8,234.03,105,400,2,1,233.73,234.1,400,100,1,1,233.7,234.13,1200,400,1,1,233.66,234.17,1,1,1,1,233.58,234.25,505,100,2,1,233.53,234.41,10,507,1,2,233.5,234.43,100,105,1,2,233.45,234.5,15,63,1,4,GOOG
2024-10-21T12:26:40.707673608Z,2024-10-21T12:26:40.707506986Z,10,2,38,A,B,3,233.74,400,130,166622,13146198,233.86,233.95,100,121,1,1,233.81,234,2,17,2,2,233.8,234.03,105,400,2,1,233.74,234.1,400,100,1,1,233.7,234.13,1200,400,1,1,233.66,234.17,1,1,1,1,233.58,234.25,505,100,2,1,233.53,234.41,10,507,1,2,233.5,234.43,100,105,1,2,233.45,234.5,15,63,1,4,GOOG
2024-10-21T12:26:40.896702274Z,2024-10-21T12:26:40.896535785Z,10,2,38,A,A,2,234.02,400,130,166489,13146521,233.86,233.95,100,121,1,1,233.81,234,2,17,2,2,233.8,234.02,105,400,2,1,233.74,234.1,400,100,1,1,233.7,234.13,1200,400,1,1,233.66,234.17,1,1,1,1,233.58,234.25,505,100,2,1,233.53,234.41,10,507,1,2,233.5,234.43,100,105,1,2,233.45,234.5,15,63,1,4,GOOG
2024-10-21T12:26:42.392700431Z,2024-10-21T12:26:42.392534365Z,10,2,38,C,A,7,234.41,7,130,166066,13148175,233.86,233.95,100,121,1,1,233.81,234,2,17,2,2,233.8,234.02,105,400,2,1,233.74,234.1,400,100,1,1,233.7,234.13,1200,400,1,1,233.66,234.17,1,1,1,1,233.58,234.25,505,100,2,1,233.53,234.41,10,500,1,1,233.5,234.43,100,105,1,2,233.45,234.5,15,63,1,4,GOOG
2024-10-21T12:26:43.555781301Z,2024-10-21T12:26:43.555613825Z,10,2,38,T,A,0,233.86,100,130,167476,13148963,233.86,233.95,100,121,1,1,233.81,234,2,17,2,2,233.8,234.02,105,400,2,1,233.74,234.1,400,100,1,1,233.7,234.13,1200,400,1,1,233.66,234.17,1,1,1,1,233.58,234.25,505,100,2,1,233.53,234.41,10,500,1,1,233.5,234.43,100,105,1,2,233.45,234.5,15,63,1,4,GOOG
2024-10-21T12:26:43.555781301Z,2024-10-21T12:26:43.555613825Z,10,2,38,C,B,0,233.86,100,130,167476,13148963,233.81,233.95,2,121,2,1,233.8,234,105,17,2,2,233.74,234.02,400,400,1,1,233.7,234.1,1200,100,1,1,233.66,234.13,1,400,1,1,233.58,234.17,505,1,2,1,233.53,234.25,10,100,1,1,233.5,234.41,100,500,1,1,233.45,234.43,15,105,1,2,233.4,234.5,110,63,2,4,GOOG
2024-10-21T12:26:43.555792717Z,2024-10-21T12:26:43.555625145Z,10,2,38,A,B,0,233.86,100,130,167572,13148964,233.86,233.95,100,121,1,1,233.81,234,2,17,2,2,233.8,234.02,105,400,2,1,233.74,234.1,400,100,1,1,233.7,234.13,1200,400,1,1,233.66,234.17,1,1,1,1,233.58,234.25,505,100,2,1,233.53,234.41,10,500,1,1,233.5,234.43,100,105,1,2,233.45,234.5,15,63,1,4,GOOG
2024-10-21T12:26:43.555803052Z,2024-10-21T12:26:43.555636531Z,10,2,38,A,A,0,233.9,100,130,166521,13148965,233.86,233.9,100,100,1,1,233.81,233.95,2,121,2,1,233.8,234,105,17,2,2,233.74,234.02,400,400,1,1,233.7,234.1,1200,100,1,1,233.66,234.13,1,400,1,1,233.58,234.17,505,1,2,1,233.53,234.25,10,100,1,1,233.5,234.41,100,500,1,1,233.45,234.43,15,105,1,2,GOOG
2024-10-21T12:26:43.555807607Z,2024-10-21T12:26:43.555641373Z,10,2,38,A,A,1,233.91,200,130,166234,13148967,233.86,233.9,100,100,1,1,233.81,233.91,2,200,2,1,233.8,233.93,105,100,2,1,233.74,233.95,400,121,1,1,233.7,234,1200,17,1,2,233.66,234.02,1,400,1,1,233.58,234.1,505,100,2,1,233.53,234.13,10,400,1,1,233.5,234.17,100,1,1,1,233.45,234.25,15,100,1,1,GOOG
2024-10-21T12:26:43.555814614Z,2024-10-21T12:26:43.555648065Z,10,2,38,A,A,2,233.93,100,130,166549,13148968,233.86,233.9,100,100,1,1,233.81,233.91,2,200,2,1,233.8,233.93,105,200,2,2,233.74,233.95,400,121,1,1,233.7,234,1200,17,1,2,233.66,234.02,1,400,1,1,233.58,234.1,505,100,2,1,233.53,234.13,10,400,1,1,233.5,234.17,100,1,1,1,233.45,234.25,15,100,1,1,GOOG
2024-10-21T12:26:43.555816268Z,2024-10-21T12:26:43.555650058Z,10,2,38,A,A,2,233.93,100,130,166210,13148969,233.86,233.9,100,100,1,1,233.81,233.91,2,200,2,1,233.8,233.93,105,300,2,3,233.74,233.95,400,121,1,1,233.7,234,1200,17,1,2,233.66,234.02,1,400,1,1,233.58,234.1,505,100,2,1,233.53,234.13,10,400,1,1,233.5,234.17,100,1,1,1,233.45,234.25,15,100,1,1,GOOG
2024-10-21T12:26:43.555819727Z,2024-10-21T12:26:43.555653371Z,10,2,38,C,A,1,233.91,200,130,166356,13148970,233.86,233.9,100,100,1,1,233.81,233.93,2,300,2,3,233.8,233.95,105,121,2,1,233.74,234,400,17,1,2,233.7,234.02,1200,400,1,1,233.66,234.1,1,100,1,1,233.58,234.13,505,400,2,1,233.53,234.17,10,1,1,1,233.5,234.25,100,100,1,1,233.45,234.41,15,500,1,1,GOOG
2024-10-21T12:26:43.555829005Z,2024-10-21T12:26:43.555663089Z,10,2,38,A,A,1,233.91,23,130,165916,13148971,233.86,233.9,100,100,1,1,233.81,233.91,2,23,2,1,233.8,233.93,105,300,2,3,233.74,233.95,400,121,1,1,233.7,234,1200,17,1,2,233.66,234.02,1,400,1,1,233.58,234.1,505,100,2,1,233.53,234.13,10,400,1,1,233.5,234.17,100,1,1,1,233.45,234.25,15,100,1,1,GOOG
2024-10-21T12:26:43.555844094Z,2024-10-21T12:26:43.555678324Z,10,2,38,C,A,0,233.9,100,130,165770,13148972,233.86,233.91,100,23,1,1,233.81,233.93,2,300,2,3,233.8,233.95,105,121,2,1,233.74,234,400,17,1,2,233.7,234.02,1200,400,1,1,233.66,234.1,1,100,1,1,233.58,234.13,505,400,2,1,233.53,234.17,10,1,1,1,233.5,234.25,100,100,1,1,233.45,234.41,15,500,1,1,GOOG
2024-10-21T12:26:43.555858526Z,2024-10-21T12:26:43.555692383Z,10,2,38,C,A,1,233.93,100,130,166143,13148974,233.86,233.91,100,23,1,1,233.81,233.93,2,200,2,2,233.8,233.95,105,121,2,1,233.74,234,400,17,1,2,233.7,234.02,1200,400,1,1,233.66,234.1,1,100,1,1,233.58,234.13,505,400,2,1,233.53,234.17,10,1,1,1,233.5,234.25,100,100,1,1,233.45,234.41,15,500,1,1,GOOG
2024-10-21T12:26:43.555866497Z,2024-10-21T12:26:43.555700148Z,10,2,38,C,A,1,233.93,100,130,166349,13148976,233.86,233.91,100,23,1,1,233.81,233.93,2,100,2,1,233.8,233.94,105,23,2,1,233.74,233.95,400,121,1,1,233.7,234,1200,17,1,2,233.66,234.02,1,400,1,1,233.58,234.1,505,100,2,1,233.53,234.13,10,400,1,1,233.5,234.17,100,1,1,1,233.45,234.25,15,100,1,1,GOOG
2024-10-21T12:26:43.555879570Z,2024-10-21T12:26:43.555711164Z,10,2,38,T,A,0,233.86,50,130,168406,13148979,233.86,233.91,100,23,1,1,233.81,233.93,2,100,2,1,233.8,233.94,105,23,2,1,233.74,233.95,400,121,1,1,233.7,234,1200,17,1,2,233.66,234.02,1,400,1,1,233.58,234.1,505,100,2,1,233.53,234.13,10,400,1,1,233.5,234.17,100,1,1,1,233.45,234.25,15,100,1,1,GOOG
2024-10-21T12:26:43.555879570Z,2024-10-21T12:26:43.555711164Z,10,2,38,C,B,0,233.86,50,130,168406,13148979,233.86,233.91,50,23,1,1,233.81,233.93,2,100,2,1,233.8,233.94,105,23,2,1,233.74,233.95,400,121,1,1,233.7,234,1200,17,1,2,233.66,234.02,1,400,1,1,233.58,234.1,505,100,2,1,233.53,234.13,10,400,1,1,233.5,234.17,100,1,1,1,233.45,234.25,15,100,1,1,GOOG
2024-10-21T12:26:43.555892512Z,2024-10-21T12:26:43.555724858Z,10,2,38,A,B,0,233.86,100,130,167654,13148980,233.86,233.91,150,23,2,1,233.81,233.93,2,100,2,1,233.8,233.94,105,23,2,1,233.74,233.95,400,121,1,1,233.7,234,1200,17,1,2,233.66,234.02,1,400,1,1,233.58,234.1,505,100,2,1,233.53,234.13,10,400,1,1,233.5,234.17,100,1,1,1,233.45,234.25,15,100,1,1,GOOG
2024-10-21T12:26:43.555904815Z,2024-10-21T12:26:43.555737821Z,10,2,38,T,A,0,233.86,50,130,166994,13148981,233.86,233.91,150,23,2,1,233.81,233.93,2,100,2,1,233.8,233.94,105,23,2,1,233.74,233.95,400,121,1,1,233.7,234,1200,17,1,2,233.66,234.02,1,400,1,1,233.58,234.1,505,100,2,1,233.53,234.13,10,400,1,1,233.5,234.17,100,1,1,1,233.45,234.25,15,100,1,1,GOOG
2024-10-21T12:26:43.555904815Z,2024-10-21T12:26:43.555737821Z,10,2,38,C,B,0,233.86,50,130,166994,13148981,233.86,233.91,100,23,1,1,233.81,233.93,2,100,2,1,233.8,233.94,105,23,2,1,233.74,233.95,400,121,1,1,233.7,234,1200,17,1,2,233.66,234.02,1,400,1,1,233.58,234.1,505,100,2,1,233.53,234.13,10,400,1,1,233.5,234.17,100,1,1,1,233.45,234.25,15,100,1,1,GOOG
2024-10-21T12:26:43.555933449Z,2024-10-21T12:26:43.555767270Z,10,2,38,C,B,3,233.74,200,130,166179,13148982,233.86,233.91,100,23,1,1,233.81,233.93,2,100,2,1,233.8,233.94,105,23,2,1,233.74,233.95,200,121,1,1,233.7,234,1200,17,1,2,233.66,234.02,1,400,1,1,233.58,234.1,505,100,2,1,233.53,234.13,10,400,1,1,233.5,234.17,100,1,1,1,233.45,234.25,15,100,1,1,GOOG
2024-10-21T12:26:43.555956286Z,2024-10-21T12:26:43.555789284Z,10,2,38,C,B,3,233.74,200,130,167002,13148983,233.86,233.91,100,23,1,1,233.81,233.93,2,100,2,1,233.8,233.94,105,23,2,1,233.7,233.95,1200,121,1,1,233.66,234,1,17,1,2,233.58,234.02,505,400,2,1,233.53,234.1,10,100,1,1,233.5,234.13,100,400,1,1,233.45,234.17,15,1,1,1,233.4,234.25,110,100,2,1,GOOG
2024-10-21T12:26:43.556155095Z,2024-10-21T12:26:43.555989102Z,10,2,38,C,A,1,233.93,100,130,165993,13148984,233.86,233.91,100,23,1,1,233.81,233.94,2,23,2,1,233.8,233.95,105,121,2,1,233.7,234,1200,17,1,2,233.66,234.02,1,400,1,1,233.58,234.1,505,100,2,1,233.53,234.13,10,400,1,1,233.5,234.17,100,1,1,1,233.45,234.25,15,100,1,1,233.4,234.41,110,500,2,1,GOOG
2024-10-21T12:26:43.556502258Z,2024-10-21T12:26:43.556335122Z,10,2,38,T,A,0,233.86,5,130,167136,13148985,233.86,233.91,100,23,1,1,233.81,233.94,2,23,2,1,233.8,233.95,105,121,2,1,233.7,234,1200,17,1,2,233.66,234.02,1,400,1,1,233.58,234.1,505,100,2,1,233.53,234.13,10,400,1,1,233.5,234.17,100,1,1,1,233.45,234.25,15,100,1,1,233.4,234.41,110,500,2,1,GOOG
2024-10-21T12:26:43.556502258Z,2024-10-21T12:26:43.556335122Z,10,2,38,C,B,0,233.86,5,130,167136,13148985,233.86,233.91,95,23,1,1,233.81,233.94,2,23,2,1,233.8,233.95,105,121,2,1,233.7,234,1200,17,1,2,233.66,234.02,1,400,1,1,233.58,234.1,505,100,2,1,233.53,234.13,10,400,1,1,233.5,234.17,100,1,1,1,233.45,234.25,15,100,1,1,233.4,234.41,110,500,2,1,GOOG
2024-10-21T12:26:43.556510636Z,2024-10-21T12:26:43.556344203Z,10,2,38,A,B,0,233.86,100,130,166433,13148986,233.86,233.91,195,23,2,1,233.81,233.94,2,23,2,1,233.8,233.95,105,121,2,1,233.7,234,1200,17,1,2,233.66,234.02,1,400,1,1,233.58,234.1,505,100,2,1,233.53,234.13,10,400,1,1,233.5,234.17,100,1,1,1,233.45,234.25,15,100,1,1,233.4,234.41,110,500,2,1,GOOG
2024-10-21T12:26:43.603087151Z,2024-10-21T12:26:43.602920183Z,10,2,38,A,B,3,233.74,200,130,166968,13149063,233.86,233.91,195,23,2,1,233.81,233.94,2,23,2,1,233.8,233.95,105,121,2,1,233.74,234,200,17,1,2,233.7,234.02,1200,400,1,1,233.66,234.1,1,100,1,1,233.58,234.13,505,400,2,1,233.53,234.17,10,1,1,1,233.5,234.25,100,100,1,1,233.45,234.41,15,500,1,1,GOOG
2024-10-21T12:26:43.633097364Z,2024-10-21T12:26:43.632931005Z,10,2,38,A,B,3,233.74,200,130,166359,13149078,233.86,233.91,195,23,2,1,233.81,233.94,2,23,2,1,233.8,233.95,105,121,2,1,233.74,234,400,17,2,2,233.7,234.02,1200,400,1,1,233.66,234.1,1,100,1,1,233.58,234.13,505,400,2,1,233.53,234.17,10,1,1,1,233.5,234.25,100,100,1,1,233.45,234.41,15,500,1,1,GOOG
2024-10-21T12:26:43.663930696Z,2024-10-21T12:26:43.663764676Z,10,2,38,C,A,1,233.94,23,130,166020,13149095,233.86,233.91,195,23,2,1,233.81,233.95,2,121,2,1,233.8,234,105,17,2,2,233.74,234.02,400,400,2,1,233.7,234.1,1200,100,1,1,233.66,234.13,1,400,1,1,233.58,234.17,505,1,2,1,233.53,234.25,10,100,1,1,233.5,234.41,100,500,1,1,233.45,234.43,15,105,1,2,GOOG
2024-10-21T12:26:43.813930819Z,2024-10-21T12:26:43.813764689Z,10,2,38,C,A,0,233.91,23,130,166130,13149215,233.86,233.95,195,121,2,1,233.81,234,2,17,2,2,233.8,234.02,105,400,2,1,233.74,234.1,400,100,2,1,233.7,234.13,1200,400,1,1,233.66,234.17,1,1,1,1,233.58,234.25,505,100,2,1,233.53,234.41,10,500,1,1,233.5,234.43,100,105,1,2,233.45,234.5,15,63,1,4,GOOG
2024-10-21T12:26:44.395306900Z,2024-10-21T12:26:44.395140599Z,10,2,38,A,A,1,233.97,7,130,166301,13149756,233.86,233.95,195,121,2,1,233.81,233.97,2,7,2,1,233.8,234,105,17,2,2,233.74,234.02,400,400,2,1,233.7,234.1,1200,100,1,1,233.66,234.13,1,400,1,1,233.58,234.17,505,1,2,1,233.53,234.25,10,100,1,1,233.5,234.41,100,500,1,1,233.45,234.43,15,105,1,2,GOOG
2024-10-21T12:26:47.317000869Z,2024-10-21T12:26:47.316834945Z,10,2,38,C,A,3,234.02,400,130,165924,13152409,233.86,233.95,195,121,2,1,233.81,233.97,2,7,2,1,233.8,234,105,17,2,2,233.74,234.1,400,100,2,1,233.7,234.13,1200,400,1,1,233.66,234.17,1,1,1,1,233.58,234.25,505,100,2,1,233.53,234.41,10,500,1,1,233.5,234.43,100,105,1,2,233.45,234.5,15,63,1,4,GOOG
2024-10-21T12:26:47.317013569Z,2024-10-21T12:26:47.316847348Z,10,2,38,A,A,3,234.04,400,130,166221,13152410,233.86,233.95,195,121,2,1,233.81,233.97,2,7,2,1,233.8,234,105,17,2,2,233.74,234.04,400,400,2,1,233.7,234.1,1200,100,1,1,233.66,234.13,1,400,1,1,233.58,234.17,505,1,2,1,233.53,234.25,10,100,1,1,233.5,234.41,100,500,1,1,233.45,234.43,15,105,1,2,GOOG
2024-10-21T12:26:47.371614290Z,2024-10-21T12:26:47.371448271Z,10,2,38,C,B,3,233.74,200,130,166019,13152673,233.86,233.95,195,121,2,1,233.81,233.97,2,7,2,1,233.8,234,105,17,2,2,233.74,234.04,200,400,1,1,233.7,234.1,1200,100,1,1,233.66,234.13,1,400,1,1,233.58,234.17,505,1,2,1,233.53,234.25,10,100,1,1,233.5,234.41,100,500,1,1,233.45,234.43,15,105,1,2,GOOG
2024-10-21T12:26:47.371627679Z,2024-10-21T12:26:47.371461367Z,10,2,38,A,B,3,233.76,400,130,166312,13152674,233.86,233.95,195,121,2,1,233.81,233.97,2,7,2,1,233.8,234,105,17,2,2,233.76,234.04,400,400,1,1,233.7,234.1,1200,100,1,1,233.66,234.13,1,400,1,1,233.58,234.17,505,1,2,1,233.53,234.25,10,100,1,1,233.5,234.41,100,500,1,1,233.45,234.43,15,105,1,2,GOOG
2024-10-21T12:26:53.381817361Z,2024-10-21T12:26:53.381650546Z,10,2,38,A,B,3,233.77,400,130,166815,13157627,233.86,233.95,195,121,2,1,233.81,233.97,2,7,2,1,233.8,234,105,17,2,2,233.77,234.04,400,400,1,1,233.7,234.1,1200,100,1,1,233.66,234.13,1,400,1,1,233.58,234.17,505,1,2,1,233.53,234.25,10,100,1,1,233.5,234.41,100,500,1,1,233.45,234.43,15,105,1,2,GOOG
2024-10-21T12:26:54.545889324Z,2024-10-21T12:26:54.545723322Z,10,2,38,C,B,3,233.77,400,130,166002,13158660,233.86,233.95,195,121,2,1,233.81,233.97,2,7,2,1,233.8,234,105,17,2,2,233.7,234.04,1200,400,1,1,233.66,234.1,1,100,1,1,233.58,234.13,505,400,2,1,233.53,234.17,10,1,1,1,233.5,234.25,100,100,1,1,233.45,234.41,15,500,1,1,233.4,234.43,110,105,2,2,GOOG
2024-10-21T12:26:54.545901500Z,2024-10-21T12:26:54.545735230Z,10,2,38,A,B,3,233.76,400,130,166270,13158661,233.86,233.95,195,121,2,1,233.81,233.97,2,7,2,1,233.8,234,105,17,2,2,233.76,234.04,400,400,1,1,233.7,234.1,1200,100,1,1,233.66,234.13,1,400,1,1,233.58,234.17,505,1,2,1,233.53,234.25,10,100,1,1,233.5,234.41,100,500,1,1,233.45,234.43,15,105,1,2,GOOG
2024-10-21T12:27:04.677969002Z,2024-10-21T12:27:04.677802802Z,10,2,38,A,B,3,233.77,400,130,166200,13168438,233.86,233.95,195,121,2,1,233.81,233.97,2,7,2,1,233.8,234,105,17,2,2,233.77,234.04,400,400,1,1,233.7,234.1,1200,100,1,1,233.66,234.13,1,400,1,1,233.58,234.17,505,1,2,1,233.53,234.25,10,100,1,1,233.5,234.41,100,500,1,1,233.45,234.43,15,105,1,2,GOOG
2024-10-21T12:27:04.858352610Z,2024-10-21T12:27:04.858186427Z,10,2,38,C,B,3,233.77,200,130,166183,13168809,233.86,233.95,195,121,2,1,233.81,233.97,2,7,2,1,233.8,234,105,17,2,2,233.77,234.04,200,400,1,1,233.7,234.1,1200,100,1,1,233.66,234.13,1,400,1,1,233.58,234.17,505,1,2,1,233.53,234.25,10,100,1,1,233.5,234.41,100,500,1,1,233.45,234.43,15,105,1,2,GOOG
2024-10-21T12:27:08.140351417Z,2024-10-21T12:27:08.140184917Z,10,2,38,A,B,0,233.86,100,130,166500,13171896,233.86,233.95,295,121,3,1,233.81,233.97,2,7,2,1,233.8,234,105,17,2,2,233.77,234.04,200,400,1,1,233.7,234.1,1200,100,1,1,233.66,234.13,1,400,1,1,233.58,234.17,505,1,2,1,233.53,234.25,10,100,1,1,233.5,234.41,100,500,1,1,233.45,234.43,15,105,1,2,GOOG
2024-10-21T12:27:08.267404175Z,2024-10-21T12:27:08.267237597Z,10,2,38,A,A,2,233.99,200,130,166578,13172040,233.86,233.95,295,121,3,1,233.81,233.97,2,7,2,1,233.8,233.99,105,200,2,1,233.77,234,200,17,1,2,233.7,234.1,1200,100,1,1,233.66,234.13,1,400,1,1,233.58,234.17,505,1,2,1,233.53,234.25,10,100,1,1,233.5,234.41,100,500,1,1,233.45,234.43,15,105,1,2,GOOG
2024-10-21T12:27:08.904013328Z,2024-10-21T12:27:08.903847050Z,10,2,38,A,B,3,233.77,200,130,166278,13172666,233.86,233.95,295,121,3,1,233.81,233.97,2,7,2,1,233.8,233.99,105,200,2,1,233.77,234,400,17,2,2,233.7,234.1,1200,100,1,1,233.66,234.13,1,400,1,1,233.58,234.17,505,1,2,1,233.53,234.25,10,100,1,1,233.5,234.41,100,500,1,1,233.45,234.43,15,105,1,2,GOOG
2024-10-21T12:27:15.211190007Z,2024-10-21T12:27:15.211023662Z,10,2,38,C,A,1,233.97,7,130,166345,13177973,233.86,233.95,295,121,3,1,233.81,233.99,2,200,2,1,233.8,234,105,17,2,2,233.77,234.1,400,100,2,1,233.7,234.13,1200,400,1,1,233.66,234.17,1,1,1,1,233.58,234.25,505,100,2,1,233.53,234.41,10,500,1,1,233.5,234.43,100,105,1,2,233.45,234.5,15,63,1,4,GOOG
2024-10-21T12:27:16.357351976Z,2024-10-21T12:27:16.357185731Z,10,2,38,C,A,0,233.95,121,130,166245,13178747,233.86,233.99,295,200,3,1,233.81,234,2,17,2,2,233.8,234.1,105,100,2,1,233.77,234.13,400,400,2,1,233.7,234.17,1200,1,1,1,233.66,234.25,1,100,1,1,233.58,234.41,505,500,2,1,233.53,234.43,10,105,1,2,233.5,234.5,100,63,1,4,233.45,234.59,15,60,1,1,GOOG
2024-10-21T12:27:16.384048756Z,2024-10-21T12:27:16.383880298Z,10,2,38,T,N,0,233.87,50,0,168458,13178752,233.86,233.99,295,200,3,1,233.81,234,2,17,2,2,233.8,234.1,105,100,2,1,233.77,234.13,400,400,2,1,233.7,234.17,1200,1,1,1,233.66,234.25,1,100,1,1,233.58,234.41,505,500,2,1,233.53,234.43,10,105,1,2,233.5,234.5,100,63,1,4,233.45,234.59,15,60,1,1,GOOG
2024-10-21T12:27:16.384048756Z,2024-10-21T12:27:16.383880298Z,10,2,38,T,N,0,233.87,71,130,168458,13178753,233.86,233.99,295,200,3,1,233.81,234,2,17,2,2,233.8,234.1,105,100,2,1,233.77,234.13,400,400,2,1,233.7,234.17,1200,1,1,1,233.66,234.25,1,100,1,1,233.58,234.41,505,500,2,1,233.53,234.43,10,105,1,2,233.5,234.5,100,63,1,4,233.45,234.59,15,60,1,1,GOOG
2024-10-21T12:27:17.218399628Z,2024-10-21T12:27:17.218233083Z,10,2,38,A,A,0,233.98,7,130,166545,13179063,233.86,233.98,295,7,3,1,233.81,233.99,2,200,2,1,233.8,234,105,17,2,2,233.77,234.1,400,100,2,1,233.7,234.13,1200,400,1,1,233.66,234.17,1,1,1,1,233.58,234.25,505,100,2,1,233.53,234.41,10,500,1,1,233.5,234.43,100,105,1,2,233.45,234.5,15,63,1,4,GOOG
2024-10-21T12:27:21.556157771Z,2024-10-21T12:27:21.555991612Z,10,2,38,C,B,3,233.77,200,130,166159,13183172,233.86,233.98,295,7,3,1,233.81,233.99,2,200,2,1,233.8,234,105,17,2,2,233.77,234.1,200,100,1,1,233.7,234.13,1200,400,1,1,233.66,234.17,1,1,1,1,233.58,234.25,505,100,2,1,233.53,234.41,10,500,1,1,233.5,234.43,100,105,1,2,233.45,234.5,15,63,1,4,GOOG
2024-10-21T12:27:21.556172659Z,2024-10-21T12:27:21.556005910Z,10,2,38,A,B,1,233.81,200,130,166749,13183173,233.86,233.98,295,7,3,1,233.81,233.99,202,200,3,1,233.8,234,105,17,2,2,233.7,234.1,1200,100,1,1,233.66,234.13,1,400,1,1,233.58,234.17,505,1,2,1,233.53,234.25,10,100,1,1,233.5,234.41,100,500,1,1,233.45,234.43,15,105,1,2,233.4,234.5,110,63,2,4,GOOG
2024-10-21T12:27:21.983295309Z,2024-10-21T12:27:21.983129451Z,10,2,38,C,B,1,233.81,200,130,165858,13183374,233.86,233.98,295,7,3,1,233.81,233.99,2,200,2,1,233.8,234,105,17,2,2,233.7,234.1,1200,100,1,1,233.66,234.13,1,400,1,1,233.58,234.17,505,1,2,1,233.53,234.25,10,100,1,1,233.5,234.41,100,500,1,1,233.45,234.43,15,105,1,2,233.4,234.5,110,63,2,4,GOOG
2024-10-21T12:27:21.983308878Z,2024-10-21T12:27:21.983142748Z,10,2,38,A,B,3,233.77,400,130,166130,13183375,233.86,233.98,295,7,3,1,233.81,233.99,2,200,2,1,233.8,234,105,17,2,2,233.77,234.1,400,100,1,1,233.7,234.13,1200,400,1,1,233.66,234.17,1,1,1,1,233.58,234.25,505,100,2,1,233.53,234.41,10,500,1,1,233.5,234.43,100,105,1,2,233.45,234.5,15,63,1,4,GOOG
2024-10-21T12:27:22.989069356Z,2024-10-21T12:27:22.988903196Z,10,2,38,C,A,0,233.98,7,130,166160,13184098,233.86,233.99,295,200,3,1,233.81,234,2,17,2,2,233.8,234.1,105,100,2,1,233.77,234.13,400,400,1,1,233.7,234.17,1200,1,1,1,233.66,234.25,1,100,1,1,233.58,234.41,505,500,2,1,233.53,234.43,10,105,1,2,233.5,234.5,100,63,1,4,233.45,234.59,15,60,1,1,GOOG
2024-10-21T12:27:23.025873698Z,2024-10-21T12:27:23.025707565Z,10,2,38,C,B,3,233.77,400,130,166133,13184133,233.86,233.99,295,200,3,1,233.81,234,2,17,2,2,233.8,234.1,105,100,2,1,233.7,234.13,1200,400,1,1,233.66,234.17,1,1,1,1,233.58,234.25,505,100,2,1,233.53,234.41,10,500,1,1,233.5,234.43,100,105,1,2,233.45,234.5,15,63,1,4,233.4,234.59,110,60,2,1,GOOG
2024-10-21T12:27:23.025886464Z,2024-10-21T12:27:23.025720316Z,10,2,38,A,B,3,233.74,200,130,166148,13184134,233.86,233.99,295,200,3,1,233.81,234,2,17,2,2,233.8,234.1,105,100,2,1,233.74,234.13,200,400,1,1,233.7,234.17,1200,1,1,1,233.66,234.25,1,100,1,1,233.58,234.41,505,500,2,1,233.53,234.43,10,105,1,2,233.5,234.5,100,63,1,4,233.45,234.59,15,60,1,1,GOOG
2024-10-21T12:27:24.992972792Z,2024-10-21T12:27:24.992239712Z,10,2,38,A,A,0,233.99,7,130,733080,13186020,233.86,233.99,295,207,3,2,233.81,234,2,17,2,2,233.8,234.1,105,100,2,1,233.74,234.13,200,400,1,1,233.7,234.17,1200,1,1,1,233.66,234.25,1,100,1,1,233.58,234.41,505,500,2,1,233.53,234.43,10,105,1,2,233.5,234.5,100,63,1,4,233.45,234.59,15,60,1,1,GOOG
2024-10-21T12:27:25.038852343Z,2024-10-21T12:27:25.038119028Z,10,2,38,A,B,3,233.77,200,130,733315,13186052,233.86,233.99,295,207,3,2,233.81,234,2,17,2,2,233.8,234.1,105,100,2,1,233.77,234.13,200,400,1,1,233.7,234.17,1200,1,1,1,233.66,234.25,1,100,1,1,233.58,234.41,505,500,2,1,233.53,234.43,10,105,1,2,233.5,234.5,100,63,1,4,233.45,234.59,15,60,1,1,GOOG
2024-10-21T12:27:26.131472457Z,2024-10-21T12:27:26.130738899Z,10,2,38,A,B,3,233.77,200,130,733558,13186986,233.86,233.99,295,207,3,2,233.81,234,2,17,2,2,233.8,234.1,105,100,2,1,233.77,234.13,400,400,2,1,233.7,234.17,1200,1,1,1,233.66,234.25,1,100,1,1,233.58,234.41,505,500,2,1,233.53,234.43,10,105,1,2,233.5,234.5,100,63,1,4,233.45,234.59,15,60,1,1,GOOG
2024-10-21T12:27:28.579136710Z,2024-10-21T12:27:28.578403729Z,10,2,38,C,A,0,233.99,7,130,732981,13188280,233.86,233.99,295,200,3,1,233.81,234,2,17,2,2,233.8,234.1,105,100,2,1,233.77,234.13,400,400,2,1,233.7,234.17,1200,1,1,1,233.66,234.25,1,100,1,1,233.58,234.41,505,500,2,1,233.53,234.43,10,105,1,2,233.5,234.5,100,63,1,4,233.45,234.59,15,60,1,1,GOOG
2024-10-21T12:27:29.136296936Z,2024-10-21T12:27:29.135563917Z,10,2,38,C,A,0,233.99,200,130,733019,13188524,233.86,234,295,17,3,2,233.81,234.1,2,100,2,1,233.8,234.13,105,400,2,1,233.77,234.17,400,1,2,1,233.7,234.25,1200,100,1,1,233.66,234.41,1,500,1,1,233.58,234.43,505,105,2,2,233.53,234.5,10,63,1,4,233.5,234.59,100,60,1,1,233.45,234.75,15,1,1,1,GOOG
2024-10-21T12:27:29.136314635Z,2024-10-21T12:27:29.135580379Z,10,2,38,A,A,1,234.05,400,130,734256,13188525,233.86,234,295,17,3,2,233.81,234.05,2,400,2,1,233.8,234.1,105,100,2,1,233.77,234.13,400,400,2,1,233.7,234.17,1200,1,1,1,233.66,234.25,1,100,1,1,233.58,234.41,505,500,2,1,233.53,234.43,10,105,1,2,233.5,234.5,100,63,1,4,233.45,234.59,15,60,1,1,GOOG
2024-10-21T12:27:30.582343028Z,2024-10-21T12:27:30.581609917Z,10,2,38,A,A,6,234.41,7,130,733111,13189750,233.86,234,295,17,3,2,233.81,234.05,2,400,2,1,233.8,234.1,105,100,2,1,233.77,234.13,400,400,2,1,233.7,234.17,1200,1,1,1,233.66,234.25,1,100,1,1,233.58,234.41,505,507,2,2,233.53,234.43,10,105,1,2,233.5,234.5,100,63,1,4,233.45,234.59,15,60,1,1,GOOG
2024-10-21T12:27:37.149919392Z,2024-10-21T12:27:37.149186319Z,10,2,38,C,B,3,233.77,200,130,733073,13194254,233.86,234,295,17,3,2,233.81,234.05,2,400,2,1,233.8,234.1,105,100,2,1,233.77,234.13,200,400,1,1,233.7,234.17,1200,1,1,1,233.66,234.25,1,100,1,1,233.58,234.41,505,507,2,2,233.53,234.43,10,105,1,2,233.5,234.5,100,63,1,4,233.45,234.59,15,60,1,1,GOOG
2024-10-21T12:27:37.149931822Z,2024-10-21T12:27:37.149198552Z,10,2,38,A,B,3,233.78,400,130,733270,13194255,233.86,234,295,17,3,2,233.81,234.05,2,400,2,1,233.8,234.1,105,100,2,1,233.78,234.13,400,400,1,1,233.7,234.17,1200,1,1,1,233.66,234.25,1,100,1,1,233.58,234.41,505,507,2,2,233.53,234.43,10,105,1,2,233.5,234.5,100,63,1,4,233.45,234.59,15,60,1,1,GOOG
2024-10-21T12:27:37.282093181Z,2024-10-21T12:27:37.281359883Z,10,2,38,A,A,1,234.02,200,130,733298,13194447,233.86,234,295,17,3,2,233.81,234.02,2,200,2,1,233.8,234.1,105,100,2,1,233.78,234.13,400,400,1,1,233.7,234.17,1200,1,1,1,233.66,234.25,1,100,1,1,233.58,234.41,505,507,2,2,233.53,234.43,10,105,1,2,233.5,234.5,100,63,1,4,233.45,234.59,15,60,1,1,GOOG
2024-10-21T12:27:37.731855277Z,2024-10-21T12:27:37.731121489Z,10,2,38,A,B,3,233.79,400,130,733788,13195199,233.86,234,295,17,3,2,233.81,234.02,2,200,2,1,233.8,234.1,105,100,2,1,233.79,234.13,400,400,1,1,233.7,234.17,1200,1,1,1,233.66,234.25,1,100,1,1,233.58,234.41,505,507,2,2,233.53,234.43,10,105,1,2,233.5,234.5,100,63,1,4,233.45,234.59,15,60,1,1,GOOG
2024-10-21T12:27:37.764573144Z,2024-10-21T12:27:37.763839849Z,10,2,38,C,B,3,233.79,200,130,733295,13195270,233.86,234,295,17,3,2,233.81,234.02,2,200,2,1,233.8,234.1,105,100,2,1,233.79,234.13,200,400,1,1,233.7,234.17,1200,1,1,1,233.66,234.25,1,100,1,1,233.58,234.41,505,507,2,2,233.53,234.43,10,105,1,2,233.5,234.5,100,63,1,4,233.45,234.59,15,60,1,1,GOOG
2024-10-21T12:27:37.767686766Z,2024-10-21T12:27:37.766952915Z,10,2,38,A,A,1,234.02,200,130,733851,13195276,233.86,234,295,17,3,2,233.81,234.02,2,400,2,2,233.8,234.1,105,100,2,1,233.79,234.13,200,400,1,1,233.7,234.17,1200,1,1,1,233.66,234.25,1,100,1,1,233.58,234.41,505,507,2,2,233.53,234.43,10,105,1,2,233.5,234.5,100,63,1,4,233.45,234.59,15,60,1,1,GOOG
2024-10-21T12:27:39.526116351Z,2024-10-21T12:27:39.525383410Z,10,2,38,C,A,1,234.02,200,130,732941,13197083,233.86,234,295,17,3,2,233.81,234.02,2,200,2,1,233.8,234.1,105,100,2,1,233.79,234.13,200,400,1,1,233.7,234.17,1200,1,1,1,233.66,234.25,1,100,1,1,233.58,234.41,505,507,2,2,233.53,234.43,10,105,1,2,233.5,234.5,100,63,1,4,233.45,234.59,15,60,1,1,GOOG
2024-10-21T12:27:39.526127909Z,2024-10-21T12:27:39.525394818Z,10,2,38,C,A,1,234.02,200,130,733091,13197084,233.86,234,295,17,3,2,233.81,234.1,2,100,2,1,233.8,234.13,105,400,2,1,233.79,234.17,200,1,1,1,233.7,234.25,1200,100,1,1,233.66,234.41,1,507,1,2,233.58,234.43,505,105,2,2,233.53,234.5,10,63,1,4,233.5,234.59,100,60,1,1,233.45,234.75,15,1,1,1,GOOG
2024-10-21T12:27:39.527631797Z,2024-10-21T12:27:39.526899044Z,10,2,38,C,A,5,234.41,7,130,732753,13197088,233.86,234,295,17,3,2,233.81,234.1,2,100,2,1,233.8,234.13,105,400,2,1,233.79,234.17,200,1,1,1,233.7,234.25,1200,100,1,1,233.66,234.41,1,500,1,1,233.58,234.43,505,105,2,2,233.53,234.5,10,63,1,4,233.5,234.59,100,60,1,1,233.45,234.75,15,1,1,1,GOOG
2024-10-21T12:27:39.593636447Z,2024-10-21T12:27:39.592903496Z,10,2,38,A,B,1,233.84,100,130,732951,13197554,233.86,234,295,17,3,2,233.84,234.1,100,100,1,1,233.81,234.13,2,400,2,1,233.8,234.17,105,1,2,1,233.79,234.25,200,100,1,1,233.7,234.41,1200,500,1,1,233.66,234.43,1,105,1,2,233.58,234.5,505,63,2,4,233.53,234.59,10,60,1,1,233.5,234.75,100,1,1,1,GOOG
2024-10-21T12:27:39.593996622Z,2024-10-21T12:27:39.593262886Z,10,2,38,C,B,1,233.84,100,130,733736,13197558,233.86,234,295,17,3,2,233.81,234.1,2,100,2,1,233.8,234.13,105,400,2,1,233.79,234.17,200,1,1,1,233.7,234.25,1200,100,1,1,233.66,234.41,1,500,1,1,233.58,234.43,505,105,2,2,233.53,234.5,10,63,1,4,233.5,234.59,100,60,1,1,233.45,234.75,15,1,1,1,GOOG
2024-10-21T12:27:39.712483751Z,2024-10-21T12:27:39.711750527Z,10,2,38,A,A,1,234.02,400,130,733224,13197970,233.86,234,295,17,3,2,233.81,234.02,2,400,2,1,233.8,234.1,105,100,2,1,233.79,234.13,200,400,1,1,233.7,234.17,1200,1,1,1,233.66,234.25,1,100,1,1,233.58,234.41,505,500,2,1,233.53,234.43,10,105,1,2,233.5,234.5,100,63,1,4,233.45,234.59,15,60,1,1,GOOG
2024-10-21T12:27:40.732061815Z,2024-10-21T12:27:40.731328339Z,10,2,38,A,A,1,234.01,400,130,733476,13198996,233.86,234,295,17,3,2,233.81,234.01,2,400,2,1,233.8,234.1,105,100,2,1,233.79,234.13,200,400,1,1,233.7,234.17,1200,1,1,1,233.66,234.25,1,100,1,1,233.58,234.41,505,500,2,1,233.53,234.43,10,105,1,2,233.5,234.5,100,63,1,4,233.45,234.59,15,60,1,1,GOOG
2024-10-21T12:27:40.758541085Z,2024-10-21T12:27:40.757807867Z,10,2,38,C,A,1,234.01,400,130,733218,13199068,233.86,234,295,17,3,2,233.81,234.1,2,100,2,1,233.8,234.13,105,400,2,1,233.79,234.17,200,1,1,1,233.7,234.25,1200,100,1,1,233.66,234.41,1,500,1,1,233.58,234.43,505,105,2,2,233.53,234.5,10,63,1,4,233.5,234.59,100,60,1,1,233.45,234.75,15,1,1,1,GOOG
2024-10-21T12:27:40.758553589Z,2024-10-21T12:27:40.757820402Z,10,2,38,A,A,1,234.02,200,130,733187,13199069,233.86,234,295,17,3,2,233.81,234.02,2,200,2,1,233.8,234.1,105,100,2,1,233.79,234.13,200,400,1,1,233.7,234.17,1200,1,1,1,233.66,234.25,1,100,1,1,233.58,234.41,505,500,2,1,233.53,234.43,10,105,1,2,233.5,234.5,100,63,1,4,233.45,234.59,15,60,1,1,GOOG
2024-10-21T12:27:41.106714797Z,2024-10-21T12:27:41.105981707Z,10,2,38,C,A,1,234.02,200,130,733090,13199310,233.86,234,295,17,3,2,233.81,234.1,2,100,2,1,233.8,234.13,105,400,2,1,233.79,234.17,200,1,1,1,233.7,234.25,1200,100,1,1,233.66,234.41,1,500,1,1,233.58,234.43,505,105,2,2,233.53,234.5,10,63,1,4,233.5,234.59,100,60,1,1,233.45,234.75,15,1,1,1,GOOG
2024-10-21T12:27:41.176308255Z,2024-10-21T12:27:41.175574942Z,10,2,38,A,A,1,234.06,200,130,733313,13199399,233.86,234,295,17,3,2,233.81,234.06,2,200,2,1,233.8,234.1,105,100,2,1,233.79,234.13,200,400,1,1,233.7,234.17,1200,1,1,1,233.66,234.25,1,100,1,1,233.58,234.41,505,500,2,1,233.53,234.43,10,105,1,2,233.5,234.5,100,63,1,4,233.45,234.59,15,60,1,1,GOOG
2024-10-21T12:27:41.223548018Z,2024-10-21T12:27:41.222814573Z,10,2,38,A,A,1,234.06,200,130,733445,13199432,233.86,234,295,17,3,2,233.81,234.06,2,400,2,2,233.8,234.1,105,100,2,1,233.79,234.13,200,400,1,1,233.7,234.17,1200,1,1,1,233.66,234.25,1,100,1,1,233.58,234.41,505,500,2,1,233.53,234.43,10,105,1,2,233.5,234.5,100,63,1,4,233.45,234.59,15,60,1,1,GOOG
2024-10-21T12:27:41.320586998Z,2024-10-21T12:27:41.319854032Z,10,2,38,C,A,1,234.06,200,130,732966,13199474,233.86,234,295,17,3,2,233.81,234.06,2,200,2,1,233.8,234.1,105,100,2,1,233.79,234.13,200,400,1,1,233.7,234.17,1200,1,1,1,233.66,234.25,1,100,1,1,233.58,234.41,505,500,2,1,233.53,234.43,10,105,1,2,233.5,234.5,100,63,1,4,233.45,234.59,15,60,1,1,GOOG
2024-10-21T12:27:41.320600607Z,2024-10-21T12:27:41.319866876Z,10,2,38,A,A,1,234.04,200,130,733731,13199475,233.86,234,295,17,3,2,233.81,234.04,2,200,2,1,233.8,234.1,105,100,2,1,233.79,234.13,200,400,1,1,233.7,234.17,1200,1,1,1,233.66,234.25,1,100,1,1,233.58,234.41,505,500,2,1,233.53,234.43,10,105,1,2,233.5,234.5,100,63,1,4,233.45,234.59,15,60,1,1,GOOG
2024-10-21T12:27:41.530250934Z,2024-10-21T12:27:41.529517717Z,10,2,38,A,A,6,234.38,7,130,733217,13199682,233.86,234,295,17,3,2,233.81,234.04,2,200,2,1,233.8,234.1,105,100,2,1,233.79,234.13,200,400,1,1,233.7,234.17,1200,1,1,1,233.66,234.25,1,100,1,1,233.58,234.38,505,7,2,1,233.53,234.41,10,500,1,1,233.5,234.43,100,105,1,2,233.45,234.5,15,63,1,4,GOOG
2024-10-21T12:27:46.418013842Z,2024-10-21T12:27:46.417280824Z,10,2,38,C,B,3,233.79,200,130,733018,13203166,233.86,234,295,17,3,2,233.81,234.04,2,200,2,1,233.8,234.1,105,100,2,1,233.7,234.13,1200,400,1,1,233.66,234.17,1,1,1,1,233.58,234.25,505,100,2,1,233.53,234.38,10,7,1,1,233.5,234.41,100,500,1,1,233.45,234.43,15,105,1,2,233.4,234.5,110,63,2,4,GOOG
2024-10-21T12:27:46.418026002Z,2024-10-21T12:27:46.417292639Z,10,2,38,A,B,3,233.77,400,130,733363,13203167,233.86,234,295,17,3,2,233.81,234.04,2,200,2,1,233.8,234.1,105,100,2,1,233.77,234.13,400,400,1,1,233.7,234.17,1200,1,1,1,233.66,234.25,1,100,1,1,233.58,234.38,505,7,2,1,233.53,234.41,10,500,1,1,233.5,234.43,100,105,1,2,233.45,234.5,15,63,1,4,GOOG
2024-10-21T12:27:46.473030357Z,2024-10-21T12:27:46.472297071Z,10,2,38,A,A,1,234.03,200,130,733286,13203213,233.86,234,295,17,3,2,233.81,234.03,2,200,2,1,233.8,234.1,105,100,2,1,233.77,234.13,400,400,1,1,233.7,234.17,1200,1,1,1,233.66,234.25,1,100,1,1,233.58,234.38,505,7,2,1,233.53,234.41,10,500,1,1,233.5,234.43,100,105,1,2,233.45,234.5,15,63,1,4,GOOG
2024-10-21T12:27:47.209450267Z,2024-10-21T12:27:47.208717142Z,10,2,38,C,A,1,234.03,200,130,733125,13204087,233.86,234,295,17,3,2,233.81,234.1,2,100,2,1,233.8,234.13,105,400,2,1,233.77,234.17,400,1,1,1,233.7,234.25,1200,100,1,1,233.66,234.38,1,7,1,1,233.58,234.41,505,500,2,1,233.53,234.43,10,105,1,2,233.5,234.5,100,63,1,4,233.45,234.59,15,60,1,1,GOOG
2024-10-21T12:27:47.310139513Z,2024-10-21T12:27:47.309406274Z,10,2,38,A,A,1,234.03,200,130,733239,13204445,233.86,234,295,17,3,2,233.81,234.03,2,200,2,1,233.8,234.1,105,100,2,1,233.77,234.13,400,400,1,1,233.7,234.17,1200,1,1,1,233.66,234.25,1,100,1,1,233.58,234.38,505,7,2,1,233.53,234.41,10,500,1,1,233.5,234.43,100,105,1,2,233.45,234.5,15,63,1,4,GOOG
2024-10-21T12:27:47.985465401Z,2024-10-21T12:27:47.985298442Z,10,2,38,A,B,3,233.78,400,130,166959,13205236,233.86,234,295,17,3,2,233.81,234.03,2,200,2,1,233.8,234.1,105,100,2,1,233.78,234.13,400,400,1,1,233.7,234.17,1200,1,1,1,233.66,234.25,1,100,1,1,233.58,234.38,505,7,2,1,233.53,234.41,10,500,1,1,233.5,234.43,100,105,1,2,233.45,234.5,15,63,1,4,GOOG
2024-10-21T12:27:50.060871934Z,2024-10-21T12:27:50.060705561Z,10,2,38,C,A,1,234.03,200,130,166373,13206376,233.86,234,295,17,3,2,233.81,234.1,2,100,2,1,233.8,234.13,105,400,2,1,233.78,234.17,400,1,1,1,233.7,234.25,1200,100,1,1,233.66,234.38,1,7,1,1,233.58,234.41,505,500,2,1,233.53,234.43,10,105,1,2,233.5,234.5,100,63,1,4,233.45,234.59,15,60,1,1,GOOG
2024-10-21T12:27:50.061591231Z,2024-10-21T12:27:50.061424726Z,10,2,38,A,B,0,233.87,4,130,166505,13206379,233.87,234,4,17,1,2,233.86,234.1,295,100,3,1,233.81,234.13,2,400,2,1,233.8,234.17,105,1,2,1,233.78,234.25,400,100,1,1,233.7,234.38,1200,7,1,1,233.66,234.41,1,500,1,1,233.58,234.43,505,105,2,2,233.53,234.5,10,63,1,4,233.5,234.59,100,60,1,1,GOOG
2024-10-21T12:27:50.061891362Z,2024-10-21T12:27:50.061724093Z,10,2,38,A,B,0,233.87,100,128,167269,13206382,233.87,234,104,17,2,2,233.86,234.1,295,100,3,1,233.81,234.13,2,400,2,1,233.8,234.17,105,1,2,1,233.78,234.25,400,100,1,1,233.7,234.38,1200,7,1,1,233.66,234.41,1,500,1,1,233.58,234.43,505,105,2,2,233.53,234.5,10,63,1,4,233.5,234.59,100,60,1,1,GOOG
2024-10-21T12:27:50.062283396Z,2024-10-21T12:27:50.062117451Z,10,2,38,C,B,0,233.87,100,130,165945,13206387,233.87,234,4,17,1,2,233.86,234.1,295,100,3,1,233.81,234.13,2,400,2,1,233.8,234.17,105,1,2,1,233.78,234.25,400,100,1,1,233.7,234.38,1200,7,1,1,233.66,234.41,1,500,1,1,233.58,234.43,505,105,2,2,233.53,234.5,10,63,1,4,233.5,234.59,100,60,1,1,GOOG
2024-10-21T12:27:50.063258837Z,2024-10-21T12:27:50.063092822Z,10,2,38,C,A,5,234.38,7,130,166015,13206393,233.87,234,4,17,1,2,233.86,234.1,295,100,3,1,233.81,234.13,2,400,2,1,233.8,234.17,105,1,2,1,233.78,234.25,400,100,1,1,233.7,234.41,1200,500,1,1,233.66,234.43,1,105,1,2,233.58,234.5,505,63,2,4,233.53,234.59,10,60,1,1,233.5,234.75,100,1,1,1,GOOG
2024-10-21T12:27:50.065683975Z,2024-10-21T12:27:50.065517946Z,10,2,38,C,B,0,233.87,4,130,166029,13206394,233.86,234,295,17,3,2,233.81,234.1,2,100,2,1,233.8,234.13,105,400,2,1,233.78,234.17,400,1,1,1,233.7,234.25,1200,100,1,1,233.66,234.41,1,500,1,1,233.58,234.43,505,105,2,2,233.53,234.5,10,63,1,4,233.5,234.59,100,60,1,1,233.45,234.75,15,1,1,1,GOOG
2024-10-21T12:27:50.072777187Z,2024-10-21T12:27:50.072608485Z,10,2,38,T,N,0,233.92,250,0,168702,13206395,233.86,234,295,17,3,2,233.81,234.1,2,100,2,1,233.8,234.13,105,400,2,1,233.78,234.17,400,1,1,1,233.7,234.25,1200,100,1,1,233.66,234.41,1,500,1,1,233.58,234.43,505,105,2,2,233.53,234.5,10,63,1,4,233.5,234.59,100,60,1,1,233.45,234.75,15,1,1,1,GOOG
2024-10-21T12:27:50.072777187Z,2024-10-21T12:27:50.072608485Z,10,2,38,T,N,0,233.87,73,130,168702,13206396,233.86,234,295,17,3,2,233.81,234.1,2,100,2,1,233.8,234.13,105,400,2,1,233.78,234.17,400,1,1,1,233.7,234.25,1200,100,1,1,233.66,234.41,1,500,1,1,233.58,234.43,505,105,2,2,233.53,234.5,10,63,1,4,233.5,234.59,100,60,1,1,233.45,234.75,15,1,1,1,GOOG
2024-10-21T12:27:50.167562575Z,2024-10-21T12:27:50.167395987Z,10,2,38,A,A,1,234.06,200,130,166588,13206479,233.86,234,295,17,3,2,233.81,234.06,2,200,2,1,233.8,234.1,105,100,2,1,233.78,234.13,400,400,1,1,233.7,234.17,1200,1,1,1,233.66,234.25,1,100,1,1,233.58,234.41,505,500,2,1,233.53,234.43,10,105,1,2,233.5,234.5,100,63,1,4,233.45,234.59,15,60,1,1,GOOG
2024-10-21T12:27:51.736371710Z,2024-10-21T12:27:51.736205355Z,10,2,38,A,A,1,234.06,200,130,166355,13207413,233.86,234,295,17,3,2,233.81,234.06,2,400,2,2,233.8,234.1,105,100,2,1,233.78,234.13,400,400,1,1,233.7,234.17,1200,1,1,1,233.66,234.25,1,100,1,1,233.58,234.41,505,500,2,1,233.53,234.43,10,105,1,2,233.5,234.5,100,63,1,4,233.45,234.59,15,60,1,1,GOOG
2024-10-21T12:27:51.790967984Z,2024-10-21T12:27:51.790801843Z,10,2,38,C,A,1,234.06,200,130,166141,13207602,233.86,234,295,17,3,2,233.81,234.06,2,200,2,1,233.8,234.1,105,100,2,1,233.78,234.13,400,400,1,1,233.7,234.17,1200,1,1,1,233.66,234.25,1,100,1,1,233.58,234.41,505,500,2,1,233.53,234.43,10,105,1,2,233.5,234.5,100,63,1,4,233.45,234.59,15,60,1,1,GOOG
2024-10-21T12:27:51.790980861Z,2024-10-21T12:27:51.790814229Z,10,2,38,A,A,1,234.05,200,130,166632,13207603,233.86,234,295,17,3,2,233.81,234.05,2,200,2,1,233.8,234.1,105,100,2,1,233.78,234.13,400,400,1,1,233.7,234.17,1200,1,1,1,233.66,234.25,1,100,1,1,233.58,234.41,505,500,2,1,233.53,234.43,10,105,1,2,233.5,234.5,100,63,1,4,233.45,234.59,15,60,1,1,GOOG
2024-10-21T12:27:52.065722099Z,2024-10-21T12:27:52.065555514Z,10,2,38,A,A,6,234.41,7,130,166585,13207879,233.86,234,295,17,3,2,233.81,234.05,2,200,2,1,233.8,234.1,105,100,2,1,233.78,234.13,400,400,1,1,233.7,234.17,1200,1,1,1,233.66,234.25,1,100,1,1,233.58,234.41,505,507,2,2,233.53,234.43,10,105,1,2,233.5,234.5,100,63,1,4,233.45,234.59,15,60,1,1,GOOG
2024-10-21T12:27:52.393306163Z,2024-10-21T12:27:52.393140055Z,10,2,38,A,B,0,233.91,100,130,166108,13208151,233.91,234,100,17,1,2,233.86,234.05,295,200,3,1,233.81,234.1,2,100,2,1,233.8,234.13,105,400,2,1,233.78,234.17,400,1,1,1,233.7,234.25,1200,100,1,1,233.66,234.41,1,507,1,2,233.58,234.43,505,105,2,2,233.53,234.5,10,63,1,4,233.5,234.59,100,60,1,1,GOOG
2024-10-21T12:27:52.393974163Z,2024-10-21T12:27:52.393807534Z,10,2,38,C,B,0,233.91,100,130,166629,13208153,233.86,234,295,17,3,2,233.81,234.05,2,200,2,1,233.8,234.1,105,100,2,1,233.78,234.13,400,400,1,1,233.7,234.17,1200,1,1,1,233.66,234.25,1,100,1,1,233.58,234.41,505,507,2,2,233.53,234.43,10,105,1,2,233.5,234.5,100,63,1,4,233.45,234.59,15,60,1,1,GOOG
2024-10-21T12:27:53.197081371Z,2024-10-21T12:27:53.196914522Z,10,2,38,A,B,1,233.81,200,130,166849,13208530,233.86,234,295,17,3,2,233.81,234.05,202,200,3,1,233.8,234.1,105,100,2,1,233.7,234.13,1200,400,1,1,233.66,234.17,1,1,1,1,233.58,234.25,505,100,2,1,233.53,234.41,10,507,1,2,233.5,234.43,100,105,1,2,233.45,234.5,15,63,1,4,233.4,234.59,110,60,2,1,GOOG
2024-10-21T12:27:55.777527005Z,2024-10-21T12:27:55.777360755Z,10,2,38,A,B,1,233.82,200,130,166250,13210010,233.86,234,295,17,3,2,233.82,234.05,200,200,1,1,233.81,234.1,2,100,2,1,233.8,234.13,105,400,2,1,233.7,234.17,1200,1,1,1,233.66,234.25,1,100,1,1,233.58,234.41,505,507,2,2,233.53,234.43,10,105,1,2,233.5,234.5,100,63,1,4,233.45,234.59,15,60,1,1,GOOG
2024-10-21T12:27:57.069810253Z,2024-10-21T12:27:57.069644133Z,10,2,38,C,A,6,234.41,7,130,166120,13211098,233.86,234,295,17,3,2,233.82,234.05,200,200,1,1,233.81,234.1,2,100,2,1,233.8,234.13,105,400,2,1,233.7,234.17,1200,1,1,1,233.66,234.25,1,100,1,1,233.58,234.41,505,500,2,1,233.53,234.43,10,105,1,2,233.5,234.5,100,63,1,4,233.45,234.59,15,60,1,1,GOOG
2024-10-21T12:27:59.075099035Z,2024-10-21T12:27:59.074932933Z,10,2,38,A,A,2,234.08,7,130,166102,13212016,233.86,234,295,17,3,2,233.82,234.05,200,200,1,1,233.81,234.08,2,7,2,1,233.8,234.1,105,100,2,1,233.7,234.13,1200,400,1,1,233.66,234.17,1,1,1,1,233.58,234.25,505,100,2,1,233.53,234.41,10,500,1,1,233.5,234.43,100,105,1,2,233.45,234.5,15,63,1,4,GOOG
2024-10-21T12:28:13.140654755Z,2024-10-21T12:28:13.140488443Z,10,2,38,C,A,2,234.08,7,130,166312,13223358,233.86,234,295,17,3,2,233.82,234.05,200,200,1,1,233.81,234.1,2,100,2,1,233.8,234.13,105,400,2,1,233.7,234.17,1200,1,1,1,233.66,234.25,1,100,1,1,233.58,234.41,505,500,2,1,233.53,234.43,10,105,1,2,233.5,234.5,100,63,1,4,233.45,234.59,15,60,1,1,GOOG
2024-10-21T12:28:13.787785757Z,2024-10-21T12:28:13.787619066Z,10,2,38,C,B,0,233.86,100,130,166691,13223694,233.86,234,195,17,2,2,233.82,234.05,200,200,1,1,233.81,234.1,2,100,2,1,233.8,234.13,105,400,2,1,233.7,234.17,1200,1,1,1,233.66,234.25,1,100,1,1,233.58,234.41,505,500,2,1,233.53,234.43,10,105,1,2,233.5,234.5,100,63,1,4,233.45,234.59,15,60,1,1,GOOG
2024-10-21T12:28:15.143565718Z,2024-10-21T12:28:15.143399309Z,10,2,38,A,A,2,234.07,7,130,166409,13224881,233.86,234,195,17,2,2,233.82,234.05,200,200,1,1,233.81,234.07,2,7,2,1,233.8,234.1,105,100,2,1,233.7,234.13,1200,400,1,1,233.66,234.17,1,1,1,1,233.58,234.25,505,100,2,1,233.53,234.41,10,500,1,1,233.5,234.43,100,105,1,2,233.45,234.5,15,63,1,4,GOOG
2024-10-21T12:28:15.998678832Z,2024-10-21T12:28:15.998512488Z,10,2,38,A,A,1,234.05,200,130,166344,13225383,233.86,234,195,17,2,2,233.82,234.05,200,400,1,2,233.81,234.07,2,7,2,1,233.8,234.1,105,100,2,1,233.7,234.13,1200,400,1,1,233.66,234.17,1,1,1,1,233.58,234.25,505,100,2,1,233.53,234.41,10,500,1,1,233.5,234.43,100,105,1,2,233.45,234.5,15,63,1,4,GOOG
2024-10-21T12:28:16.004651224Z,2024-10-21T12:28:16.004484708Z,10,2,38,C,A,1,234.05,200,130,166516,13225389,233.86,234,195,17,2,2,233.82,234.05,200,200,1,1,233.81,234.07,2,7,2,1,233.8,234.1,105,100,2,1,233.7,234.13,1200,400,1,1,233.66,234.17,1,1,1,1,233.58,234.25,505,100,2,1,233.53,234.41,10,500,1,1,233.5,234.43,100,105,1,2,233.45,234.5,15,63,1,4,GOOG
2024-10-21T12:28:16.009541505Z,2024-10-21T12:28:16.009375121Z,10,2,38,A,A,1,234.05,200,130,166384,13225390,233.86,234,195,17,2,2,233.82,234.05,200,400,1,2,233.81,234.07,2,7,2,1,233.8,234.1,105,100,2,1,233.7,234.13,1200,400,1,1,233.66,234.17,1,1,1,1,233.58,234.25,505,100,2,1,233.53,234.41,10,500,1,1,233.5,234.43,100,105,1,2,233.45,234.5,15,63,1,4,GOOG
2024-10-21T12:28:18.439960157Z,2024-10-21T12:28:18.439793678Z,10,2,38,C,B,1,233.82,200,130,166479,13226392,233.86,234,195,17,2,2,233.81,234.05,2,400,2,2,233.8,234.07,105,7,2,1,233.7,234.1,1200,100,1,1,233.66,234.13,1,400,1,1,233.58,234.17,505,1,2,1,233.53,234.25,10,100,1,1,233.5,234.41,100,500,1,1,233.45,234.43,15,105,1,2,233.4,234.5,110,63,2,4,GOOG
2024-10-21T12:28:18.439973348Z,2024-10-21T12:28:18.439806868Z,10,2,38,A,B,3,233.77,400,130,166480,13226393,233.86,234,195,17,2,2,233.81,234.05,2,400,2,2,233.8,234.07,105,7,2,1,233.77,234.1,400,100,1,1,233.7,234.13,1200,400,1,1,233.66,234.17,1,1,1,1,233.58,234.25,505,100,2,1,233.53,234.41,10,500,1,1,233.5,234.43,100,105,1,2,233.45,234.5,15,63,1,4,GOOG
2024-10-21T12:28:18.595699607Z,2024-10-21T12:28:18.595532956Z,10,2,38,A,B,3,233.78,400,130,166651,13226507,233.86,234,195,17,2,2,233.81,234.05,2,400,2,2,233.8,234.07,105,7,2,1,233.78,234.1,400,100,1,1,233.7,234.13,1200,400,1,1,233.66,234.17,1,1,1,1,233.58,234.25,505,100,2,1,233.53,234.41,10,500,1,1,233.5,234.43,100,105,1,2,233.45,234.5,15,63,1,4,GOOG
2024-10-21T12:28:21.754746040Z,2024-10-21T12:28:21.754579574Z,10,2,38,C,A,1,234.05,200,130,166466,13230028,233.86,234,195,17,2,2,233.81,234.05,2,200,2,1,233.8,234.07,105,7,2,1,233.78,234.1,400,100,1,1,233.7,234.13,1200,400,1,1,233.66,234.17,1,1,1,1,233.58,234.25,505,100,2,1,233.53,234.41,10,500,1,1,233.5,234.43,100,105,1,2,233.45,234.5,15,63,1,4,GOOG
2024-10-21T12:28:21.754755709Z,2024-10-21T12:28:21.754589712Z,10,2,38,C,A,1,234.05,200,130,165997,13230029,233.86,234,195,17,2,2,233.81,234.07,2,7,2,1,233.8,234.1,105,100,2,1,233.78,234.13,400,400,1,1,233.7,234.17,1200,1,1,1,233.66,234.25,1,100,1,1,233.58,234.41,505,500,2,1,233.53,234.43,10,105,1,2,233.5,234.5,100,63,1,4,233.45,234.59,15,60,1,1,GOOG
2024-10-21T12:28:21.754767171Z,2024-10-21T12:28:21.754600821Z,10,2,38,A,A,1,234.07,400,130,166350,13230030,233.86,234,195,17,2,2,233.81,234.07,2,407,2,2,233.8,234.1,105,100,2,1,233.78,234.13,400,400,1,1,233.7,234.17,1200,1,1,1,233.66,234.25,1,100,1,1,233.58,234.41,505,500,2,1,233.53,234.43,10,105,1,2,233.5,234.5,100,63,1,4,233.45,234.59,15,60,1,1,GOOG
2024-10-21T12:28:21.805412137Z,2024-10-21T12:28:21.805245495Z,10,2,38,A,B,3,233.79,400,130,166642,13230137,233.86,234,195,17,2,2,233.81,234.07,2,407,2,2,233.8,234.1,105,100,2,1,233.79,234.13,400,400,1,1,233.7,234.17,1200,1,1,1,233.66,234.25,1,100,1,1,233.58,234.41,505,500,2,1,233.53,234.43,10,105,1,2,233.5,234.5,100,63,1,4,233.45,234.59,15,60,1,1,GOOG
2024-10-21T12:28:21.865391217Z,2024-10-21T12:28:21.865225042Z,10,2,38,C,B,3,233.79,200,130,166175,13230295,233.86,234,195,17,2,2,233.81,234.07,2,407,2,2,233.8,234.1,105,100,2,1,233.79,234.13,200,400,1,1,233.7,234.17,1200,1,1,1,233.66,234.25,1,100,1,1,233.58,234.41,505,500,2,1,233.53,234.43,10,105,1,2,233.5,234.5,100,63,1,4,233.45,234.59,15,60,1,1,GOOG
2024-10-21T12:28:32.979289251Z,2024-10-21T12:28:32.979122877Z,10,2,38,A,B,2,233.8,200,130,166374,13238520,233.86,234,195,17,2,2,233.81,234.07,2,407,2,2,233.8,234.1,305,100,3,1,233.7,234.13,1200,400,1,1,233.66,234.17,1,1,1,1,233.58,234.25,505,100,2,1,233.53,234.41,10,500,1,1,233.5,234.43,100,105,1,2,233.45,234.5,15,63,1,4,233.4,234.59,110,60,2,1,GOOG
2024-10-21T12:28:35.114875495Z,2024-10-21T12:28:35.114709429Z,10,2,38,C,B,2,233.8,200,130,166066,13241058,233.86,234,195,17,2,2,233.81,234.07,2,407,2,2,233.8,234.1,105,100,2,1,233.7,234.13,1200,400,1,1,233.66,234.17,1,1,1,1,233.58,234.25,505,100,2,1,233.53,234.41,10,500,1,1,233.5,234.43,100,105,1,2,233.45,234.5,15,63,1,4,233.4,234.59,110,60,2,1,GOOG
2024-10-21T12:28:35.114888161Z,2024-10-21T12:28:35.114721686Z,10,2,38,A,B,3,233.78,200,130,166475,13241059,233.86,234,195,17,2,2,233.81,234.07,2,407,2,2,233.8,234.1,105,100,2,1,233.78,234.13,200,400,1,1,233.7,234.17,1200,1,1,1,233.66,234.25,1,100,1,1,233.58,234.41,505,500,2,1,233.53,234.43,10,105,1,2,233.5,234.5,100,63,1,4,233.45,234.59,15,60,1,1,GOOG
2024-10-21T12:28:35.213164931Z,2024-10-21T12:28:35.212998331Z,10,2,38,A,A,1,234.06,400,130,166600,13241339,233.86,234,195,17,2,2,233.81,234.06,2,400,2,1,233.8,234.07,105,7,2,1,233.78,234.1,200,100,1,1,233.7,234.13,1200,400,1,1,233.66,234.17,1,1,1,1,233.58,234.25,505,100,2,1,233.53,234.41,10,500,1,1,233.5,234.43,100,105,1,2,233.45,234.5,15,63,1,4,GOOG
2024-10-21T12:28:35.345220081Z,2024-10-21T12:28:35.345053997Z,10,2,38,A,B,3,233.78,200,130,166084,13241459,233.86,234,195,17,2,2,233.81,234.06,2,400,2,1,233.8,234.07,105,7,2,1,233.78,234.1,400,100,2,1,233.7,234.13,1200,400,1,1,233.66,234.17,1,1,1,1,233.58,234.25,505,100,2,1,233.53,234.41,10,500,1,1,233.5,234.43,100,105,1,2,233.45,234.5,15,63,1,4,GOOG
2024-10-21T12:28:42.162258578Z,2024-10-21T12:28:42.162092040Z,10,2,38,C,B,3,233.78,200,130,166538,13247773,233.86,234,195,17,2,2,233.81,234.06,2,400,2,1,233.8,234.07,105,7,2,1,233.78,234.1,200,100,1,1,233.7,234.13,1200,400,1,1,233.66,234.17,1,1,1,1,233.58,234.25,505,100,2,1,233.53,234.41,10,500,1,1,233.5,234.43,100,105,1,2,233.45,234.5,15,63,1,4,GOOG
2024-10-21T12:28:42.162271836Z,2024-10-21T12:28:42.162105350Z,10,2,38,A,B,1,233.82,200,130,166486,13247774,233.86,234,195,17,2,2,233.82,234.06,200,400,1,1,233.81,234.07,2,7,2,1,233.8,234.1,105,100,2,1,233.7,234.13,1200,400,1,1,233.66,234.17,1,1,1,1,233.58,234.25,505,100,2,1,233.53,234.41,10,500,1,1,233.5,234.43,100,105,1,2,233.45,234.5,15,63,1,4,GOOG
2024-10-21T12:28:45.429450324Z,2024-10-21T12:28:45.429284120Z,10,2,38,C,B,1,233.82,200,130,166204,13250330,233.86,234,195,17,2,2,233.81,234.06,2,400,2,1,233.8,234.07,105,7,2,1,233.7,234.1,1200,100,1,1,233.66,234.13,1,400,1,1,233.58,234.17,505,1,2,1,233.53,234.25,10,100,1,1,233.5,234.41,100,500,1,1,233.45,234.43,15,105,1,2,233.4,234.5,110,63,2,4,GOOG
2024-10-21T12:28:45.429463288Z,2024-10-21T12:28:45.429297045Z,10,2,38,A,B,3,233.78,400,130,166243,13250331,233.86,234,195,17,2,2,233.81,234.06,2,400,2,1,233.8,234.07,105,7,2,1,233.78,234.1,400,100,1,1,233.7,234.13,1200,400,1,1,233.66,234.17,1,1,1,1,233.58,234.25,505,100,2,1,233.53,234.41,10,500,1,1,233.5,234.43,100,105,1,2,233.45,234.5,15,63,1,4,GOOG
2024-10-21T12:28:48.483286864Z,2024-10-21T12:28:48.483119828Z,10,2,38,A,B,1,233.82,200,130,167036,13252635,233.86,234,195,17,2,2,233.82,234.06,200,400,1,1,233.81,234.07,2,7,2,1,233.8,234.1,105,100,2,1,233.7,234.13,1200,400,1,1,233.66,234.17,1,1,1,1,233.58,234.25,505,100,2,1,233.53,234.41,10,500,1,1,233.5,234.43,100,105,1,2,233.45,234.5,15,63,1,4,GOOG
2024-10-21T12:28:55.560984753Z,2024-10-21T12:28:55.560815833Z,10,2,38,T,A,0,233.86,10,0,168920,13258219,233.86,234,195,17,2,2,233.82,234.06,200,400,1,1,233.81,234.07,2,7,2,1,233.8,234.1,105,100,2,1,233.7,234.13,1200,400,1,1,233.66,234.17,1,1,1,1,233.58,234.25,505,100,2,1,233.53,234.41,10,500,1,1,233.5,234.43,100,105,1,2,233.45,234.5,15,63,1,4,GOOG
2024-10-21T12:28:55.560984753Z,2024-10-21T12:28:55.560817191Z,10,2,38,A,N,0,233.9,100,130,167562,13258220,233.86,233.9,185,100,2,1,233.82,234,200,17,1,2,233.81,234.06,2,400,2,1,233.8,234.07,105,7,2,1,233.7,234.1,1200,100,1,1,233.66,234.13,1,400,1,1,233.58,234.17,505,1,2,1,233.53,234.25,10,100,1,1,233.5,234.41,100,500,1,1,233.45,234.43,15,105,1,2,GOOG
2024-10-21T12:28:55.561007655Z,2024-10-21T12:28:55.560841422Z,10,2,38,A,A,0,233.9,100,130,166233,13258221,233.86,233.9,185,200,2,2,233.82,234,200,17,1,2,233.81,234.06,2,400,2,1,233.8,234.07,105,7,2,1,233.7,234.1,1200,100,1,1,233.66,234.13,1,400,1,1,233.58,234.17,505,1,2,1,233.53,234.25,10,100,1,1,233.5,234.41,100,500,1,1,233.45,234.43,15,105,1,2,GOOG
2024-10-21T12:28:55.561058773Z,2024-10-21T12:28:55.560892756Z,10,2,38,C,B,1,233.82,200,130,166017,13258225,233.86,233.9,185,200,2,2,233.81,234,2,17,2,2,233.8,234.06,105,400,2,1,233.7,234.07,1200,7,1,1,233.66,234.1,1,100,1,1,233.58,234.13,505,400,2,1,233.53,234.17,10,1,1,1,233.5,234.25,100,100,1,1,233.45,234.41,15,500,1,1,233.4,234.43,110,105,2,2,GOOG
2024-10-21T12:28:55.561286132Z,2024-10-21T12:28:55.561120579Z,10,2,38,C,A,0,233.9,100,130,165553,13258227,233.86,233.9,185,100,2,1,233.81,234,2,17,2,2,233.8,234.06,105,400,2,1,233.7,234.07,1200,7,1,1,233.66,234.1,1,100,1,1,233.58,234.13,505,400,2,1,233.53,234.17,10,1,1,1,233.5,234.25,100,100,1,1,233.45,234.41,15,500,1,1,233.4,234.43,110,105,2,2,GOOG
2024-10-21T12:28:55.561361290Z,2024-10-21T12:28:55.561195478Z,10,2,38,C,A,0,233.9,100,130,165812,13258228,233.86,234,185,17,2,2,233.81,234.06,2,400,2,1,233.8,234.07,105,7,2,1,233.7,234.1,1200,100,1,1,233.66,234.13,1,400,1,1,233.58,234.17,505,1,2,1,233.53,234.25,10,100,1,1,233.5,234.41,100,500,1,1,233.45,234.43,15,105,1,2,233.4,234.5,110,63,2,4,GOOG
2024-10-21T12:28:55.562326440Z,2024-10-21T12:28:55.562160475Z,10,2,38,C,A,2,234.07,7,130,165965,13258230,233.86,234,185,17,2,2,233.81,234.06,2,400,2,1,233.8,234.1,105,100,2,1,233.7,234.13,1200,400,1,1,233.66,234.17,1,1,1,1,233.58,234.25,505,100,2,1,233.53,234.41,10,500,1,1,233.5,234.43,100,105,1,2,233.45,234.5,15,63,1,4,233.4,234.59,110,60,2,1,GOOG
2024-10-21T12:28:55.639858396Z,2024-10-21T12:28:55.639691686Z,10,2,38,A,B,3,233.72,400,130,166710,13258325,233.86,234,185,17,2,2,233.81,234.06,2,400,2,1,233.8,234.1,105,100,2,1,233.72,234.13,400,400,1,1,233.7,234.17,1200,1,1,1,233.66,234.25,1,100,1,1,233.58,234.41,505,500,2,1,233.53,234.43,10,105,1,2,233.5,234.5,100,63,1,4,233.45,234.59,15,60,1,1,GOOG
2024-10-21T12:28:55.964596099Z,2024-10-21T12:28:55.964429174Z,10,2,38,A,B,3,233.75,200,130,166925,13258541,233.86,234,185,17,2,2,233.81,234.06,2,400,2,1,233.8,234.1,105,100,2,1,233.75,234.13,200,400,1,1,233.7,234.17,1200,1,1,1,233.66,234.25,1,100,1,1,233.58,234.41,505,500,2,1,233.53,234.43,10,105,1,2,233.5,234.5,100,63,1,4,233.45,234.59,15,60,1,1,GOOG
2024-10-21T12:28:56.442773675Z,2024-10-21T12:28:56.442607241Z,10,2,38,A,A,1,234.05,400,130,166434,13258927,233.86,234,185,17,2,2,233.81,234.05,2,400,2,1,233.8,234.1,105,100,2,1,233.75,234.13,200,400,1,1,233.7,234.17,1200,1,1,1,233.66,234.25,1,100,1,1,233.58,234.41,505,500,2,1,233.53,234.43,10,105,1,2,233.5,234.5,100,63,1,4,233.45,234.59,15,60,1,1,GOOG
2024-10-21T12:28:57.565514672Z,2024-10-21T12:28:57.565348157Z,10,2,38,A,A,2,234.07,7,130,166515,13259953,233.86,234,185,17,2,2,233.81,234.05,2,400,2,1,233.8,234.07,105,7,2,1,233.75,234.1,200,100,1,1,233.7,234.13,1200,400,1,1,233.66,234.17,1,1,1,1,233.58,234.25,505,100,2,1,233.53,234.41,10,500,1,1,233.5,234.43,100,105,1,2,233.45,234.5,15,63,1,4,GOOG
2024-10-21T12:28:57.831005951Z,2024-10-21T12:28:57.830839869Z,10,2,38,A,A,1,234.01,200,130,166082,13260122,233.86,234,185,17,2,2,233.81,234.01,2,200,2,1,233.8,234.07,105,7,2,1,233.75,234.1,200,100,1,1,233.7,234.13,1200,400,1,1,233.66,234.17,1,1,1,1,233.58,234.25,505,100,2,1,233.53,234.41,10,500,1,1,233.5,234.43,100,105,1,2,233.45,234.5,15,63,1,4,GOOG
2024-10-21T12:28:57.891061549Z,2024-10-21T12:28:57.890894861Z,10,2,38,A,A,0,234,200,130,166688,13260139,233.86,234,185,217,2,3,233.81,234.07,2,7,2,1,233.8,234.1,105,100,2,1,233.75,234.13,200,400,1,1,233.7,234.17,1200,1,1,1,233.66,234.25,1,100,1,1,233.58,234.41,505,500,2,1,233.53,234.43,10,105,1,2,233.5,234.5,100,63,1,4,233.45,234.59,15,60,1,1,GOOG
2024-10-21T12:28:58.006126423Z,2024-10-21T12:28:58.005959828Z,10,2,38,A,A,0,233.99,200,130,166595,13260238,233.86,233.99,185,200,2,1,233.81,234,2,17,2,2,233.8,234.07,105,7,2,1,233.75,234.1,200,100,1,1,233.7,234.13,1200,400,1,1,233.66,234.17,1,1,1,1,233.58,234.25,505,100,2,1,233.53,234.41,10,500,1,1,233.5,234.43,100,105,1,2,233.45,234.5,15,63,1,4,GOOG
2024-10-21T12:28:58.694606149Z,2024-10-21T12:28:58.694439582Z,10,2,38,A,B,1,233.81,200,130,166567,13260587,233.86,233.99,185,200,2,1,233.81,234,202,17,3,2,233.8,234.07,105,7,2,1,233.7,234.1,1200,100,1,1,233.66,234.13,1,400,1,1,233.58,234.17,505,1,2,1,233.53,234.25,10,100,1,1,233.5,234.41,100,500,1,1,233.45,234.43,15,105,1,2,233.4,234.5,110,63,2,4,GOOG
2024-10-21T12:29:01.022290262Z,2024-10-21T12:29:01.022123658Z,10,2,38,C,B,1,233.81,200,130,166604,13262995,233.86,233.99,185,200,2,1,233.81,234,2,17,2,2,233.8,234.07,105,7,2,1,233.7,234.1,1200,100,1,1,233.66,234.13,1,400,1,1,233.58,234.17,505,1,2,1,233.53,234.25,10,100,1,1,233.5,234.41,100,500,1,1,233.45,234.43,15,105,1,2,233.4,234.5,110,63,2,4,GOOG
2024-10-21T12:29:01.022303152Z,2024-10-21T12:29:01.022136915Z,10,2,38,A,B,3,233.76,400,130,166237,13262996,233.86,233.99,185,200,2,1,233.81,234,2,17,2,2,233.8,234.07,105,7,2,1,233.76,234.1,400,100,1,1,233.7,234.13,1200,400,1,1,233.66,234.17,1,1,1,1,233.58,234.25,505,100,2,1,233.53,234.41,10,500,1,1,233.5,234.43,100,105,1,2,233.45,234.5,15,63,1,4,GOOG
2024-10-21T12:29:01.158549246Z,2024-10-21T12:29:01.158380499Z,10,2,38,T,A,0,233.86,85,0,168747,13263131,233.86,233.99,185,200,2,1,233.81,234,2,17,2,2,233.8,234.07,105,7,2,1,233.76,234.1,400,100,1,1,233.7,234.13,1200,400,1,1,233.66,234.17,1,1,1,1,233.58,234.25,505,100,2,1,233.53,234.41,10,500,1,1,233.5,234.43,100,105,1,2,233.45,234.5,15,63,1,4,GOOG
2024-10-21T12:29:01.158549246Z,2024-10-21T12:29:01.158380499Z,10,2,38,T,A,0,233.86,100,130,168747,13263132,233.86,233.99,100,200,1,1,233.81,234,2,17,2,2,233.8,234.07,105,7,2,1,233.76,234.1,400,100,1,1,233.7,234.13,1200,400,1,1,233.66,234.17,1,1,1,1,233.58,234.25,505,100,2,1,233.53,234.41,10,500,1,1,233.5,234.43,100,105,1,2,233.45,234.5,15,63,1,4,GOOG
2024-10-21T12:29:01.158549246Z,2024-10-21T12:29:01.158380499Z,10,2,38,C,B,0,233.86,100,130,168747,13263132,233.81,233.99,2,200,2,1,233.8,234,105,17,2,2,233.76,234.07,400,7,1,1,233.7,234.1,1200,100,1,1,233.66,234.13,1,400,1,1,233.58,234.17,505,1,2,1,233.53,234.25,10,100,1,1,233.5,234.41,100,500,1,1,233.45,234.43,15,105,1,2,233.4,234.5,110,63,2,4,GOOG
2024-10-21T12:29:01.158567848Z,2024-10-21T12:29:01.158396024Z,10,2,38,A,B,0,233.86,100,128,171824,13263141,233.86,233.99,100,200,1,1,233.81,234,2,17,2,2,233.8,234.07,105,7,2,1,233.76,234.1,400,100,1,1,233.7,234.13,1200,400,1,1,233.66,234.17,1,1,1,1,233.58,234.25,505,100,2,1,233.53,234.41,10,500,1,1,233.5,234.43,100,105,1,2,233.45,234.5,15,63,1,4,GOOG
2024-10-21T12:29:01.158571366Z,2024-10-21T12:29:01.158404180Z,10,2,38,A,A,0,233.92,100,130,167186,13263148,233.86,233.92,100,100,1,1,233.81,233.99,2,200,2,1,233.8,234,105,17,2,2,233.76,234.07,400,7,1,1,233.7,234.1,1200,100,1,1,233.66,234.13,1,400,1,1,233.58,234.17,505,1,2,1,233.53,234.25,10,100,1,1,233.5,234.41,100,500,1,1,233.45,234.43,15,105,1,2,GOOG
2024-10-21T12:29:01.158576809Z,2024-10-21T12:29:01.158408745Z,10,2,38,A,A,1,233.96,100,128,168064,13263151,233.86,233.92,100,100,1,1,233.81,233.93,2,130,2,1,233.8,233.96,105,100,2,1,233.76,233.99,400,200,1,1,233.7,234,1200,17,1,2,233.66,234.07,1,7,1,1,233.58,234.1,505,100,2,1,233.53,234.13,10,400,1,1,233.5,234.17,100,1,1,1,233.45,234.25,15,100,1,1,GOOG
2024-10-21T12:29:01.158585584Z,2024-10-21T12:29:01.158418184Z,10,2,38,A,A,0,233.92,100,128,167400,13263156,233.86,233.92,100,200,1,2,233.81,233.93,2,130,2,1,233.8,233.96,105,100,2,1,233.76,233.99,400,200,1,1,233.7,234,1200,17,1,2,233.66,234.07,1,7,1,1,233.58,234.1,505,100,2,1,233.53,234.13,10,400,1,1,233.5,234.17,100,1,1,1,233.45,234.25,15,100,1,1,GOOG
2024-10-21T12:29:01.158586865Z,2024-10-21T12:29:01.158419809Z,10,2,38,A,A,2,233.96,100,130,167056,13263158,233.86,233.92,100,200,1,2,233.81,233.93,2,130,2,1,233.8,233.96,105,200,2,2,233.76,233.99,400,200,1,1,233.7,234,1200,17,1,2,233.66,234.07,1,7,1,1,233.58,234.1,505,100,2,1,233.53,234.13,10,400,1,1,233.5,234.17,100,1,1,1,233.45,234.25,15,100,1,1,GOOG
2024-10-21T12:29:01.158590064Z,2024-10-21T12:29:01.158423515Z,10,2,38,A,A,1,233.93,26,130,166549,13263160,233.86,233.92,100,200,1,2,233.81,233.93,2,156,2,2,233.8,233.96,105,200,2,2,233.76,233.99,400,200,1,1,233.7,234,1200,17,1,2,233.66,234.07,1,7,1,1,233.58,234.1,505,100,2,1,233.53,234.13,10,400,1,1,233.5,234.17,100,1,1,1,233.45,234.25,15,100,1,1,GOOG
2024-10-21T12:29:01.158592348Z,2024-10-21T12:29:01.158424717Z,10,2,38,T,A,0,233.86,100,0,167631,13263161,233.86,233.92,100,200,1,2,233.81,233.93,2,156,2,2,233.8,233.96,105,200,2,2,233.76,233.99,400,200,1,1,233.7,234,1200,17,1,2,233.66,234.07,1,7,1,1,233.58,234.1,505,100,2,1,233.53,234.13,10,400,1,1,233.5,234.17,100,1,1,1,233.45,234.25,15,100,1,1,GOOG
2024-10-21T12:29:01.158592348Z,2024-10-21T12:29:01.158424717Z,10,2,38,T,N,0,233.86,150,130,167631,13263162,233.81,233.92,2,200,2,2,233.8,233.93,105,156,2,2,233.76,233.96,400,200,1,2,233.7,233.99,1200,200,1,1,233.66,234,1,17,1,2,233.58,234.07,505,7,2,1,233.53,234.1,10,100,1,1,233.5,234.13,100,400,1,1,233.45,234.17,15,1,1,1,233.4,234.25,110,100,2,1,GOOG
2024-10-21T12:29:01.158594194Z,2024-10-21T12:29:01.158426997Z,10,2,38,T,N,0,233.86,50,0,167197,13263163,233.81,233.92,2,200,2,2,233.8,233.93,105,156,2,2,233.76,233.96,400,200,1,2,233.7,233.99,1200,200,1,1,233.66,234,1,17,1,2,233.58,234.07,505,7,2,1,233.53,234.1,10,100,1,1,233.5,234.13,100,400,1,1,233.45,234.17,15,1,1,1,233.4,234.25,110,100,2,1,GOOG
2024-10-21T12:29:01.158594194Z,2024-10-21T12:29:01.158427442Z,10,2,38,C,A,1,233.93,130,130,166752,13263164,233.81,233.92,2,200,2,2,233.8,233.93,105,26,2,1,233.76,233.96,400,200,1,2,233.7,233.99,1200,200,1,1,233.66,234,1,17,1,2,233.58,234.07,505,7,2,1,233.53,234.1,10,100,1,1,233.5,234.13,100,400,1,1,233.45,234.17,15,1,1,1,233.4,234.25,110,100,2,1,GOOG
2024-10-21T12:29:01.158598557Z,2024-10-21T12:29:01.158431288Z,10,2,38,A,A,2,233.96,100,130,167269,13263165,233.81,233.92,2,200,2,2,233.8,233.93,105,26,2,1,233.76,233.96,400,300,1,3,233.7,233.99,1200,200,1,1,233.66,234,1,17,1,2,233.58,234.07,505,7,2,1,233.53,234.1,10,100,1,1,233.5,234.13,100,400,1,1,233.45,234.17,15,1,1,1,233.4,234.25,110,100,2,1,GOOG
2024-10-21T12:29:01.158601250Z,2024-10-21T12:29:01.158434916Z,10,2,38,A,B,0,233.86,100,130,166334,13263166,233.86,233.92,100,200,1,2,233.81,233.93,2,26,2,1,233.8,233.96,105,300,2,3,233.76,233.99,400,200,1,1,233.7,234,1200,17,1,2,233.66,234.07,1,7,1,1,233.58,234.1,505,100,2,1,233.53,234.13,10,400,1,1,233.5,234.17,100,1,1,1,233.45,234.25,15,100,1,1,GOOG
2024-10-21T12:29:01.158603851Z,2024-10-21T12:29:01.158437825Z,10,2,38,A,A,3,233.97,26,130,166026,13263167,233.86,233.92,100,200,1,2,233.81,233.93,2,26,2,1,233.8,233.96,105,300,2,3,233.76,233.97,400,26,1,1,233.7,233.99,1200,200,1,1,233.66,234,1,17,1,2,233.58,234.07,505,7,2,1,233.53,234.1,10,100,1,1,233.5,234.13,100,400,1,1,233.45,234.17,15,1,1,1,GOOG
2024-10-21T12:29:01.158622043Z,2024-10-21T12:29:01.158453404Z,10,2,38,C,B,3,233.76,400,130,168639,13263171,233.86,233.92,100,200,1,2,233.81,233.93,2,26,2,1,233.8,233.96,105,300,2,3,233.7,233.97,1200,26,1,1,233.66,233.99,1,200,1,1,233.58,234,505,17,2,2,233.53,234.07,10,7,1,1,233.5,234.1,100,100,1,1,233.45,234.13,15,400,1,1,233.4,234.17,110,1,2,1,GOOG
2024-10-21T12:29:01.158626083Z,2024-10-21T12:29:01.158458726Z,10,2,38,C,A,0,233.92,100,128,167357,13263172,233.86,233.92,100,100,1,1,233.81,233.93,2,26,2,1,233.8,233.96,105,300,2,3,233.7,233.97,1200,26,1,1,233.66,233.99,1,200,1,1,233.58,234,505,17,2,2,233.53,234.07,10,7,1,1,233.5,234.1,100,100,1,1,233.45,234.13,15,400,1,1,233.4,234.17,110,1,2,1,GOOG
2024-10-21T12:29:01.158642773Z,2024-10-21T12:29:01.158475713Z,10,2,38,C,A,0,233.92,100,128,167060,13263180,233.86,233.93,100,26,1,1,233.81,233.96,2,300,2,3,233.8,233.97,105,26,2,1,233.7,233.99,1200,200,1,1,233.66,234,1,17,1,2,233.58,234.07,505,7,2,1,233.53,234.1,10,100,1,1,233.5,234.13,100,400,1,1,233.45,234.17,15,1,1,1,233.4,234.25,110,100,2,1,GOOG
2024-10-21T12:29:01.158651784Z,2024-10-21T12:29:01.158485485Z,10,2,38,A,A,0,233.91,26,130,166299,13263183,233.86,233.91,100,26,1,1,233.81,233.93,2,26,2,1,233.8,233.96,105,300,2,3,233.7,233.97,1200,26,1,1,233.66,233.99,1,200,1,1,233.58,234,505,17,2,2,233.53,234.07,10,7,1,1,233.5,234.1,100,100,1,1,233.45,234.13,15,400,1,1,233.4,234.17,110,1,2,1,GOOG
2024-10-21T12:29:01.158666241Z,2024-10-21T12:29:01.158498852Z,10,2,38,T,A,0,233.86,50,128,167389,13263184,233.86,233.91,100,26,1,1,233.81,233.93,2,26,2,1,233.8,233.96,105,300,2,3,233.7,233.97,1200,26,1,1,233.66,233.99,1,200,1,1,233.58,234,505,17,2,2,233.53,234.07,10,7,1,1,233.5,234.1,100,100,1,1,233.45,234.13,15,400,1,1,233.4,234.17,110,1,2,1,GOOG
2024-10-21T12:29:01.158666241Z,2024-10-21T12:29:01.158498852Z,10,2,38,C,B,0,233.86,50,128,167389,13263184,233.86,233.91,50,26,1,1,233.81,233.93,2,26,2,1,233.8,233.96,105,300,2,3,233.7,233.97,1200,26,1,1,233.66,233.99,1,200,1,1,233.58,234,505,17,2,2,233.53,234.07,10,7,1,1,233.5,234.1,100,100,1,1,233.45,234.13,15,400,1,1,233.4,234.17,110,1,2,1,GOOG
2024-10-21T12:29:01.158674864Z,2024-10-21T12:29:01.158508412Z,10,2,38,A,B,0,233.86,100,130,166452,13263188,233.86,233.91,150,26,2,1,233.81,233.93,2,26,2,1,233.8,233.96,105,300,2,3,233.7,233.97,1200,26,1,1,233.66,233.99,1,200,1,1,233.58,234,505,17,2,2,233.53,234.07,10,7,1,1,233.5,234.1,100,100,1,1,233.45,234.13,15,400,1,1,233.4,234.17,110,1,2,1,GOOG
2024-10-21T12:29:01.158688501Z,2024-10-21T12:29:01.158520941Z,10,2,38,T,A,0,233.86,50,0,167560,13263189,233.86,233.91,150,26,2,1,233.81,233.93,2,26,2,1,233.8,233.96,105,300,2,3,233.7,233.97,1200,26,1,1,233.66,233.99,1,200,1,1,233.58,234,505,17,2,2,233.53,234.07,10,7,1,1,233.5,234.1,100,100,1,1,233.45,234.13,15,400,1,1,233.4,234.17,110,1,2,1,GOOG
2024-10-21T12:29:01.158688501Z,2024-10-21T12:29:01.158520941Z,10,2,38,T,A,0,233.86,50,130,167560,13263190,233.86,233.91,100,26,1,1,233.81,233.93,2,26,2,1,233.8,233.96,105,300,2,3,233.7,233.97,1200,26,1,1,233.66,233.99,1,200,1,1,233.58,234,505,17,2,2,233.53,234.07,10,7,1,1,233.5,234.1,100,100,1,1,233.45,234.13,15,400,1,1,233.4,234.17,110,1,2,1,GOOG
2024-10-21T12:29:01.158688501Z,2024-10-21T12:29:01.158520941Z,10,2,38,C,B,0,233.86,50,130,167560,13263190,233.86,233.91,50,26,1,1,233.81,233.93,2,26,2,1,233.8,233.96,105,300,2,3,233.7,233.97,1200,26,1,1,233.66,233.99,1,200,1,1,233.58,234,505,17,2,2,233.53,234.07,10,7,1,1,233.5,234.1,100,100,1,1,233.45,234.13,15,400,1,1,233.4,234.17,110,1,2,1,GOOG
2024-10-21T12:29:01.158696696Z,2024-10-21T12:29:01.158530490Z,10,2,38,C,A,2,233.96,100,130,166206,13263192,233.86,233.91,50,26,1,1,233.81,233.93,2,26,2,1,233.8,233.96,105,200,2,2,233.7,233.97,1200,26,1,1,233.66,233.99,1,200,1,1,233.58,234,505,17,2,2,233.53,234.07,10,7,1,1,233.5,234.1,100,100,1,1,233.45,234.13,15,400,1,1,233.4,234.17,110,1,2,1,GOOG
2024-10-21T12:29:01.158698384Z,2024-10-21T12:29:01.158531815Z,10,2,38,C,B,0,233.96,100,130,166569,13263194,233.86,233.91,150,26,2,1,233.81,233.93,2,26,2,1,233.8,233.96,105,100,2,1,233.7,233.97,1200,26,1,1,233.66,233.99,1,200,1,1,233.58,234,505,17,2,2,233.53,234.07,10,7,1,1,233.5,234.1,100,100,1,1,233.45,234.13,15,400,1,1,233.4,234.17,110,1,2,1,GOOG
2024-10-21T12:29:01.158723924Z,2024-10-21T12:29:01.158554739Z,10,2,38,T,A,0,233.86,50,128,169185,13263197,233.86,233.91,150,26,2,1,233.81,233.93,2,26,2,1,233.8,233.96,105,100,2,1,233.7,233.97,1200,26,1,1,233.66,233.99,1,200,1,1,233.58,234,505,17,2,2,233.53,234.07,10,7,1,1,233.5,234.1,100,100,1,1,233.45,234.13,15,400,1,1,233.4,234.17,110,1,2,1,GOOG
2024-10-21T12:29:01.158723924Z,2024-10-21T12:29:01.158554739Z,10,2,38,C,B,0,233.86,50,128,169185,13263197,233.86,233.91,100,26,1,1,233.81,233.93,2,26,2,1,233.8,233.96,105,100,2,1,233.7,233.97,1200,26,1,1,233.66,233.99,1,200,1,1,233.58,234,505,17,2,2,233.53,234.07,10,7,1,1,233.5,234.1,100,100,1,1,233.45,234.13,15,400,1,1,233.4,234.17,110,1,2,1,GOOG
2024-10-21T12:29:01.159002676Z,2024-10-21T12:29:01.158835732Z,10,2,38,C,A,2,233.96,100,130,166944,13263231,233.86,233.91,100,26,1,1,233.81,233.93,2,26,2,1,233.8,233.97,105,26,2,1,233.7,233.99,1200,200,1,1,233.66,234,1,17,1,2,233.58,234.07,505,7,2,1,233.53,234.1,10,100,1,1,233.5,234.13,100,400,1,1,233.45,234.17,15,1,1,1,233.4,234.25,110,100,2,1,GOOG
2024-10-21T12:29:01.260977964Z,2024-10-21T12:29:01.260812083Z,10,2,38,C,A,2,233.97,26,130,165881,13263664,233.86,233.91,100,26,1,1,233.81,233.93,2,26,2,1,233.8,233.99,105,200,2,1,233.7,234,1200,17,1,2,233.66,234.07,1,7,1,1,233.58,234.1,505,100,2,1,233.53,234.13,10,400,1,1,233.5,234.17,100,1,1,1,233.45,234.25,15,100,1,1,233.4,234.41,110,500,2,1,GOOG
2024-10-21T12:29:01.260986860Z,2024-10-21T12:29:01.260820985Z,10,2,38,C,A,0,233.91,26,130,165875,13263665,233.86,233.93,100,26,1,1,233.81,233.99,2,200,2,1,233.8,234,105,17,2,2,233.7,234.07,1200,7,1,1,233.66,234.1,1,100,1,1,233.58,234.13,505,400,2,1,233.53,234.17,10,1,1,1,233.5,234.25,100,100,1,1,233.45,234.41,15,500,1,1,233.4,234.43,110,105,2,2,GOOG
2024-10-21T12:29:01.261039132Z,2024-10-21T12:29:01.260872777Z,10,2,38,A,B,3,233.74,200,130,166355,13263667,233.86,233.93,100,26,1,1,233.81,233.99,2,200,2,1,233.8,234,105,17,2,2,233.74,234.07,200,7,1,1,233.7,234.1,1200,100,1,1,233.66,234.13,1,400,1,1,233.58,234.17,505,1,2,1,233.53,234.25,10,100,1,1,233.5,234.41,100,500,1,1,233.45,234.43,15,105,1,2,GOOG
2024-10-21T12:29:01.411202852Z,2024-10-21T12:29:01.411037140Z,10,2,38,C,A,0,233.93,26,130,165712,13264096,233.86,233.99,100,200,1,1,233.81,234,2,17,2,2,233.8,234.07,105,7,2,1,233.74,234.1,200,100,1,1,233.7,234.13,1200,400,1,1,233.66,234.17,1,1,1,1,233.58,234.25,505,100,2,1,233.53,234.41,10,500,1,1,233.5,234.43,100,105,1,2,233.45,234.5,15,63,1,4,GOOG
2024-10-21T12:29:01.477305998Z,2024-10-21T12:29:01.477138444Z,10,2,38,T,A,0,233.86,50,130,167554,13264991,233.86,233.99,100,200,1,1,233.81,234,2,17,2,2,233.8,234.07,105,7,2,1,233.74,234.1,200,100,1,1,233.7,234.13,1200,400,1,1,233.66,234.17,1,1,1,1,233.58,234.25,505,100,2,1,233.53,234.41,10,500,1,1,233.5,234.43,100,105,1,2,233.45,234.5,15,63,1,4,GOOG
2024-10-21T12:29:01.477305998Z,2024-10-21T12:29:01.477138444Z,10,2,38,C,B,0,233.86,50,130,167554,13264991,233.86,233.99,50,200,1,1,233.81,234,2,17,2,2,233.8,234.07,105,7,2,1,233.74,234.1,200,100,1,1,233.7,234.13,1200,400,1,1,233.66,234.17,1,1,1,1,233.58,234.25,505,100,2,1,233.53,234.41,10,500,1,1,233.5,234.43,100,105,1,2,233.45,234.5,15,63,1,4,GOOG
2024-10-21T12:29:01.477315667Z,2024-10-21T12:29:01.477149422Z,10,2,38,A,B,0,233.86,100,130,166245,13264992,233.86,233.99,150,200,2,1,233.81,234,2,17,2,2,233.8,234.07,105,7,2,1,233.74,234.1,200,100,1,1,233.7,234.13,1200,400,1,1,233.66,234.17,1,1,1,1,233.58,234.25,505,100,2,1,233.53,234.41,10,500,1,1,233.5,234.43,100,105,1,2,233.45,234.5,15,63,1,4,GOOG
2024-10-21T12:29:01.477365108Z,2024-10-21T12:29:01.477199123Z,10,2,38,C,B,3,233.74,200,130,165985,13264994,233.86,233.99,150,200,2,1,233.81,234,2,17,2,2,233.8,234.07,105,7,2,1,233.7,234.1,1200,100,1,1,233.66,234.13,1,400,1,1,233.58,234.17,505,1,2,1,233.53,234.25,10,100,1,1,233.5,234.41,100,500,1,1,233.45,234.43,15,105,1,2,233.4,234.5,110,63,2,4,GOOG
2024-10-21T12:29:01.541193716Z,2024-10-21T12:29:01.541027344Z,10,2,38,A,B,4,233.66,400,130,166372,13265322,233.86,233.99,150,200,2,1,233.81,234,2,17,2,2,233.8,234.07,105,7,2,1,233.7,234.1,1200,100,1,1,233.66,234.13,401,400,2,1,233.58,234.17,505,1,2,1,233.53,234.25,10,100,1,1,233.5,234.41,100,500,1,1,233.45,234.43,15,105,1,2,233.4,234.5,110,63,2,4,GOOG
2024-10-21T12:29:01.544861244Z,2024-10-21T12:29:01.544694740Z,10,2,38,A,A,0,233.99,200,130,166504,13265329,233.86,233.99,150,400,2,2,233.81,234,2,17,2,2,233.8,234.07,105,7,2,1,233.7,234.1,1200,100,1,1,233.66,234.13,401,400,2,1,233.58,234.17,505,1,2,1,233.53,234.25,10,100,1,1,233.5,234.41,100,500,1,1,233.45,234.43,15,105,1,2,233.4,234.5,110,63,2,4,GOOG
2024-10-21T12:29:01.602737737Z,2024-10-21T12:29:01.602571884Z,10,2,38,C,A,0,233.99,200,130,165853,13265457,233.86,233.99,150,200,2,1,233.81,234,2,17,2,2,233.8,234.07,105,7,2,1,233.7,234.1,1200,100,1,1,233.66,234.13,401,400,2,1,233.58,234.17,505,1,2,1,233.53,234.25,10,100,1,1,233.5,234.41,100,500,1,1,233.45,234.43,15,105,1,2,233.4,234.5,110,63,2,4,GOOG
2024-10-21T12:29:01.602775080Z,2024-10-21T12:29:01.602608635Z,10,2,38,A,A,0,233.94,400,130,166445,13265458,233.86,233.94,150,400,2,1,233.81,234,2,17,2,2,233.8,234.07,105,7,2,1,233.7,234.1,1200,100,1,1,233.66,234.13,401,400,2,1,233.58,234.17,505,1,2,1,233.53,234.25,10,100,1,1,233.5,234.41,100,500,1,1,233.45,234.43,15,105,1,2,233.4,234.5,110,63,2,4,GOOG
2024-10-21T12:29:01.646283514Z,2024-10-21T12:29:01.646117074Z,10,2,38,C,A,0,233.94,400,130,166440,13265552,233.86,234,150,17,2,2,233.81,234.07,2,7,2,1,233.8,234.1,105,100,2,1,233.7,234.13,1200,400,1,1,233.66,234.17,401,1,2,1,233.58,234.25,505,100,2,1,233.53,234.41,10,500,1,1,233.5,234.43,100,105,1,2,233.45,234.5,15,63,1,4,233.4,234.59,110,60,2,1,GOOG
2024-10-21T12:29:01.646296993Z,2024-10-21T12:29:01.646130641Z,10,2,38,A,A,0,233.95,200,130,166352,13265553,233.86,233.95,150,200,2,1,233.81,234,2,17,2,2,233.8,234.07,105,7,2,1,233.7,234.1,1200,100,1,1,233.66,234.13,401,400,2,1,233.58,234.17,505,1,2,1,233.53,234.25,10,100,1,1,233.5,234.41,100,500,1,1,233.45,234.43,15,105,1,2,233.4,234.5,110,63,2,4,GOOG
2024-10-21T12:29:01.700803405Z,2024-10-21T12:29:01.700637009Z,10,2,38,A,B,3,233.71,200,130,166396,13265636,233.86,233.95,150,200,2,1,233.81,234,2,17,2,2,233.8,234.07,105,7,2,1,233.71,234.1,200,100,1,1,233.7,234.13,1200,400,1,1,233.66,234.17,1,1,1,1,233.58,234.25,505,100,2,1,233.53,234.41,10,500,1,1,233.5,234.43,100,105,1,2,233.45,234.5,15,63,1,4,GOOG
2024-10-21T12:29:01.702597558Z,2024-10-21T12:29:01.702431410Z,10,2,38,C,A,0,233.95,200,130,166148,13265638,233.86,234,150,17,2,2,233.81,234.07,2,7,2,1,233.8,234.1,105,100,2,1,233.71,234.13,200,400,1,1,233.7,234.17,1200,1,1,1,233.66,234.25,1,100,1,1,233.58,234.41,505,500,2,1,233.53,234.43,10,105,1,2,233.5,234.5,100,63,1,4,233.45,234.59,15,60,1,1,GOOG
2024-10-21T12:29:01.702610835Z,2024-10-21T12:29:01.702443831Z,10,2,38,A,A,0,233.99,200,130,167004,13265639,233.86,233.99,150,200,2,1,233.81,234,2,17,2,2,233.8,234.07,105,7,2,1,233.71,234.1,200,100,1,1,233.7,234.13,1200,400,1,1,233.66,234.17,1,1,1,1,233.58,234.25,505,100,2,1,233.53,234.41,10,500,1,1,233.5,234.43,100,105,1,2,233.45,234.5,15,63,1,4,GOOG
2024-10-21T12:29:01.829025695Z,2024-10-21T12:29:01.828859341Z,10,2,38,A,B,3,233.71,200,130,166354,13265781,233.86,233.99,150,200,2,1,233.81,234,2,17,2,2,233.8,234.07,105,7,2,1,233.71,234.1,400,100,2,1,233.7,234.13,1200,400,1,1,233.66,234.17,1,1,1,1,233.58,234.25,505,100,2,1,233.53,234.41,10,500,1,1,233.5,234.43,100,105,1,2,233.45,234.5,15,63,1,4,GOOG
2024-10-21T12:29:01.883954105Z,2024-10-21T12:29:01.883788028Z,10,2,38,C,B,3,233.71,200,130,166077,13265824,233.86,233.99,150,200,2,1,233.81,234,2,17,2,2,233.8,234.07,105,7,2,1,233.71,234.1,200,100,1,1,233.7,234.13,1200,400,1,1,233.66,234.17,1,1,1,1,233.58,234.25,505,100,2,1,233.53,234.41,10,500,1,1,233.5,234.43,100,105,1,2,233.45,234.5,15,63,1,4,GOOG
2024-10-21T12:29:01.883967618Z,2024-10-21T12:29:01.883801296Z,10,2,38,A,B,3,233.76,400,130,166322,13265825,233.86,233.99,150,200,2,1,233.81,234,2,17,2,2,233.8,234.07,105,7,2,1,233.76,234.1,400,100,1,1,233.7,234.13,1200,400,1,1,233.66,234.17,1,1,1,1,233.58,234.25,505,100,2,1,233.53,234.41,10,500,1,1,233.5,234.43,100,105,1,2,233.45,234.5,15,63,1,4,GOOG
2024-10-21T12:29:04.074542032Z,2024-10-21T12:29:04.074375510Z,10,2,38,A,B,1,233.81,200,130,166522,13268362,233.86,233.99,150,200,2,1,233.81,234,202,17,3,2,233.8,234.07,105,7,2,1,233.7,234.1,1200,100,1,1,233.66,234.13,1,400,1,1,233.58,234.17,505,1,2,1,233.53,234.25,10,100,1,1,233.5,234.41,100,500,1,1,233.45,234.43,15,105,1,2,233.4,234.5,110,63,2,4,GOOG
2024-10-21T12:29:04.429667694Z,2024-10-21T12:29:04.429500359Z,10,2,38,T,A,0,233.86,3,130,167335,13268523,233.86,233.99,150,200,2,1,233.81,234,202,17,3,2,233.8,234.07,105,7,2,1,233.7,234.1,1200,100,1,1,233.66,234.13,1,400,1,1,233.58,234.17,505,1,2,1,233.53,234.25,10,100,1,1,233.5,234.41,100,500,1,1,233.45,234.43,15,105,1,2,233.4,234.5,110,63,2,4,GOOG
2024-10-21T12:29:04.429667694Z,2024-10-21T12:29:04.429500359Z,10,2,38,C,B,0,233.86,3,130,167335,13268523,233.86,233.99,147,200,2,1,233.81,234,202,17,3,2,233.8,234.07,105,7,2,1,233.7,234.1,1200,100,1,1,233.66,234.13,1,400,1,1,233.58,234.17,505,1,2,1,233.53,234.25,10,100,1,1,233.5,234.41,100,500,1,1,233.45,234.43,15,105,1,2,233.4,234.5,110,63,2,4,GOOG
2024-10-21T12:29:04.493717825Z,2024-10-21T12:29:04.493551721Z,10,2,38,C,B,1,233.81,200,130,166104,13268610,233.86,233.99,147,200,2,1,233.81,234,2,17,2,2,233.8,234.07,105,7,2,1,233.7,234.1,1200,100,1,1,233.66,234.13,1,400,1,1,233.58,234.17,505,1,2,1,233.53,234.25,10,100,1,1,233.5,234.41,100,500,1,1,233.45,234.43,15,105,1,2,233.4,234.5,110,63,2,4,GOOG
2024-10-21T12:29:04.493730953Z,2024-10-21T12:29:04.493564498Z,10,2,38,A,B,3,233.78,200,130,166455,13268611,233.86,233.99,147,200,2,1,233.81,234,2,17,2,2,233.8,234.07,105,7,2,1,233.78,234.1,200,100,1,1,233.7,234.13,1200,400,1,1,233.66,234.17,1,1,1,1,233.58,234.25,505,100,2,1,233.53,234.41,10,500,1,1,233.5,234.43,100,105,1,2,233.45,234.5,15,63,1,4,GOOG
2024-10-21T12:29:04.660589203Z,2024-10-21T12:29:04.660423222Z,10,2,38,C,B,3,233.78,200,130,165981,13268807,233.86,233.99,147,200,2,1,233.81,234,2,17,2,2,233.8,234.07,105,7,2,1,233.7,234.1,1200,100,1,1,233.66,234.13,1,400,1,1,233.58,234.17,505,1,2,1,233.53,234.25,10,100,1,1,233.5,234.41,100,500,1,1,233.45,234.43,15,105,1,2,233.4,234.5,110,63,2,4,GOOG
2024-10-21T12:29:04.660602729Z,2024-10-21T12:29:04.660436269Z,10,2,38,A,B,4,233.66,400,130,166460,13268808,233.86,233.99,147,200,2,1,233.81,234,2,17,2,2,233.8,234.07,105,7,2,1,233.7,234.1,1200,100,1,1,233.66,234.13,401,400,2,1,233.58,234.17,505,1,2,1,233.53,234.25,10,100,1,1,233.5,234.41,100,500,1,1,233.45,234.43,15,105,1,2,233.4,234.5,110,63,2,4,GOOG
2024-10-21T12:29:04.679306243Z,2024-10-21T12:29:04.679139876Z,10,2,38,A,A,0,233.99,200,130,166367,13268819,233.86,233.99,147,400,2,2,233.81,234,2,17,2,2,233.8,234.07,105,7,2,1,233.7,234.1,1200,100,1,1,233.66,234.13,401,400,2,1,233.58,234.17,505,1,2,1,233.53,234.25,10,100,1,1,233.5,234.41,100,500,1,1,233.45,234.43,15,105,1,2,233.4,234.5,110,63,2,4,GOOG
2024-10-21T12:29:04.736956452Z,2024-10-21T12:29:04.736790546Z,10,2,38,C,A,0,233.99,200,130,165906,13268859,233.86,233.99,147,200,2,1,233.81,234,2,17,2,2,233.8,234.07,105,7,2,1,233.7,234.1,1200,100,1,1,233.66,234.13,401,400,2,1,233.58,234.17,505,1,2,1,233.53,234.25,10,100,1,1,233.5,234.41,100,500,1,1,233.45,234.43,15,105,1,2,233.4,234.5,110,63,2,4,GOOG
2024-10-21T12:29:04.736969863Z,2024-10-21T12:29:04.736803679Z,10,2,38,A,A,0,233.94,200,130,166184,13268860,233.86,233.94,147,200,2,1,233.81,234,2,17,2,2,233.8,234.07,105,7,2,1,233.7,234.1,1200,100,1,1,233.66,234.13,401,400,2,1,233.58,234.17,505,1,2,1,233.53,234.25,10,100,1,1,233.5,234.41,100,500,1,1,233.45,234.43,15,105,1,2,233.4,234.5,110,63,2,4,GOOG
2024-10-21T12:29:04.942576593Z,2024-10-21T12:29:04.942410445Z,10,2,38,C,A,0,233.94,200,130,166148,13269072,233.86,234,147,17,2,2,233.81,234.07,2,7,2,1,233.8,234.1,105,100,2,1,233.7,234.13,1200,400,1,1,233.66,234.17,401,1,2,1,233.58,234.25,505,100,2,1,233.53,234.41,10,500,1,1,233.5,234.43,100,105,1,2,233.45,234.5,15,63,1,4,233.4,234.59,110,60,2,1,GOOG
2024-10-21T12:29:04.942589417Z,2024-10-21T12:29:04.942423141Z,10,2,38,A,A,0,233.99,200,130,166276,13269073,233.86,233.99,147,200,2,1,233.81,234,2,17,2,2,233.8,234.07,105,7,2,1,233.7,234.1,1200,100,1,1,233.66,234.13,401,400,2,1,233.58,234.17,505,1,2,1,233.53,234.25,10,100,1,1,233.5,234.41,100,500,1,1,233.45,234.43,15,105,1,2,233.4,234.5,110,63,2,4,GOOG
2024-10-21T12:29:04.997130813Z,2024-10-21T12:29:04.996963888Z,10,2,38,A,B,3,233.76,400,130,166925,13269127,233.86,233.99,147,200,2,1,233.81,234,2,17,2,2,233.8,234.07,105,7,2,1,233.76,234.1,400,100,1,1,233.7,234.13,1200,400,1,1,233.66,234.17,1,1,1,1,233.58,234.25,505,100,2,1,233.53,234.41,10,500,1,1,233.5,234.43,100,105,1,2,233.45,234.5,15,63,1,4,GOOG
2024-10-21T12:29:07.476323268Z,2024-10-21T12:29:07.476155585Z,10,2,38,T,A,0,233.86,30,130,167683,13271447,233.86,233.99,147,200,2,1,233.81,234,2,17,2,2,233.8,234.07,105,7,2,1,233.76,234.1,400,100,1,1,233.7,234.13,1200,400,1,1,233.66,234.17,1,1,1,1,233.58,234.25,505,100,2,1,233.53,234.41,10,500,1,1,233.5,234.43,100,105,1,2,233.45,234.5,15,63,1,4,GOOG
2024-10-21T12:29:07.476323268Z,2024-10-21T12:29:07.476155585Z,10,2,38,C,B,0,233.86,30,130,167683,13271447,233.86,233.99,117,200,2,1,233.81,234,2,17,2,2,233.8,234.07,105,7,2,1,233.76,234.1,400,100,1,1,233.7,234.13,1200,400,1,1,233.66,234.17,1,1,1,1,233.58,234.25,505,100,2,1,233.53,234.41,10,500,1,1,233.5,234.43,100,105,1,2,233.45,234.5,15,63,1,4,GOOG
2024-10-21T12:29:07.543978531Z,2024-10-21T12:29:07.543812287Z,10,2,38,C,B,3,233.76,400,130,166244,13271500,233.86,233.99,117,200,2,1,233.81,234,2,17,2,2,233.8,234.07,105,7,2,1,233.7,234.1,1200,100,1,1,233.66,234.13,1,400,1,1,233.58,234.17,505,1,2,1,233.53,234.25,10,100,1,1,233.5,234.41,100,500,1,1,233.45,234.43,15,105,1,2,233.4,234.5,110,63,2,4,GOOG
2024-10-21T12:29:07.573087456Z,2024-10-21T12:29:07.572921012Z,10,2,38,C,A,2,234.07,7,130,166444,13271562,233.86,233.99,117,200,2,1,233.81,234,2,17,2,2,233.8,234.1,105,100,2,1,233.7,234.13,1200,400,1,1,233.66,234.17,1,1,1,1,233.58,234.25,505,100,2,1,233.53,234.41,10,500,1,1,233.5,234.43,100,105,1,2,233.45,234.5,15,63,1,4,233.4,234.59,110,60,2,1,GOOG
2024-10-21T12:29:07.583042273Z,2024-10-21T12:29:07.582875842Z,10,2,38,A,B,3,233.74,200,130,166431,13271567,233.86,233.99,117,200,2,1,233.81,234,2,17,2,2,233.8,234.1,105,100,2,1,233.74,234.13,200,400,1,1,233.7,234.17,1200,1,1,1,233.66,234.25,1,100,1,1,233.58,234.41,505,500,2,1,233.53,234.43,10,105,1,2,233.5,234.5,100,63,1,4,233.45,234.59,15,60,1,1,GOOG
2024-10-21T12:29:07.715099060Z,2024-10-21T12:29:07.714932040Z,10,2,38,A,B,3,233.76,200,130,167020,13271618,233.86,233.99,117,200,2,1,233.81,234,2,17,2,2,233.8,234.1,105,100,2,1,233.76,234.13,200,400,1,1,233.7,234.17,1200,1,1,1,233.66,234.25,1,100,1,1,233.58,234.41,505,500,2,1,233.53,234.43,10,105,1,2,233.5,234.5,100,63,1,4,233.45,234.59,15,60,1,1,GOOG
2024-10-21T12:29:08.288393145Z,2024-10-21T12:29:08.288226889Z,10,2,38,A,B,3,233.77,200,130,166256,13272141,233.86,233.99,117,200,2,1,233.81,234,2,17,2,2,233.8,234.1,105,100,2,1,233.77,234.13,200,400,1,1,233.7,234.17,1200,1,1,1,233.66,234.25,1,100,1,1,233.58,234.41,505,500,2,1,233.53,234.43,10,105,1,2,233.5,234.5,100,63,1,4,233.45,234.59,15,60,1,1,GOOG
2024-10-21T12:29:08.937139462Z,2024-10-21T12:29:08.936973408Z,10,2,38,C,A,0,233.99,200,130,166054,13272432,233.86,234,117,17,2,2,233.81,234.1,2,100,2,1,233.8,234.13,105,400,2,1,233.77,234.17,200,1,1,1,233.7,234.25,1200,100,1,1,233.66,234.41,1,500,1,1,233.58,234.43,505,105,2,2,233.53,234.5,10,63,1,4,233.5,234.59,100,60,1,1,233.45,234.75,15,1,1,1,GOOG
2024-10-21T12:29:08.937151622Z,2024-10-21T12:29:08.936985355Z,10,2,38,A,A,1,234.01,200,130,166267,13272433,233.86,234,117,17,2,2,233.81,234.01,2,200,2,1,233.8,234.1,105,100,2,1,233.77,234.13,200,400,1,1,233.7,234.17,1200,1,1,1,233.66,234.25,1,100,1,1,233.58,234.41,505,500,2,1,233.53,234.43,10,105,1,2,233.5,234.5,100,63,1,4,233.45,234.59,15,60,1,1,GOOG
2024-10-21T12:29:08.992072347Z,2024-10-21T12:29:08.991905949Z,10,2,38,A,B,3,233.78,200,130,166398,13272483,233.86,234,117,17,2,2,233.81,234.01,2,200,2,1,233.8,234.1,105,100,2,1,233.78,234.13,200,400,1,1,233.7,234.17,1200,1,1,1,233.66,234.25,1,100,1,1,233.58,234.41,505,500,2,1,233.53,234.43,10,105,1,2,233.5,234.5,100,63,1,4,233.45,234.59,15,60,1,1,GOOG
2024-10-21T12:29:09.054222160Z,2024-10-21T12:29:09.054055599Z,10,2,38,A,A,0,234,200,130,166561,13272549,233.86,234,117,217,2,3,233.81,234.1,2,100,2,1,233.8,234.13,105,400,2,1,233.78,234.17,200,1,1,1,233.7,234.25,1200,100,1,1,233.66,234.41,1,500,1,1,233.58,234.43,505,105,2,2,233.53,234.5,10,63,1,4,233.5,234.59,100,60,1,1,233.45,234.75,15,1,1,1,GOOG
2024-10-21T12:29:09.096780188Z,2024-10-21T12:29:09.096609749Z,10,2,38,T,A,0,233.86,17,0,170439,13272571,233.86,234,117,217,2,3,233.81,234.1,2,100,2,1,233.8,234.13,105,400,2,1,233.78,234.17,200,1,1,1,233.7,234.25,1200,100,1,1,233.66,234.41,1,500,1,1,233.58,234.43,505,105,2,2,233.53,234.5,10,63,1,4,233.5,234.59,100,60,1,1,233.45,234.75,15,1,1,1,GOOG
2024-10-21T12:29:09.096780188Z,2024-10-21T12:29:09.096609749Z,10,2,38,T,A,0,233.86,100,0,170439,13272572,233.86,234,100,217,1,3,233.81,234.1,2,100,2,1,233.8,234.13,105,400,2,1,233.78,234.17,200,1,1,1,233.7,234.25,1200,100,1,1,233.66,234.41,1,500,1,1,233.58,234.43,505,105,2,2,233.53,234.5,10,63,1,4,233.5,234.59,100,60,1,1,233.45,234.75,15,1,1,1,GOOG
2024-10-21T12:29:09.096780188Z,2024-10-21T12:29:09.096609749Z,10,2,38,T,N,0,233.86,683,130,170439,13272573,233.81,234,2,217,2,3,233.8,234.1,105,100,2,1,233.78,234.13,200,400,1,1,233.7,234.17,1200,1,1,1,233.66,234.25,1,100,1,1,233.58,234.41,505,500,2,1,233.53,234.43,10,105,1,2,233.5,234.5,100,63,1,4,233.45,234.59,15,60,1,1,233.4,234.75,110,1,2,1,GOOG
2024-10-21T12:29:09.096791448Z,2024-10-21T12:29:09.096622742Z,10,2,38,A,B,0,233.86,100,130,168706,13272574,233.86,234,100,217,1,3,233.81,234.1,2,100,2,1,233.8,234.13,105,400,2,1,233.78,234.17,200,1,1,1,233.7,234.25,1200,100,1,1,233.66,234.41,1,500,1,1,233.58,234.43,505,105,2,2,233.53,234.5,10,63,1,4,233.5,234.59,100,60,1,1,233.45,234.75,15,1,1,1,GOOG
2024-10-21T12:29:09.096803407Z,2024-10-21T12:29:09.096634813Z,10,2,38,A,A,0,233.92,100,130,168594,13272575,233.86,233.92,100,100,1,1,233.81,234,2,217,2,3,233.8,234.1,105,100,2,1,233.78,234.13,200,400,1,1,233.7,234.17,1200,1,1,1,233.66,234.25,1,100,1,1,233.58,234.41,505,500,2,1,233.53,234.43,10,105,1,2,233.5,234.5,100,63,1,4,233.45,234.59,15,60,1,1,GOOG
2024-10-21T12:29:09.096806296Z,2024-10-21T12:29:09.096639241Z,10,2,38,A,A,1,233.93,135,130,167055,13272576,233.86,233.92,100,100,1,1,233.81,233.93,2,135,2,1,233.8,234,105,217,2,3,233.78,234.1,200,100,1,1,233.7,234.13,1200,400,1,1,233.66,234.17,1,1,1,1,233.58,234.25,505,100,2,1,233.53,234.41,10,500,1,1,233.5,234.43,100,105,1,2,233.45,234.5,15,63,1,4,GOOG
2024-10-21T12:29:09.096808055Z,2024-10-21T12:29:09.096640225Z,10,2,38,A,A,2,233.97,100,130,167830,13272577,233.86,233.92,100,100,1,1,233.81,233.93,2,135,2,1,233.8,233.97,105,100,2,1,233.78,234,200,217,1,3,233.7,234.1,1200,100,1,1,233.66,234.13,1,400,1,1,233.58,234.17,505,1,2,1,233.53,234.25,10,100,1,1,233.5,234.41,100,500,1,1,233.45,234.43,15,105,1,2,GOOG
2024-10-21T12:29:09.096815657Z,2024-10-21T12:29:09.096649377Z,10,2,38,A,A,2,233.97,100,130,166280,13272579,233.86,233.92,100,100,1,1,233.81,233.93,2,135,2,1,233.8,233.97,105,300,2,3,233.78,234,200,217,1,3,233.7,234.1,1200,100,1,1,233.66,234.13,1,400,1,1,233.58,234.17,505,1,2,1,233.53,234.25,10,100,1,1,233.5,234.41,100,500,1,1,233.45,234.43,15,105,1,2,GOOG
2024-10-21T12:29:09.096817407Z,2024-10-21T12:29:09.096651465Z,10,2,38,C,A,1,233.93,135,130,165942,13272580,233.86,233.92,100,100,1,1,233.81,233.97,2,300,2,3,233.8,234,105,217,2,3,233.78,234.1,200,100,1,1,233.7,234.13,1200,400,1,1,233.66,234.17,1,1,1,1,233.58,234.25,505,100,2,1,233.53,234.41,10,500,1,1,233.5,234.43,100,105,1,2,233.45,234.5,15,63,1,4,GOOG
2024-10-21T12:29:09.096825400Z,2024-10-21T12:29:09.096659107Z,10,2,38,A,A,1,233.93,27,130,166293,13272581,233.86,233.92,100,100,1,1,233.81,233.93,2,27,2,1,233.8,233.97,105,300,2,3,233.78,234,200,217,1,3,233.7,234.1,1200,100,1,1,233.66,234.13,1,400,1,1,233.58,234.17,505,1,2,1,233.53,234.25,10,100,1,1,233.5,234.41,100,500,1,1,233.45,234.43,15,105,1,2,GOOG
2024-10-21T12:29:09.096839118Z,2024-10-21T12:29:09.096672869Z,10,2,38,A,A,3,233.98,27,130,166249,13272582,233.86,233.92,100,100,1,1,233.81,233.93,2,27,2,1,233.8,233.97,105,300,2,3,233.78,233.98,200,27,1,1,233.7,234,1200,217,1,3,233.66,234.1,1,100,1,1,233.58,234.13,505,400,2,1,233.53,234.17,10,1,1,1,233.5,234.25,100,100,1,1,233.45,234.41,15,500,1,1,GOOG
2024-10-21T12:29:09.096849122Z,2024-10-21T12:29:09.096683301Z,10,2,38,C,A,0,233.92,100,130,165821,13272583,233.86,233.93,100,27,1,1,233.81,233.97,2,300,2,3,233.8,233.98,105,27,2,1,233.78,234,200,217,1,3,233.7,234.1,1200,100,1,1,233.66,234.13,1,400,1,1,233.58,234.17,505,1,2,1,233.53,234.25,10,100,1,1,233.5,234.41,100,500,1,1,233.45,234.43,15,105,1,2,GOOG
2024-10-21T12:29:09.096859383Z,2024-10-21T12:29:09.096693428Z,10,2,38,C,B,3,233.78,200,130,165955,13272584,233.86,233.93,100,27,1,1,233.81,233.97,2,300,2,3,233.8,233.98,105,27,2,1,233.7,234,1200,217,1,3,233.66,234.1,1,100,1,1,233.58,234.13,505,400,2,1,233.53,234.17,10,1,1,1,233.5,234.25,100,100,1,1,233.45,234.41,15,500,1,1,233.4,234.43,110,105,2,2,GOOG
2024-10-21T12:29:09.096872549Z,2024-10-21T12:29:09.096705312Z,10,2,38,C,A,1,233.97,100,130,167237,13272586,233.86,233.93,100,27,1,1,233.81,233.97,2,200,2,2,233.8,233.98,105,27,2,1,233.7,234,1200,217,1,3,233.66,234.1,1,100,1,1,233.58,234.13,505,400,2,1,233.53,234.17,10,1,1,1,233.5,234.25,100,100,1,1,233.45,234.41,15,500,1,1,233.4,234.43,110,105,2,2,GOOG
2024-10-21T12:29:09.096873527Z,2024-10-21T12:29:09.096706998Z,10,2,38,C,A,1,233.97,100,130,166529,13272587,233.86,233.93,100,27,1,1,233.81,233.97,2,100,2,1,233.8,233.98,105,27,2,1,233.7,234,1200,217,1,3,233.66,234.1,1,100,1,1,233.58,234.13,505,400,2,1,233.53,234.17,10,1,1,1,233.5,234.25,100,100,1,1,233.45,234.41,15,500,1,1,233.4,234.43,110,105,2,2,GOOG
2024-10-21T12:29:09.097202819Z,2024-10-21T12:29:09.097036830Z,10,2,38,C,A,1,233.97,100,130,165989,13272589,233.86,233.93,100,27,1,1,233.81,233.98,2,27,2,1,233.8,234,105,217,2,3,233.7,234.1,1200,100,1,1,233.66,234.13,1,400,1,1,233.58,234.17,505,1,2,1,233.53,234.25,10,100,1,1,233.5,234.41,100,500,1,1,233.45,234.43,15,105,1,2,233.4,234.5,110,63,2,4,GOOG
2024-10-21T12:29:09.197974288Z,2024-10-21T12:29:09.197808423Z,10,2,38,C,A,1,233.98,27,130,165865,13272635,233.86,233.93,100,27,1,1,233.81,234,2,217,2,3,233.8,234.1,105,100,2,1,233.7,234.13,1200,400,1,1,233.66,234.17,1,1,1,1,233.58,234.25,505,100,2,1,233.53,234.41,10,500,1,1,233.5,234.43,100,105,1,2,233.45,234.5,15,63,1,4,233.4,234.59,110,60,2,1,GOOG
2024-10-21T12:29:09.198031378Z,2024-10-21T12:29:09.197865189Z,10,2,38,A,B,3,233.77,200,130,166189,13272636,233.86,233.93,100,27,1,1,233.81,234,2,217,2,3,233.8,234.1,105,100,2,1,233.77,234.13,200,400,1,1,233.7,234.17,1200,1,1,1,233.66,234.25,1,100,1,1,233.58,234.41,505,500,2,1,233.53,234.43,10,105,1,2,233.5,234.5,100,63,1,4,233.45,234.59,15,60,1,1,GOOG
2024-10-21T12:29:09.349683778Z,2024-10-21T12:29:09.349517861Z,10,2,38,C,A,0,233.93,27,130,165917,13272742,233.86,234,100,217,1,3,233.81,234.1,2,100,2,1,233.8,234.13,105,400,2,1,233.77,234.17,200,1,1,1,233.7,234.25,1200,100,1,1,233.66,234.41,1,500,1,1,233.58,234.43,505,105,2,2,233.53,234.5,10,63,1,4,233.5,234.59,100,60,1,1,233.45,234.75,15,1,1,1,GOOG
2024-10-21T12:29:09.576065628Z,2024-10-21T12:29:09.575899057Z,10,2,38,A,A,0,233.97,7,130,166571,13272947,233.86,233.97,100,7,1,1,233.81,234,2,217,2,3,233.8,234.1,105,100,2,1,233.77,234.13,200,400,1,1,233.7,234.17,1200,1,1,1,233.66,234.25,1,100,1,1,233.58,234.41,505,500,2,1,233.53,234.43,10,105,1,2,233.5,234.5,100,63,1,4,233.45,234.59,15,60,1,1,GOOG
2024-10-21T12:29:11.490610915Z,2024-10-21T12:29:11.490444580Z,10,2,38,A,B,3,233.78,200,130,166335,13273947,233.86,233.97,100,7,1,1,233.81,234,2,217,2,3,233.8,234.1,105,100,2,1,233.78,234.13,200,400,1,1,233.7,234.17,1200,1,1,1,233.66,234.25,1,100,1,1,233.58,234.41,505,500,2,1,233.53,234.43,10,105,1,2,233.5,234.5,100,63,1,4,233.45,234.59,15,60,1,1,GOOG
2024-10-21T12:29:12.051247514Z,2024-10-21T12:29:12.051081325Z,10,2,38,C,A,1,234,200,130,166189,13274358,233.86,233.97,100,7,1,1,233.81,234,2,17,2,2,233.8,234.1,105,100,2,1,233.78,234.13,200,400,1,1,233.7,234.17,1200,1,1,1,233.66,234.25,1,100,1,1,233.58,234.41,505,500,2,1,233.53,234.43,10,105,1,2,233.5,234.5,100,63,1,4,233.45,234.59,15,60,1,1,GOOG
2024-10-21T12:29:12.051260608Z,2024-10-21T12:29:12.051094374Z,10,2,38,A,A,2,234.02,200,130,166234,13274359,233.86,233.97,100,7,1,1,233.81,234,2,17,2,2,233.8,234.02,105,200,2,1,233.78,234.1,200,100,1,1,233.7,234.13,1200,400,1,1,233.66,234.17,1,1,1,1,233.58,234.25,505,100,2,1,233.53,234.41,10,500,1,1,233.5,234.43,100,105,1,2,233.45,234.5,15,63,1,4,GOOG
2024-10-21T12:29:12.054550814Z,2024-10-21T12:29:12.054384594Z,10,2,38,C,A,2,234.02,200,130,166220,13274363,233.86,233.97,100,7,1,1,233.81,234,2,17,2,2,233.8,234.1,105,100,2,1,233.78,234.13,200,400,1,1,233.7,234.17,1200,1,1,1,233.66,234.25,1,100,1,1,233.58,234.41,505,500,2,1,233.53,234.43,10,105,1,2,233.5,234.5,100,63,1,4,233.45,234.59,15,60,1,1,GOOG
2024-10-21T12:29:12.054563570Z,2024-10-21T12:29:12.054397299Z,10,2,38,A,A,2,234.06,200,130,166271,13274364,233.86,233.97,100,7,1,1,233.81,234,2,17,2,2,233.8,234.06,105,200,2,1,233.78,234.1,200,100,1,1,233.7,234.13,1200,400,1,1,233.66,234.17,1,1,1,1,233.58,234.25,505,100,2,1,233.53,234.41,10,500,1,1,233.5,234.43,100,105,1,2,233.45,234.5,15,63,1,4,GOOG
2024-10-21T12:29:12.061445338Z,2024-10-21T12:29:12.061278295Z,10,2,38,A,A,2,234.06,200,130,167043,13274376,233.86,233.97,100,7,1,1,233.81,234,2,17,2,2,233.8,234.06,105,400,2,2,233.78,234.1,200,100,1,1,233.7,234.13,1200,400,1,1,233.66,234.17,1,1,1,1,233.58,234.25,505,100,2,1,233.53,234.41,10,500,1,1,233.5,234.43,100,105,1,2,233.45,234.5,15,63,1,4,GOOG
2024-10-21T12:29:12.188908222Z,2024-10-21T12:29:12.188742107Z,10,2,38,A,B,3,233.78,200,130,166115,13274537,233.86,233.97,100,7,1,1,233.81,234,2,17,2,2,233.8,234.06,105,400,2,2,233.78,234.1,400,100,2,1,233.7,234.13,1200,400,1,1,233.66,234.17,1,1,1,1,233.58,234.25,505,100,2,1,233.53,234.41,10,500,1,1,233.5,234.43,100,105,1,2,233.45,234.5,15,63,1,4,GOOG
2024-10-21T12:29:14.061306232Z,2024-10-21T12:29:14.061139742Z,10,2,38,C,A,0,233.97,7,130,166490,13276931,233.86,234,100,17,1,2,233.81,234.06,2,400,2,2,233.8,234.1,105,100,2,1,233.78,234.13,400,400,2,1,233.7,234.17,1200,1,1,1,233.66,234.25,1,100,1,1,233.58,234.41,505,500,2,1,233.53,234.43,10,105,1,2,233.5,234.5,100,63,1,4,233.45,234.59,15,60,1,1,GOOG
2024-10-21T12:29:16.067207511Z,2024-10-21T12:29:16.067040933Z,10,2,38,A,A,2,234.07,7,130,166578,13278868,233.86,234,100,17,1,2,233.81,234.06,2,400,2,2,233.8,234.07,105,7,2,1,233.78,234.1,400,100,2,1,233.7,234.13,1200,400,1,1,233.66,234.17,1,1,1,1,233.58,234.25,505,100,2,1,233.53,234.41,10,500,1,1,233.5,234.43,100,105,1,2,233.45,234.5,15,63,1,4,GOOG
2024-10-21T12:29:26.243021844Z,2024-10-21T12:29:26.242855402Z,10,2,38,C,B,3,233.78,200,130,166442,13287675,233.86,234,100,17,1,2,233.81,234.06,2,400,2,2,233.8,234.07,105,7,2,1,233.78,234.1,200,100,1,1,233.7,234.13,1200,400,1,1,233.66,234.17,1,1,1,1,233.58,234.25,505,100,2,1,233.53,234.41,10,500,1,1,233.5,234.43,100,105,1,2,233.45,234.5,15,63,1,4,GOOG
2024-10-21T12:29:26.243034702Z,2024-10-21T12:29:26.242868183Z,10,2,38,A,B,3,233.79,400,130,166519,13287676,233.86,234,100,17,1,2,233.81,234.06,2,400,2,2,233.8,234.07,105,7,2,1,233.79,234.1,400,100,1,1,233.7,234.13,1200,400,1,1,233.66,234.17,1,1,1,1,233.58,234.25,505,100,2,1,233.53,234.41,10,500,1,1,233.5,234.43,100,105,1,2,233.45,234.5,15,63,1,4,GOOG
2024-10-21T12:29:26.365400353Z,2024-10-21T12:29:26.365233464Z,10,2,38,C,B,3,233.79,200,130,166889,13287960,233.86,234,100,17,1,2,233.81,234.06,2,400,2,2,233.8,234.07,105,7,2,1,233.79,234.1,200,100,1,1,233.7,234.13,1200,400,1,1,233.66,234.17,1,1,1,1,233.58,234.25,505,100,2,1,233.53,234.41,10,500,1,1,233.5,234.43,100,105,1,2,233.45,234.5,15,63,1,4,GOOG
2024-10-21T12:29:49.448914487Z,2024-10-21T12:29:49.448744098Z,10,2,38,T,N,0,233.87,500,0,170389,13303883,233.86,234,100,17,1,2,233.81,234.06,2,400,2,2,233.8,234.07,105,7,2,1,233.79,234.1,200,100,1,1,233.7,234.13,1200,400,1,1,233.66,234.17,1,1,1,1,233.58,234.25,505,100,2,1,233.53,234.41,10,500,1,1,233.5,234.43,100,105,1,2,233.45,234.5,15,63,1,4,GOOG
2024-10-21T12:29:49.448914487Z,2024-10-21T12:29:49.448744098Z,10,2,38,T,N,0,233.87,50,0,170389,13303884,233.86,234,100,17,1,2,233.81,234.06,2,400,2,2,233.8,234.07,105,7,2,1,233.79,234.1,200,100,1,1,233.7,234.13,1200,400,1,1,233.66,234.17,1,1,1,1,233.58,234.25,505,100,2,1,233.53,234.41,10,500,1,1,233.5,234.43,100,105,1,2,233.45,234.5,15,63,1,4,GOOG
2024-10-21T12:29:49.448914487Z,2024-10-21T12:29:49.448744098Z,10,2,38,T,N,0,233.87,100,130,170389,13303885,233.86,234,100,17,1,2,233.81,234.06,2,400,2,2,233.8,234.07,105,7,2,1,233.79,234.1,200,100,1,1,233.7,234.13,1200,400,1,1,233.66,234.17,1,1,1,1,233.58,234.25,505,100,2,1,233.53,234.41,10,500,1,1,233.5,234.43,100,105,1,2,233.45,234.5,15,63,1,4,GOOG
2024-10-21T12:29:49.450467509Z,2024-10-21T12:29:49.450300162Z,10,2,38,T,A,0,233.86,100,130,167347,13303886,233.86,234,100,17,1,2,233.81,234.06,2,400,2,2,233.8,234.07,105,7,2,1,233.79,234.1,200,100,1,1,233.7,234.13,1200,400,1,1,233.66,234.17,1,1,1,1,233.58,234.25,505,100,2,1,233.53,234.41,10,500,1,1,233.5,234.43,100,105,1,2,233.45,234.5,15,63,1,4,GOOG
2024-10-21T12:29:49.450467509Z,2024-10-21T12:29:49.450300162Z,10,2,38,C,B,0,233.86,100,130,167347,13303886,233.81,234,2,17,2,2,233.8,234.06,105,400,2,2,233.79,234.07,200,7,1,1,233.7,234.1,1200,100,1,1,233.66,234.13,1,400,1,1,233.58,234.17,505,1,2,1,233.53,234.25,10,100,1,1,233.5,234.41,100,500,1,1,233.45,234.43,15,105,1,2,233.4,234.5,110,63,2,4,GOOG
2024-10-21T12:29:49.450478735Z,2024-10-21T12:29:49.450311621Z,10,2,38,A,B,0,233.86,100,130,167114,13303887,233.86,234,100,17,1,2,233.81,234.06,2,400,2,2,233.8,234.07,105,7,2,1,233.79,234.1,200,100,1,1,233.7,234.13,1200,400,1,1,233.66,234.17,1,1,1,1,233.58,234.25,505,100,2,1,233.53,234.41,10,500,1,1,233.5,234.43,100,105,1,2,233.45,234.5,15,63,1,4,GOOG
2024-10-21T12:29:49.450482704Z,2024-10-21T12:29:49.450314673Z,10,2,38,T,A,0,233.86,100,0,168031,13303888,233.86,234,100,17,1,2,233.81,234.06,2,400,2,2,233.8,234.07,105,7,2,1,233.79,234.1,200,100,1,1,233.7,234.13,1200,400,1,1,233.66,234.17,1,1,1,1,233.58,234.25,505,100,2,1,233.53,234.41,10,500,1,1,233.5,234.43,100,105,1,2,233.45,234.5,15,63,1,4,GOOG
2024-10-21T12:29:49.450482704Z,2024-10-21T12:29:49.450314673Z,10,2,38,T,N,0,233.86,17,130,168031,13303889,233.81,234,2,17,2,2,233.8,234.06,105,400,2,2,233.79,234.07,200,7,1,1,233.7,234.1,1200,100,1,1,233.66,234.13,1,400,1,1,233.58,234.17,505,1,2,1,233.53,234.25,10,100,1,1,233.5,234.41,100,500,1,1,233.45,234.43,15,105,1,2,233.4,234.5,110,63,2,4,GOOG
2024-10-21T12:29:49.450488087Z,2024-10-21T12:29:49.450321900Z,10,2,38,A,A,0,233.92,100,130,166187,13303890,233.81,233.92,2,100,2,1,233.8,234,105,17,2,2,233.79,234.06,200,400,1,2,233.7,234.07,1200,7,1,1,233.66,234.1,1,100,1,1,233.58,234.13,505,400,2,1,233.53,234.17,10,1,1,1,233.5,234.25,100,100,1,1,233.45,234.41,15,500,1,1,233.4,234.43,110,105,2,2,GOOG
2024-10-21T12:29:49.450494597Z,2024-10-21T12:29:49.450325841Z,10,2,38,A,A,1,233.93,54,130,168756,13303892,233.81,233.92,2,100,2,1,233.8,233.93,105,54,2,1,233.79,233.97,200,100,1,1,233.7,234,1200,17,1,2,233.66,234.06,1,400,1,2,233.58,234.07,505,7,2,1,233.53,234.1,10,100,1,1,233.5,234.13,100,400,1,1,233.45,234.17,15,1,1,1,233.4,234.25,110,100,2,1,GOOG
2024-10-21T12:29:49.450500673Z,2024-10-21T12:29:49.450334304Z,10,2,38,A,A,2,233.97,100,130,166369,13303894,233.81,233.92,2,100,2,1,233.8,233.93,105,54,2,1,233.79,233.97,200,300,1,3,233.7,234,1200,17,1,2,233.66,234.06,1,400,1,2,233.58,234.07,505,7,2,1,233.53,234.1,10,100,1,1,233.5,234.13,100,400,1,1,233.45,234.17,15,1,1,1,233.4,234.25,110,100,2,1,GOOG
2024-10-21T12:29:49.450503676Z,2024-10-21T12:29:49.450337787Z,10,2,38,A,A,1,233.93,19,130,165889,13303895,233.81,233.92,2,100,2,1,233.8,233.93,105,73,2,2,233.79,233.97,200,300,1,3,233.7,234,1200,17,1,2,233.66,234.06,1,400,1,2,233.58,234.07,505,7,2,1,233.53,234.1,10,100,1,1,233.5,234.13,100,400,1,1,233.45,234.17,15,1,1,1,233.4,234.25,110,100,2,1,GOOG
2024-10-21T12:29:49.450507723Z,2024-10-21T12:29:49.450341436Z,10,2,38,C,A,1,233.93,54,130,166287,13303896,233.81,233.92,2,100,2,1,233.8,233.93,105,19,2,1,233.79,233.97,200,300,1,3,233.7,234,1200,17,1,2,233.66,234.06,1,400,1,2,233.58,234.07,505,7,2,1,233.53,234.1,10,100,1,1,233.5,234.13,100,400,1,1,233.45,234.17,15,1,1,1,233.4,234.25,110,100,2,1,GOOG
2024-10-21T12:29:49.450510407Z,2024-10-21T12:29:49.450344611Z,10,2,38,C,A,0,233.92,100,130,165796,13303897,233.81,233.93,2,19,2,1,233.8,233.97,105,300,2,3,233.79,234,200,17,1,2,233.7,234.06,1200,400,1,2,233.66,234.07,1,7,1,1,233.58,234.1,505,100,2,1,233.53,234.13,10,400,1,1,233.5,234.17,100,1,1,1,233.45,234.25,15,100,1,1,233.4,234.41,110,500,2,1,GOOG
2024-10-21T12:29:49.450516082Z,2024-10-21T12:29:49.450349606Z,10,2,38,A,A,2,233.98,19,130,166476,13303898,233.81,233.93,2,19,2,1,233.8,233.97,105,300,2,3,233.79,233.98,200,19,1,1,233.7,234,1200,17,1,2,233.66,234.06,1,400,1,2,233.58,234.07,505,7,2,1,233.53,234.1,10,100,1,1,233.5,234.13,100,400,1,1,233.45,234.17,15,1,1,1,233.4,234.25,110,100,2,1,GOOG
2024-10-21T12:29:49.450517345Z,2024-10-21T12:29:49.450351627Z,10,2,38,C,A,1,233.97,100,130,165718,13303899,233.81,233.93,2,19,2,1,233.8,233.97,105,200,2,2,233.79,233.98,200,19,1,1,233.7,234,1200,17,1,2,233.66,234.06,1,400,1,2,233.58,234.07,505,7,2,1,233.53,234.1,10,100,1,1,233.5,234.13,100,400,1,1,233.45,234.17,15,1,1,1,233.4,234.25,110,100,2,1,GOOG
2024-10-21T12:29:49.450521006Z,2024-10-21T12:29:49.450355047Z,10,2,38,C,A,1,233.97,100,130,165959,13303900,233.81,233.93,2,19,2,1,233.8,233.97,105,100,2,1,233.79,233.98,200,19,1,1,233.7,234,1200,17,1,2,233.66,234.06,1,400,1,2,233.58,234.07,505,7,2,1,233.53,234.1,10,100,1,1,233.5,234.13,100,400,1,1,233.45,234.17,15,1,1,1,233.4,234.25,110,100,2,1,GOOG
2024-10-21T12:29:49.450560627Z,2024-10-21T12:29:49.450394230Z,10,2,38,C,B,2,233.79,200,130,166397,13303902,233.81,233.93,2,19,2,1,233.8,233.97,105,100,2,1,233.7,233.98,1200,19,1,1,233.66,234,1,17,1,2,233.58,234.06,505,400,2,2,233.53,234.07,10,7,1,1,233.5,234.1,100,100,1,1,233.45,234.13,15,400,1,1,233.4,234.17,110,1,2,1,233.39,234.25,10,100,1,1,GOOG
2024-10-21T12:29:49.450818190Z,2024-10-21T12:29:49.450652186Z,10,2,38,C,A,1,233.97,100,130,166004,13303903,233.81,233.93,2,19,2,1,233.8,233.98,105,19,2,1,233.7,234,1200,17,1,2,233.66,234.06,1,400,1,2,233.58,234.07,505,7,2,1,233.53,234.1,10,100,1,1,233.5,234.13,100,400,1,1,233.45,234.17,15,1,1,1,233.4,234.25,110,100,2,1,233.39,234.41,10,500,1,1,GOOG
2024-10-21T12:29:49.452437450Z,2024-10-21T12:29:49.452270874Z,10,2,38,C,A,4,234.07,7,130,166576,13303906,233.81,233.93,2,19,2,1,233.8,233.98,105,19,2,1,233.7,234,1200,17,1,2,233.66,234.06,1,400,1,2,233.58,234.1,505,100,2,1,233.53,234.13,10,400,1,1,233.5,234.17,100,1,1,1,233.45,234.25,15,100,1,1,233.4,234.41,110,500,2,1,233.39,234.43,10,105,1,2,GOOG
2024-10-21T12:29:49.553930519Z,2024-10-21T12:29:49.553764632Z,10,2,38,C,A,1,233.98,19,130,165887,13304055,233.81,233.93,2,19,2,1,233.8,234,105,17,2,2,233.7,234.06,1200,400,1,2,233.66,234.1,1,100,1,1,233.58,234.13,505,400,2,1,233.53,234.17,10,1,1,1,233.5,234.25,100,100,1,1,233.45,234.41,15,500,1,1,233.4,234.43,110,105,2,2,233.39,234.5,10,63,1,4,GOOG
2024-10-21T12:29:49.553989527Z,2024-10-21T12:29:49.553823391Z,10,2,38,A,B,2,233.79,200,130,166136,13304056,233.81,233.93,2,19,2,1,233.8,234,105,17,2,2,233.79,234.06,200,400,1,2,233.7,234.1,1200,100,1,1,233.66,234.13,1,400,1,1,233.58,234.17,505,1,2,1,233.53,234.25,10,100,1,1,233.5,234.41,100,500,1,1,233.45,234.43,15,105,1,2,233.4,234.5,110,63,2,4,GOOG
2024-10-21T12:29:49.703932459Z,2024-10-21T12:29:49.703766083Z,10,2,38,C,A,0,233.93,19,130,166376,13304148,233.81,234,2,17,2,2,233.8,234.06,105,400,2,2,233.79,234.1,200,100,1,1,233.7,234.13,1200,400,1,1,233.66,234.17,1,1,1,1,233.58,234.25,505,100,2,1,233.53,234.41,10,500,1,1,233.5,234.43,100,105,1,2,233.45,234.5,15,63,1,4,233.4,234.59,110,60,2,1,GOOG
2024-10-21T12:29:50.524188835Z,2024-10-21T12:29:50.524022649Z,10,2,38,C,B,2,233.79,200,130,166186,13304862,233.81,234,2,17,2,2,233.8,234.06,105,400,2,2,233.7,234.1,1200,100,1,1,233.66,234.13,1,400,1,1,233.58,234.17,505,1,2,1,233.53,234.25,10,100,1,1,233.5,234.41,100,500,1,1,233.45,234.43,15,105,1,2,233.4,234.5,110,63,2,4,233.39,234.59,10,60,1,1,GOOG
2024-10-21T12:29:50.524201597Z,2024-10-21T12:29:50.524034831Z,10,2,38,A,B,2,233.78,200,130,166766,13304863,233.81,234,2,17,2,2,233.8,234.06,105,400,2,2,233.78,234.1,200,100,1,1,233.7,234.13,1200,400,1,1,233.66,234.17,1,1,1,1,233.58,234.25,505,100,2,1,233.53,234.41,10,500,1,1,233.5,234.43,100,105,1,2,233.45,234.5,15,63,1,4,233.4,234.59,110,60,2,1,GOOG
2024-10-21T12:29:51.461716502Z,2024-10-21T12:29:51.461550015Z,10,2,38,A,A,0,233.97,7,130,166487,13307787,233.81,233.97,2,7,2,1,233.8,234,105,17,2,2,233.78,234.06,200,400,1,2,233.7,234.1,1200,100,1,1,233.66,234.13,1,400,1,1,233.58,234.17,505,1,2,1,233.53,234.25,10,100,1,1,233.5,234.41,100,500,1,1,233.45,234.43,15,105,1,2,233.4,234.5,110,63,2,4,GOOG
2024-10-21T12:29:54.581217052Z,2024-10-21T12:29:54.581050838Z,10,2,38,C,A,2,234.06,200,130,166214,13309491,233.81,233.97,2,7,2,1,233.8,234,105,17,2,2,233.78,234.06,200,200,1,1,233.7,234.1,1200,100,1,1,233.66,234.13,1,400,1,1,233.58,234.17,505,1,2,1,233.53,234.25,10,100,1,1,233.5,234.41,100,500,1,1,233.45,234.43,15,105,1,2,233.4,234.5,110,63,2,4,GOOG
2024-10-21T12:29:54.581231517Z,2024-10-21T12:29:54.581064740Z,10,2,38,A,A,2,234.02,400,130,166777,13309492,233.81,233.97,2,7,2,1,233.8,234,105,17,2,2,233.78,234.02,200,400,1,1,233.7,234.1,1200,100,1,1,233.66,234.13,1,400,1,1,233.58,234.17,505,1,2,1,233.53,234.25,10,100,1,1,233.5,234.41,100,500,1,1,233.45,234.43,15,105,1,2,233.4,234.5,110,63,2,4,GOOG
2024-10-21T12:29:54.639536184Z,2024-10-21T12:29:54.639369336Z,10,2,38,A,A,1,233.98,200,130,166848,13309521,233.81,233.97,2,7,2,1,233.8,233.98,105,200,2,1,233.78,234,200,17,1,2,233.7,234.1,1200,100,1,1,233.66,234.13,1,400,1,1,233.58,234.17,505,1,2,1,233.53,234.25,10,100,1,1,233.5,234.41,100,500,1,1,233.45,234.43,15,105,1,2,233.4,234.5,110,63,2,4,GOOG
2024-10-21T12:29:55.410480455Z,2024-10-21T12:29:55.410313755Z,10,2,38,A,A,0,233.96,200,130,166700,13310140,233.81,233.96,2,200,2,1,233.8,233.97,105,7,2,1,233.78,234,200,17,1,2,233.7,234.1,1200,100,1,1,233.66,234.13,1,400,1,1,233.58,234.17,505,1,2,1,233.53,234.25,10,100,1,1,233.5,234.41,100,500,1,1,233.45,234.43,15,105,1,2,233.4,234.5,110,63,2,4,GOOG
2024-10-21T12:30:01.594536029Z,2024-10-21T12:30:01.594370016Z,10,2,38,C,B,2,233.78,200,130,166013,13329349,233.81,233.96,2,200,2,1,233.8,233.97,105,7,2,1,233.7,234,1200,17,1,2,233.66,234.1,1,100,1,1,233.58,234.13,505,400,2,1,233.53,234.17,10,1,1,1,233.5,234.25,100,100,1,1,233.45,234.41,15,500,1,1,233.4,234.43,110,105,2,2,233.39,234.5,10,63,1,4,GOOG
2024-10-21T12:30:01.675240968Z,2024-10-21T12:30:01.675073949Z,10,2,38,A,B,2,233.77,200,130,167019,13329475,233.81,233.96,2,200,2,1,233.8,233.97,105,7,2,1,233.77,234,200,17,1,2,233.7,234.1,1200,100,1,1,233.66,234.13,1,400,1,1,233.58,234.17,505,1,2,1,233.53,234.25,10,100,1,1,233.5,234.41,100,500,1,1,233.45,234.43,15,105,1,2,233.4,234.5,110,63,2,4,GOOG
2024-10-21T12:30:01.702448731Z,2024-10-21T12:30:01.702282387Z,10,2,38,C,B,2,233.77,200,130,166344,13329489,233.81,233.96,2,200,2,1,233.8,233.97,105,7,2,1,233.7,234,1200,17,1,2,233.66,234.1,1,100,1,1,233.58,234.13,505,400,2,1,233.53,234.17,10,1,1,1,233.5,234.25,100,100,1,1,233.45,234.41,15,500,1,1,233.4,234.43,110,105,2,2,233.39,234.5,10,63,1,4,GOOG
2024-10-21T12:30:01.702462409Z,2024-10-21T12:30:01.702295886Z,10,2,38,A,B,2,233.73,400,130,166523,13329490,233.81,233.96,2,200,2,1,233.8,233.97,105,7,2,1,233.73,234,400,17,1,2,233.7,234.1,1200,100,1,1,233.66,234.13,1,400,1,1,233.58,234.17,505,1,2,1,233.53,234.25,10,100,1,1,233.5,234.41,100,500,1,1,233.45,234.43,15,105,1,2,233.4,234.5,110,63,2,4,GOOG
2024-10-21T12:30:01.702795294Z,2024-10-21T12:30:01.702628858Z,10,2,38,A,A,0,233.96,200,130,166436,13329491,233.81,233.96,2,400,2,2,233.8,233.97,105,7,2,1,233.73,234,400,17,1,2,233.7,234.1,1200,100,1,1,233.66,234.13,1,400,1,1,233.58,234.17,505,1,2,1,233.53,234.25,10,100,1,1,233.5,234.41,100,500,1,1,233.45,234.43,15,105,1,2,233.4,234.5,110,63,2,4,GOOG
2024-10-21T12:30:09.716422273Z,2024-10-21T12:30:09.716255586Z,10,2,38,A,B,2,233.77,200,130,166687,13350054,233.81,233.96,2,400,2,2,233.8,233.97,105,7,2,1,233.77,234,200,17,1,2,233.7,234.1,1200,100,1,1,233.66,234.13,1,400,1,1,233.58,234.17,505,1,2,1,233.53,234.25,10,100,1,1,233.5,234.41,100,500,1,1,233.45,234.43,15,105,1,2,233.4,234.5,110,63,2,4,GOOG
2024-10-21T12:30:10.321686875Z,2024-10-21T12:30:10.321520576Z,10,2,38,A,B,2,233.78,200,130,166299,13350463,233.81,233.96,2,400,2,2,233.8,233.97,105,7,2,1,233.78,234,200,17,1,2,233.7,234.1,1200,100,1,1,233.66,234.13,1,400,1,1,233.58,234.17,505,1,2,1,233.53,234.25,10,100,1,1,233.5,234.41,100,500,1,1,233.45,234.43,15,105,1,2,233.4,234.5,110,63,2,4,GOOG
2024-10-21T12:30:10.800190917Z,2024-10-21T12:30:10.800024827Z,10,2,38,A,A,0,233.88,2,130,166090,13351078,233.81,233.88,2,2,2,1,233.8,233.96,105,400,2,2,233.78,233.97,200,7,1,1,233.7,234,1200,17,1,2,233.66,234.1,1,100,1,1,233.58,234.13,505,400,2,1,233.53,234.17,10,1,1,1,233.5,234.25,100,100,1,1,233.45,234.41,15,500,1,1,233.4,234.43,110,105,2,2,GOOG
2024-10-21T12:30:10.800218508Z,2024-10-21T12:30:10.800051476Z,10,2,38,C,B,2,233.78,200,130,167032,13351080,233.81,233.88,2,2,2,1,233.8,233.96,105,400,2,2,233.7,233.97,1200,7,1,1,233.66,234,1,17,1,2,233.58,234.1,505,100,2,1,233.53,234.13,10,400,1,1,233.5,234.17,100,1,1,1,233.45,234.25,15,100,1,1,233.4,234.41,110,500,2,1,233.39,234.43,10,105,1,2,GOOG
2024-10-21T12:30:10.801387277Z,2024-10-21T12:30:10.801218083Z,10,2,38,T,A,0,233.81,1,0,169194,13351086,233.81,233.88,2,2,2,1,233.8,233.96,105,400,2,2,233.7,233.97,1200,7,1,1,233.66,234,1,17,1,2,233.58,234.1,505,100,2,1,233.53,234.13,10,400,1,1,233.5,234.17,100,1,1,1,233.45,234.25,15,100,1,1,233.4,234.41,110,500,2,1,233.39,234.43,10,105,1,2,GOOG
2024-10-21T12:30:10.801387277Z,2024-10-21T12:30:10.801218083Z,10,2,38,T,A,0,233.81,1,130,169194,13351087,233.81,233.88,1,2,1,1,233.8,233.96,105,400,2,2,233.7,233.97,1200,7,1,1,233.66,234,1,17,1,2,233.58,234.1,505,100,2,1,233.53,234.13,10,400,1,1,233.5,234.17,100,1,1,1,233.45,234.25,15,100,1,1,233.4,234.41,110,500,2,1,233.39,234.43,10,105,1,2,GOOG
2024-10-21T12:30:10.801387277Z,2024-10-21T12:30:10.801218083Z,10,2,38,C,B,0,233.81,1,130,169194,13351087,233.8,233.88,105,2,2,1,233.7,233.96,1200,400,1,2,233.66,233.97,1,7,1,1,233.58,234,505,17,2,2,233.53,234.1,10,100,1,1,233.5,234.13,100,400,1,1,233.45,234.17,15,1,1,1,233.4,234.25,110,100,2,1,233.39,234.41,10,500,1,1,233.31,234.43,110,105,2,2,GOOG
2024-10-21T12:30:10.801408166Z,2024-10-21T12:30:10.801242022Z,10,2,38,A,A,0,233.86,100,130,166144,13351089,233.8,233.86,105,100,2,1,233.7,233.88,1200,2,1,1,233.66,233.96,1,400,1,2,233.58,233.97,505,7,2,1,233.53,234,10,17,1,2,233.5,234.1,100,100,1,1,233.45,234.13,15,400,1,1,233.4,234.17,110,1,2,1,233.39,234.25,10,100,1,1,233.31,234.41,110,500,2,1,GOOG
2024-10-21T12:30:10.801415386Z,2024-10-21T12:30:10.801249125Z,10,2,38,A,A,0,233.85,14,130,166261,13351090,233.8,233.85,105,14,2,1,233.7,233.86,1200,100,1,1,233.66,233.88,1,2,1,1,233.58,233.96,505,400,2,2,233.53,233.97,10,7,1,1,233.5,234,100,17,1,2,233.45,234.1,15,100,1,1,233.4,234.13,110,400,2,1,233.39,234.17,10,1,1,1,233.31,234.25,110,100,2,1,GOOG
2024-10-21T12:30:10.801421493Z,2024-10-21T12:30:10.801255194Z,10,2,38,A,A,1,233.86,100,130,166299,13351091,233.8,233.85,105,14,2,1,233.7,233.86,1200,200,1,2,233.66,233.88,1,2,1,1,233.58,233.96,505,400,2,2,233.53,233.97,10,7,1,1,233.5,234,100,17,1,2,233.45,234.1,15,100,1,1,233.4,234.13,110,400,2,1,233.39,234.17,10,1,1,1,233.31,234.25,110,100,2,1,GOOG
2024-10-21T12:30:10.801423606Z,2024-10-21T12:30:10.801256016Z,10,2,38,A,A,2,233.87,21,130,167590,13351092,233.8,233.85,105,14,2,1,233.7,233.86,1200,200,1,2,233.66,233.87,1,21,1,1,233.58,233.88,505,2,2,1,233.53,233.96,10,400,1,2,233.5,233.97,100,7,1,1,233.45,234,15,17,1,2,233.4,234.1,110,100,2,1,233.39,234.13,10,400,1,1,233.31,234.17,110,1,2,1,GOOG
2024-10-21T12:30:10.801453006Z,2024-10-21T12:30:10.801285169Z,10,2,38,C,A,1,233.86,100,130,167837,13351093,233.8,233.85,105,14,2,1,233.7,233.86,1200,100,1,1,233.66,233.87,1,21,1,1,233.58,233.88,505,2,2,1,233.53,233.96,10,400,1,2,233.5,233.97,100,7,1,1,233.45,234,15,17,1,2,233.4,234.1,110,100,2,1,233.39,234.13,10,400,1,1,233.31,234.17,110,1,2,1,GOOG
2024-10-21T12:30:10.801459804Z,2024-10-21T12:30:10.801293865Z,10,2,38,C,A,1,233.86,100,130,165939,13351094,233.8,233.85,105,14,2,1,233.7,233.87,1200,21,1,1,233.66,233.88,1,2,1,1,233.58,233.96,505,400,2,2,233.53,233.97,10,7,1,1,233.5,234,100,17,1,2,233.45,234.1,15,100,1,1,233.4,234.13,110,400,2,1,233.39,234.17,10,1,1,1,233.31,234.25,110,100,2,1,GOOG
2024-10-21T12:30:10.801684920Z,2024-10-21T12:30:10.801518640Z,10,2,38,A,A,3,233.89,100,130,166280,13351095,233.8,233.85,105,14,2,1,233.7,233.87,1200,21,1,1,233.66,233.88,1,2,1,1,233.58,233.89,505,100,2,1,233.53,233.96,10,400,1,2,233.5,233.97,100,7,1,1,233.45,234,15,17,1,2,233.4,234.1,110,100,2,1,233.39,234.13,10,400,1,1,233.31,234.17,110,1,2,1,GOOG
2024-10-21T12:30:10.802005192Z,2024-10-21T12:30:10.801839030Z,10,2,38,A,A,0,233.83,4,130,166162,13351096,233.8,233.83,105,4,2,1,233.7,233.85,1200,14,1,1,233.66,233.87,1,21,1,1,233.58,233.88,505,2,2,1,233.53,233.89,10,100,1,1,233.5,233.96,100,400,1,2,233.45,233.97,15,7,1,1,233.4,234,110,17,2,2,233.39,234.1,10,100,1,1,233.31,234.13,110,400,2,1,GOOG
2024-10-21T12:30:10.802018507Z,2024-10-21T12:30:10.801849830Z,10,2,38,T,A,0,233.8,5,0,168677,13351097,233.8,233.83,105,4,2,1,233.7,233.85,1200,14,1,1,233.66,233.87,1,21,1,1,233.58,233.88,505,2,2,1,233.53,233.89,10,100,1,1,233.5,233.96,100,400,1,2,233.45,233.97,15,7,1,1,233.4,234,110,17,2,2,233.39,234.1,10,100,1,1,233.31,234.13,110,400,2,1,GOOG
2024-10-21T12:30:10.802018507Z,2024-10-21T12:30:10.801849830Z,10,2,38,T,A,0,233.8,100,130,168677,13351098,233.8,233.83,100,4,1,1,233.7,233.85,1200,14,1,1,233.66,233.87,1,21,1,1,233.58,233.88,505,2,2,1,233.53,233.89,10,100,1,1,233.5,233.96,100,400,1,2,233.45,233.97,15,7,1,1,233.4,234,110,17,2,2,233.39,234.1,10,100,1,1,233.31,234.13,110,400,2,1,GOOG
2024-10-21T12:30:10.802018507Z,2024-10-21T12:30:10.801849830Z,10,2,38,C,B,0,233.8,100,130,168677,13351098,233.7,233.83,1200,4,1,1,233.66,233.85,1,14,1,1,233.58,233.87,505,21,2,1,233.53,233.88,10,2,1,1,233.5,233.89,100,100,1,1,233.45,233.96,15,400,1,2,233.4,233.97,110,7,2,1,233.39,234,10,17,1,2,233.31,234.1,110,100,2,1,233.3,234.13,100,400,1,1,GOOG
2024-10-21T12:30:10.802042064Z,2024-10-21T12:30:10.801875239Z,10,2,38,A,A,0,233.82,100,130,166825,13351100,233.7,233.82,1200,200,1,2,233.66,233.83,1,4,1,1,233.58,233.85,505,14,2,1,233.53,233.87,10,21,1,1,233.5,233.88,100,2,1,1,233.45,233.89,15,100,1,1,233.4,233.96,110,400,2,2,233.39,233.97,10,7,1,1,233.31,234,110,17,2,2,233.3,234.1,100,100,1,1,GOOG
2024-10-21T12:30:10.802051826Z,2024-10-21T12:30:10.801885691Z,10,2,38,A,A,0,233.82,100,130,166135,13351101,233.7,233.82,1200,300,1,3,233.66,233.83,1,4,1,1,233.58,233.85,505,14,2,1,233.53,233.87,10,21,1,1,233.5,233.88,100,2,1,1,233.45,233.89,15,100,1,1,233.4,233.96,110,400,2,2,233.39,233.97,10,7,1,1,233.31,234,110,17,2,2,233.3,234.1,100,100,1,1,GOOG
2024-10-21T12:30:10.802056341Z,2024-10-21T12:30:10.801887002Z,10,2,38,A,A,0,233.82,100,130,169339,13351102,233.7,233.82,1200,400,1,4,233.66,233.83,1,4,1,1,233.58,233.85,505,14,2,1,233.53,233.87,10,21,1,1,233.5,233.88,100,2,1,1,233.45,233.89,15,100,1,1,233.4,233.96,110,400,2,2,233.39,233.97,10,7,1,1,233.31,234,110,17,2,2,233.3,234.1,100,100,1,1,GOOG
2024-10-21T12:30:10.802062956Z,2024-10-21T12:30:10.801896921Z,10,2,38,C,A,0,233.82,100,130,166035,13351103,233.7,233.82,1200,300,1,3,233.66,233.83,1,4,1,1,233.58,233.85,505,14,2,1,233.53,233.87,10,21,1,1,233.5,233.88,100,2,1,1,233.45,233.89,15,100,1,1,233.4,233.96,110,400,2,2,233.39,233.97,10,7,1,1,233.31,234,110,17,2,2,233.3,234.1,100,100,1,1,GOOG
2024-10-21T12:30:10.802076696Z,2024-10-21T12:30:10.801910649Z,10,2,38,C,A,5,233.89,100,130,166047,13351104,233.7,233.82,1200,300,1,3,233.66,233.83,1,4,1,1,233.58,233.85,505,14,2,1,233.53,233.87,10,21,1,1,233.5,233.88,100,2,1,1,233.45,233.96,15,400,1,2,233.4,233.97,110,7,2,1,233.39,234,10,17,1,2,233.31,234.1,110,100,2,1,233.3,234.13,100,400,1,1,GOOG
2024-10-21T12:30:10.802078886Z,2024-10-21T12:30:10.801912958Z,10,2,38,C,A,0,233.82,100,130,165928,13351105,233.7,233.82,1200,200,1,2,233.66,233.83,1,4,1,1,233.58,233.85,505,14,2,1,233.53,233.87,10,21,1,1,233.5,233.88,100,2,1,1,233.45,233.96,15,400,1,2,233.4,233.97,110,7,2,1,233.39,234,10,17,1,2,233.31,234.1,110,100,2,1,233.3,234.13,100,400,1,1,GOOG
2024-10-21T12:30:10.802114011Z,2024-10-21T12:30:10.801948090Z,10,2,38,C,A,0,233.82,100,130,165921,13351106,233.7,233.82,1200,100,1,1,233.66,233.83,1,4,1,1,233.58,233.85,505,14,2,1,233.53,233.87,10,21,1,1,233.5,233.88,100,2,1,1,233.45,233.96,15,400,1,2,233.4,233.97,110,7,2,1,233.39,234,10,17,1,2,233.31,234.1,110,100,2,1,233.3,234.13,100,400,1,1,GOOG
2024-10-21T12:30:10.802313903Z,2024-10-21T12:30:10.802147907Z,10,2,38,C,A,0,233.82,100,130,165996,13351107,233.7,233.83,1200,4,1,1,233.66,233.85,1,14,1,1,233.58,233.87,505,21,2,1,233.53,233.88,10,2,1,1,233.5,233.96,100,400,1,2,233.45,233.97,15,7,1,1,233.4,234,110,17,2,2,233.39,234.1,10,100,1,1,233.31,234.13,110,400,2,1,233.3,234.17,100,1,1,1,GOOG
2024-10-21T12:30:10.802335407Z,2024-10-21T12:30:10.802168655Z,10,2,38,C,A,1,233.85,14,130,166752,13351108,233.7,233.83,1200,4,1,1,233.66,233.87,1,21,1,1,233.58,233.88,505,2,2,1,233.53,233.96,10,400,1,2,233.5,233.97,100,7,1,1,233.45,234,15,17,1,2,233.4,234.1,110,100,2,1,233.39,234.13,10,400,1,1,233.31,234.17,110,1,2,1,233.3,234.25,100,100,1,1,GOOG
2024-10-21T12:30:10.803237363Z,2024-10-21T12:30:10.803071076Z,10,2,38,C,A,4,233.97,7,130,166287,13351112,233.7,233.83,1200,4,1,1,233.66,233.87,1,21,1,1,233.58,233.88,505,2,2,1,233.53,233.96,10,400,1,2,233.5,234,100,17,1,2,233.45,234.1,15,100,1,1,233.4,234.13,110,400,2,1,233.39,234.17,10,1,1,1,233.31,234.25,110,100,2,1,233.3,234.41,100,500,1,1,GOOG
2024-10-21T12:30:10.804290650Z,2024-10-21T12:30:10.804124159Z,10,2,38,C,A,2,233.88,2,130,166491,13351118,233.7,233.83,1200,4,1,1,233.66,233.87,1,21,1,1,233.58,233.96,505,400,2,2,233.53,234,10,17,1,2,233.5,234.1,100,100,1,1,233.45,234.13,15,400,1,1,233.4,234.17,110,1,2,1,233.39,234.25,10,100,1,1,233.31,234.41,110,500,2,1,233.3,234.43,100,105,1,2,GOOG
2024-10-21T12:30:10.806095967Z,2024-10-21T12:30:10.805929875Z,10,2,38,C,A,0,233.83,4,130,166092,13351123,233.7,233.87,1200,21,1,1,233.66,233.96,1,400,1,2,233.58,234,505,17,2,2,233.53,234.1,10,100,1,1,233.5,234.13,100,400,1,1,233.45,234.17,15,1,1,1,233.4,234.25,110,100,2,1,233.39,234.41,10,500,1,1,233.31,234.43,110,105,2,2,233.3,234.5,100,63,1,4,GOOG
2024-10-21T12:30:10.872321876Z,2024-10-21T12:30:10.872155138Z,10,2,38,A,B,2,233.62,200,130,166738,13351674,233.7,233.87,1200,21,1,1,233.66,233.96,1,400,1,2,233.62,234,200,17,1,2,233.58,234.1,505,100,2,1,233.53,234.13,10,400,1,1,233.5,234.17,100,1,1,1,233.45,234.25,15,100,1,1,233.4,234.41,110,500,2,1,233.39,234.43,10,105,1,2,233.31,234.5,110,63,2,4,GOOG
2024-10-21T12:30:10.898101085Z,2024-10-21T12:30:10.897934717Z,10,2,38,A,B,2,233.62,200,130,166368,13351708,233.7,233.87,1200,21,1,1,233.66,233.96,1,400,1,2,233.62,234,400,17,2,2,233.58,234.1,505,100,2,1,233.53,234.13,10,400,1,1,233.5,234.17,100,1,1,1,233.45,234.25,15,100,1,1,233.4,234.41,110,500,2,1,233.39,234.43,10,105,1,2,233.31,234.5,110,63,2,4,GOOG
2024-10-21T12:30:10.903932828Z,2024-10-21T12:30:10.903766597Z,10,2,38,C,A,0,233.87,21,130,166231,13351712,233.7,233.96,1200,400,1,2,233.66,234,1,17,1,2,233.62,234.1,400,100,2,1,233.58,234.13,505,400,2,1,233.53,234.17,10,1,1,1,233.5,234.25,100,100,1,1,233.45,234.41,15,500,1,1,233.4,234.43,110,105,2,2,233.39,234.5,10,63,1,4,233.31,234.59,110,60,2,1,GOOG
2024-10-21T12:30:10.926143379Z,2024-10-21T12:30:10.925970633Z,10,2,38,A,A,0,233.91,400,130,172746,13351770,233.7,233.91,1200,400,1,1,233.66,234,1,17,1,2,233.62,234.1,400,100,2,1,233.58,234.13,505,400,2,1,233.53,234.17,10,1,1,1,233.5,234.25,100,100,1,1,233.45,234.41,15,500,1,1,233.4,234.43,110,105,2,2,233.39,234.5,10,63,1,4,233.31,234.59,110,60,2,1,GOOG
2024-10-21T12:30:11.987630030Z,2024-10-21T12:30:11.987463739Z,10,2,38,C,B,2,233.62,200,130,166291,13353675,233.7,233.91,1200,400,1,1,233.66,234,1,17,1,2,233.62,234.1,200,100,1,1,233.58,234.13,505,400,2,1,233.53,234.17,10,1,1,1,233.5,234.25,100,100,1,1,233.45,234.41,15,500,1,1,233.4,234.43,110,105,2,2,233.39,234.5,10,63,1,4,233.31,234.59,110,60,2,1,GOOG
2024-10-21T12:30:11.987640828Z,2024-10-21T12:30:11.987474545Z,10,2,38,C,B,2,233.62,200,130,166283,13353676,233.7,233.91,1200,400,1,1,233.66,234,1,17,1,2,233.58,234.1,505,100,2,1,233.53,234.13,10,400,1,1,233.5,234.17,100,1,1,1,233.45,234.25,15,100,1,1,233.4,234.41,110,500,2,1,233.39,234.43,10,105,1,2,233.31,234.5,110,63,2,4,233.3,234.59,100,60,1,1,GOOG
2024-10-21T12:30:11.987652703Z,2024-10-21T12:30:11.987486150Z,10,2,38,A,B,2,233.6,200,130,166553,13353677,233.7,233.91,1200,400,1,1,233.66,234,1,17,1,2,233.6,234.1,200,100,1,1,233.58,234.13,505,400,2,1,233.53,234.17,10,1,1,1,233.5,234.25,100,100,1,1,233.45,234.41,15,500,1,1,233.4,234.43,110,105,2,2,233.39,234.5,10,63,1,4,233.31,234.59,110,60,2,1,GOOG
2024-10-21T12:30:12.806349843Z,2024-10-21T12:30:12.806183466Z,10,2,38,A,A,1,233.97,7,130,166377,13354393,233.7,233.91,1200,400,1,1,233.66,233.97,1,7,1,1,233.6,234,200,17,1,2,233.58,234.1,505,100,2,1,233.53,234.13,10,400,1,1,233.5,234.17,100,1,1,1,233.45,234.25,15,100,1,1,233.4,234.41,110,500,2,1,233.39,234.43,10,105,1,2,233.31,234.5,110,63,2,4,GOOG
2024-10-21T12:30:13.320307781Z,2024-10-21T12:30:13.320141102Z,10,2,38,A,B,2,233.61,200,130,166679,13354988,233.7,233.91,1200,400,1,1,233.66,233.97,1,7,1,1,233.61,234,200,17,1,2,233.58,234.1,505,100,2,1,233.53,234.13,10,400,1,1,233.5,234.17,100,1,1,1,233.45,234.25,15,100,1,1,233.4,234.41,110,500,2,1,233.39,234.43,10,105,1,2,233.31,234.5,110,63,2,4,GOOG
2024-10-21T12:30:13.927027211Z,2024-10-21T12:30:13.926860673Z,10,2,38,A,B,1,233.68,200,130,166538,13356286,233.7,233.91,1200,400,1,1,233.68,233.97,200,7,1,1,233.66,234,1,17,1,2,233.58,234.1,505,100,2,1,233.53,234.13,10,400,1,1,233.5,234.17,100,1,1,1,233.45,234.25,15,100,1,1,233.4,234.41,110,500,2,1,233.39,234.43,10,105,1,2,233.31,234.5,110,63,2,4,GOOG
2024-10-21T12:30:33.768736428Z,2024-10-21T12:30:33.768570061Z,10,2,38,C,B,1,233.68,200,130,166367,13375759,233.7,233.91,1200,400,1,1,233.66,233.97,1,7,1,1,233.58,234,505,17,2,2,233.53,234.1,10,100,1,1,233.5,234.13,100,400,1,1,233.45,234.17,15,1,1,1,233.4,234.25,110,100,2,1,233.39,234.41,10,500,1,1,233.31,234.43,110,105,2,2,233.3,234.5,100,63,1,4,GOOG
2024-10-21T12:30:33.768783306Z,2024-10-21T12:30:33.768615671Z,10,2,38,A,A,0,233.86,2,130,167635,13375763,233.7,233.86,1200,2,1,1,233.66,233.91,1,400,1,1,233.58,233.97,505,7,2,1,233.53,234,10,17,1,2,233.5,234.1,100,100,1,1,233.45,234.13,15,400,1,1,233.4,234.17,110,1,2,1,233.39,234.25,10,100,1,1,233.31,234.41,110,500,2,1,233.3,234.43,100,105,1,2,GOOG
2024-10-21T12:30:33.772891039Z,2024-10-21T12:30:33.772724890Z,10,2,38,C,A,0,233.86,2,130,166149,13375767,233.7,233.91,1200,400,1,1,233.66,233.97,1,7,1,1,233.58,234,505,17,2,2,233.53,234.1,10,100,1,1,233.5,234.13,100,400,1,1,233.45,234.17,15,1,1,1,233.4,234.25,110,100,2,1,233.39,234.41,10,500,1,1,233.31,234.43,110,105,2,2,233.3,234.5,100,63,1,4,GOOG
2024-10-21T12:30:33.842053425Z,2024-10-21T12:30:33.841886930Z,10,2,38,A,B,3,233.53,400,130,166495,13375851,233.7,233.91,1200,400,1,1,233.66,233.97,1,7,1,1,233.58,234,505,17,2,2,233.53,234.1,410,100,2,1,233.5,234.13,100,400,1,1,233.45,234.17,15,1,1,1,233.4,234.25,110,100,2,1,233.39,234.41,10,500,1,1,233.31,234.43,110,105,2,2,233.3,234.5,100,63,1,4,GOOG
2024-10-21T12:30:33.993930780Z,2024-10-21T12:30:33.993763813Z,10,2,38,A,B,3,233.57,200,130,166967,13375889,233.7,233.91,1200,400,1,1,233.66,233.97,1,7,1,1,233.58,234,505,17,2,2,233.57,234.1,200,100,1,1,233.53,234.13,10,400,1,1,233.5,234.17,100,1,1,1,233.45,234.25,15,100,1,1,233.4,234.41,110,500,2,1,233.39,234.43,10,105,1,2,233.31,234.5,110,63,2,4,GOOG
2024-10-21T12:30:34.614057394Z,2024-10-21T12:30:34.613890939Z,10,2,38,A,B,3,233.57,200,130,166455,13376208,233.7,233.91,1200,400,1,1,233.66,233.97,1,7,1,1,233.58,234,505,17,2,2,233.57,234.1,400,100,2,1,233.53,234.13,10,400,1,1,233.5,234.17,100,1,1,1,233.45,234.25,15,100,1,1,233.4,234.41,110,500,2,1,233.39,234.43,10,105,1,2,233.31,234.5,110,63,2,4,GOOG
2024-10-21T12:30:34.668260203Z,2024-10-21T12:30:34.668094071Z,10,2,38,C,B,3,233.57,200,130,166132,13376228,233.7,233.91,1200,400,1,1,233.66,233.97,1,7,1,1,233.58,234,505,17,2,2,233.57,234.1,200,100,1,1,233.53,234.13,10,400,1,1,233.5,234.17,100,1,1,1,233.45,234.25,15,100,1,1,233.4,234.41,110,500,2,1,233.39,234.43,10,105,1,2,233.31,234.5,110,63,2,4,GOOG
2024-10-21T12:30:34.668273099Z,2024-10-21T12:30:34.668106643Z,10,2,38,A,B,2,233.61,200,130,166456,13376229,233.7,233.91,1200,400,1,1,233.66,233.97,1,7,1,1,233.61,234,200,17,1,2,233.58,234.1,505,100,2,1,233.53,234.13,10,400,1,1,233.5,234.17,100,1,1,1,233.45,234.25,15,100,1,1,233.4,234.41,110,500,2,1,233.39,234.43,10,105,1,2,233.31,234.5,110,63,2,4,GOOG
2024-10-21T12:30:35.854025768Z,2024-10-21T12:30:35.853859462Z,10,2,38,C,A,1,233.97,7,130,166306,13377241,233.7,233.91,1200,400,1,1,233.66,234,1,17,1,2,233.61,234.1,200,100,1,1,233.58,234.13,505,400,2,1,233.53,234.17,10,1,1,1,233.5,234.25,100,100,1,1,233.45,234.41,15,500,1,1,233.4,234.43,110,105,2,2,233.39,234.5,10,63,1,4,233.31,234.59,110,60,2,1,GOOG
2024-10-21T12:30:36.897254958Z,2024-10-21T12:30:36.897088633Z,10,2,38,A,B,2,233.63,200,130,166325,13378495,233.7,233.91,1200,400,1,1,233.66,234,1,17,1,2,233.63,234.1,200,100,1,1,233.58,234.13,505,400,2,1,233.53,234.17,10,1,1,1,233.5,234.25,100,100,1,1,233.45,234.41,15,500,1,1,233.4,234.43,110,105,2,2,233.39,234.5,10,63,1,4,233.31,234.59,110,60,2,1,GOOG
2024-10-21T12:30:37.857455846Z,2024-10-21T12:30:37.857289497Z,10,2,38,A,A,0,233.91,7,130,166349,13379698,233.7,233.91,1200,407,1,2,233.66,234,1,17,1,2,233.63,234.1,200,100,1,1,233.58,234.13,505,400,2,1,233.53,234.17,10,1,1,1,233.5,234.25,100,100,1,1,233.45,234.41,15,500,1,1,233.4,234.43,110,105,2,2,233.39,234.5,10,63,1,4,233.31,234.59,110,60,2,1,GOOG
2024-10-21T12:30:37.933071217Z,2024-10-21T12:30:37.932904919Z,10,2,38,C,A,0,233.91,400,130,166298,13379830,233.7,233.91,1200,7,1,1,233.66,234,1,17,1,2,233.63,234.1,200,100,1,1,233.58,234.13,505,400,2,1,233.53,234.17,10,1,1,1,233.5,234.25,100,100,1,1,233.45,234.41,15,500,1,1,233.4,234.43,110,105,2,2,233.39,234.5,10,63,1,4,233.31,234.59,110,60,2,1,GOOG
2024-10-21T12:30:37.933084228Z,2024-10-21T12:30:37.932917819Z,10,2,38,A,A,1,233.93,200,130,166409,13379831,233.7,233.91,1200,7,1,1,233.66,233.93,1,200,1,1,233.63,234,200,17,1,2,233.58,234.1,505,100,2,1,233.53,234.13,10,400,1,1,233.5,234.17,100,1,1,1,233.45,234.25,15,100,1,1,233.4,234.41,110,500,2,1,233.39,234.43,10,105,1,2,233.31,234.5,110,63,2,4,GOOG
2024-10-21T12:30:40.401799790Z,2024-10-21T12:30:40.401633392Z,10,2,38,A,B,2,233.64,200,130,166398,13382028,233.7,233.91,1200,7,1,1,233.66,233.93,1,200,1,1,233.64,234,200,17,1,2,233.58,234.1,505,100,2,1,233.53,234.13,10,400,1,1,233.5,234.17,100,1,1,1,233.45,234.25,15,100,1,1,233.4,234.41,110,500,2,1,233.39,234.43,10,105,1,2,233.31,234.5,110,63,2,4,GOOG
2024-10-21T12:30:40.472793565Z,2024-10-21T12:30:40.472627145Z,10,2,38,A,A,1,233.93,200,130,166420,13382215,233.7,233.91,1200,7,1,1,233.66,233.93,1,400,1,2,233.64,234,200,17,1,2,233.58,234.1,505,100,2,1,233.53,234.13,10,400,1,1,233.5,234.17,100,1,1,1,233.45,234.25,15,100,1,1,233.4,234.41,110,500,2,1,233.39,234.43,10,105,1,2,233.31,234.5,110,63,2,4,GOOG
2024-10-21T12:30:40.523923090Z,2024-10-21T12:30:40.523757097Z,10,2,38,C,A,1,233.93,200,130,165993,13382285,233.7,233.91,1200,7,1,1,233.66,233.93,1,200,1,1,233.64,234,200,17,1,2,233.58,234.1,505,100,2,1,233.53,234.13,10,400,1,1,233.5,234.17,100,1,1,1,233.45,234.25,15,100,1,1,233.4,234.41,110,500,2,1,233.39,234.43,10,105,1,2,233.31,234.5,110,63,2,4,GOOG
2024-10-21T12:30:40.523936566Z,2024-10-21T12:30:40.523770024Z,10,2,38,A,A,0,233.87,200,130,166542,13382286,233.7,233.87,1200,200,1,1,233.66,233.91,1,7,1,1,233.64,234,200,17,1,2,233.58,234.1,505,100,2,1,233.53,234.13,10,400,1,1,233.5,234.17,100,1,1,1,233.45,234.25,15,100,1,1,233.4,234.41,110,500,2,1,233.39,234.43,10,105,1,2,233.31,234.5,110,63,2,4,GOOG
2024-10-21T12:30:40.959465649Z,2024-10-21T12:30:40.959299618Z,10,2,38,C,A,0,233.87,200,130,166031,13382848,233.7,233.91,1200,7,1,1,233.66,234,1,17,1,2,233.64,234.1,200,100,1,1,233.58,234.13,505,400,2,1,233.53,234.17,10,1,1,1,233.5,234.25,100,100,1,1,233.45,234.41,15,500,1,1,233.4,234.43,110,105,2,2,233.39,234.5,10,63,1,4,233.31,234.59,110,60,2,1,GOOG
2024-10-21T12:30:40.959478166Z,2024-10-21T12:30:40.959311816Z,10,2,38,A,A,1,234,200,130,166350,13382849,233.7,233.91,1200,7,1,1,233.66,234,1,217,1,3,233.64,234.1,200,100,1,1,233.58,234.13,505,400,2,1,233.53,234.17,10,1,1,1,233.5,234.25,100,100,1,1,233.45,234.41,15,500,1,1,233.4,234.43,110,105,2,2,233.39,234.5,10,63,1,4,233.31,234.59,110,60,2,1,GOOG
2024-10-21T12:30:40.959825223Z,2024-10-21T12:30:40.959659070Z,10,2,38,A,A,1,234,200,130,166153,13382851,233.7,233.91,1200,7,1,1,233.66,234,1,417,1,4,233.64,234.1,200,100,1,1,233.58,234.13,505,400,2,1,233.53,234.17,10,1,1,1,233.5,234.25,100,100,1,1,233.45,234.41,15,500,1,1,233.4,234.43,110,105,2,2,233.39,234.5,10,63,1,4,233.31,234.59,110,60,2,1,GOOG
2024-10-21T12:30:41.011466621Z,2024-10-21T12:30:41.011299851Z,10,2,38,C,A,1,234,200,130,166770,13382912,233.7,233.91,1200,7,1,1,233.66,234,1,217,1,3,233.64,234.1,200,100,1,1,233.58,234.13,505,400,2,1,233.53,234.17,10,1,1,1,233.5,234.25,100,100,1,1,233.45,234.41,15,500,1,1,233.4,234.43,110,105,2,2,233.39,234.5,10,63,1,4,233.31,234.59,110,60,2,1,GOOG
2024-10-21T12:30:41.011478729Z,2024-10-21T12:30:41.011312427Z,10,2,38,A,A,1,233.93,400,130,166302,13382913,233.7,233.91,1200,7,1,1,233.66,233.93,1,400,1,1,233.64,234,200,17,1,2,233.58,234.1,505,100,2,1,233.53,234.13,10,400,1,1,233.5,234.17,100,1,1,1,233.45,234.25,15,100,1,1,233.4,234.41,110,500,2,1,233.39,234.43,10,105,1,2,233.31,234.5,110,63,2,4,GOOG
2024-10-21T12:30:42.852966987Z,2024-10-21T12:30:42.852800519Z,10,2,38,A,B,2,233.65,200,130,166468,13385315,233.7,233.91,1200,7,1,1,233.66,233.93,1,400,1,1,233.65,234,200,17,1,2,233.58,234.1,505,100,2,1,233.53,234.13,10,400,1,1,233.5,234.17,100,1,1,1,233.45,234.25,15,100,1,1,233.4,234.41,110,500,2,1,233.39,234.43,10,105,1,2,233.31,234.5,110,63,2,4,GOOG
2024-10-21T12:30:42.911272136Z,2024-10-21T12:30:42.911106065Z,10,2,38,C,B,2,233.65,200,130,166071,13385545,233.7,233.91,1200,7,1,1,233.66,233.93,1,400,1,1,233.58,234,505,17,2,2,233.53,234.1,10,100,1,1,233.5,234.13,100,400,1,1,233.45,234.17,15,1,1,1,233.4,234.25,110,100,2,1,233.39,234.41,10,500,1,1,233.31,234.43,110,105,2,2,233.3,234.5,100,63,1,4,GOOG
2024-10-21T12:30:42.911285351Z,2024-10-21T12:30:42.911118704Z,10,2,38,A,B,2,233.63,200,130,166647,13385546,233.7,233.91,1200,7,1,1,233.66,233.93,1,400,1,1,233.63,234,200,17,1,2,233.58,234.1,505,100,2,1,233.53,234.13,10,400,1,1,233.5,234.17,100,1,1,1,233.45,234.25,15,100,1,1,233.4,234.41,110,500,2,1,233.39,234.43,10,105,1,2,233.31,234.5,110,63,2,4,GOOG
2024-10-21T12:30:43.077926603Z,2024-10-21T12:30:43.077759194Z,10,2,38,A,A,0,233.81,100,130,167409,13386086,233.7,233.81,1200,100,1,1,233.66,233.91,1,7,1,1,233.63,233.93,200,400,1,1,233.58,234,505,17,2,2,233.53,234.1,10,100,1,1,233.5,234.13,100,400,1,1,233.45,234.17,15,1,1,1,233.4,234.25,110,100,2,1,233.39,234.41,10,500,1,1,233.31,234.43,110,105,2,2,GOOG
2024-10-21T12:30:43.078011775Z,2024-10-21T12:30:43.077845659Z,10,2,38,A,A,0,233.79,2,130,166116,13386087,233.7,233.79,1200,2,1,1,233.66,233.81,1,100,1,1,233.63,233.91,200,7,1,1,233.58,233.93,505,400,2,1,233.53,234,10,17,1,2,233.5,234.1,100,100,1,1,233.45,234.13,15,400,1,1,233.4,234.17,110,1,2,1,233.39,234.25,10,100,1,1,233.31,234.41,110,500,2,1,GOOG
2024-10-21T12:30:43.078020128Z,2024-10-21T12:30:43.077853974Z,10,2,38,A,A,2,233.82,27,130,166154,13386088,233.7,233.79,1200,2,1,1,233.66,233.81,1,100,1,1,233.63,233.82,200,27,1,1,233.58,233.91,505,7,2,1,233.53,233.93,10,400,1,1,233.5,234,100,17,1,2,233.45,234.1,15,100,1,1,233.4,234.13,110,400,2,1,233.39,234.17,10,1,1,1,233.31,234.25,110,100,2,1,GOOG
2024-10-21T12:30:43.078046807Z,2024-10-21T12:30:43.077880864Z,10,2,38,C,B,2,233.63,200,130,165943,13386089,233.7,233.79,1200,2,1,1,233.66,233.81,1,100,1,1,233.58,233.82,505,27,2,1,233.53,233.91,10,7,1,1,233.5,233.93,100,400,1,1,233.45,234,15,17,1,2,233.4,234.1,110,100,2,1,233.39,234.13,10,400,1,1,233.31,234.17,110,1,2,1,233.3,234.25,100,100,1,1,GOOG
2024-10-21T12:30:43.078335932Z,2024-10-21T12:30:43.078169970Z,10,2,38,C,A,1,233.81,100,130,165962,13386090,233.7,233.79,1200,2,1,1,233.66,233.82,1,27,1,1,233.58,233.91,505,7,2,1,233.53,233.93,10,400,1,1,233.5,234,100,17,1,2,233.45,234.1,15,100,1,1,233.4,234.13,110,400,2,1,233.39,234.17,10,1,1,1,233.31,234.25,110,100,2,1,233.3,234.41,100,500,1,1,GOOG
2024-10-21T12:30:43.082113679Z,2024-10-21T12:30:43.081947674Z,10,2,38,C,A,1,233.82,27,130,166005,13386104,233.7,233.79,1200,2,1,1,233.66,233.91,1,7,1,1,233.58,233.93,505,400,2,1,233.53,234,10,17,1,2,233.5,234.1,100,100,1,1,233.45,234.13,15,400,1,1,233.4,234.17,110,1,2,1,233.39,234.25,10,100,1,1,233.31,234.41,110,500,2,1,233.3,234.43,100,105,1,2,GOOG
2024-10-21T12:30:43.082118638Z,2024-10-21T12:30:43.081952786Z,10,2,38,C,A,0,233.79,2,130,165852,13386105,233.7,233.91,1200,7,1,1,233.66,233.93,1,400,1,1,233.58,234,505,17,2,2,233.53,234.1,10,100,1,1,233.5,234.13,100,400,1,1,233.45,234.17,15,1,1,1,233.4,234.25,110,100,2,1,233.39,234.41,10,500,1,1,233.31,234.43,110,105,2,2,233.3,234.5,100,63,1,4,GOOG
2024-10-21T12:30:43.145395752Z,2024-10-21T12:30:43.145229452Z,10,2,38,A,B,2,233.6,400,130,166300,13386208,233.7,233.91,1200,7,1,1,233.66,233.93,1,400,1,1,233.6,234,400,17,1,2,233.58,234.1,505,100,2,1,233.53,234.13,10,400,1,1,233.5,234.17,100,1,1,1,233.45,234.25,15,100,1,1,233.4,234.41,110,500,2,1,233.39,234.43,10,105,1,2,233.31,234.5,110,63,2,4,GOOG
2024-10-21T12:30:51.064674265Z,2024-10-21T12:30:51.064507066Z,10,2,38,A,A,0,233.9,200,130,167199,13392451,233.7,233.9,1200,200,1,1,233.66,233.91,1,7,1,1,233.6,234,400,17,1,2,233.58,234.1,505,100,2,1,233.53,234.13,10,400,1,1,233.5,234.17,100,1,1,1,233.45,234.25,15,100,1,1,233.4,234.41,110,500,2,1,233.39,234.43,10,105,1,2,233.31,234.5,110,63,2,4,GOOG
2024-10-21T12:30:51.126805554Z,2024-10-21T12:30:51.126612912Z,10,2,38,C,A,1,233.91,7,130,192642,13392493,233.7,233.9,1200,200,1,1,233.66,234,1,17,1,2,233.6,234.1,400,100,1,1,233.58,234.13,505,400,2,1,233.53,234.17,10,1,1,1,233.5,234.25,100,100,1,1,233.45,234.41,15,500,1,1,233.4,234.43,110,105,2,2,233.39,234.5,10,63,1,4,233.31,234.59,110,60,2,1,GOOG
2024-10-21T12:30:53.132825110Z,2024-10-21T12:30:53.132658845Z,10,2,38,A,A,0,233.89,7,130,166265,13394395,233.7,233.89,1200,7,1,1,233.66,233.9,1,200,1,1,233.6,234,400,17,1,2,233.58,234.1,505,100,2,1,233.53,234.13,10,400,1,1,233.5,234.17,100,1,1,1,233.45,234.25,15,100,1,1,233.4,234.41,110,500,2,1,233.39,234.43,10,105,1,2,233.31,234.5,110,63,2,4,GOOG
2024-10-21T12:30:53.159112566Z,2024-10-21T12:30:53.158946223Z,10,2,38,C,A,1,233.9,200,130,166343,13394422,233.7,233.89,1200,7,1,1,233.66,234,1,17,1,2,233.6,234.1,400,100,1,1,233.58,234.13,505,400,2,1,233.53,234.17,10,1,1,1,233.5,234.25,100,100,1,1,233.45,234.41,15,500,1,1,233.4,234.43,110,105,2,2,233.39,234.5,10,63,1,4,233.31,234.59,110,60,2,1,GOOG
2024-10-21T12:30:53.159126656Z,2024-10-21T12:30:53.158960124Z,10,2,38,A,A,1,233.94,400,130,166532,13394423,233.7,233.89,1200,7,1,1,233.66,233.94,1,400,1,1,233.6,234,400,17,1,2,233.58,234.1,505,100,2,1,233.53,234.13,10,400,1,1,233.5,234.17,100,1,1,1,233.45,234.25,15,100,1,1,233.4,234.41,110,500,2,1,233.39,234.43,10,105,1,2,233.31,234.5,110,63,2,4,GOOG
2024-10-21T12:30:54.725160534Z,2024-10-21T12:30:54.724993656Z,10,2,38,A,B,2,233.61,400,130,166878,13395667,233.7,233.89,1200,7,1,1,233.66,233.94,1,400,1,1,233.61,234,400,17,1,2,233.58,234.1,505,100,2,1,233.53,234.13,10,400,1,1,233.5,234.17,100,1,1,1,233.45,234.25,15,100,1,1,233.4,234.41,110,500,2,1,233.39,234.43,10,105,1,2,233.31,234.5,110,63,2,4,GOOG
2024-10-21T12:30:57.250136599Z,2024-10-21T12:30:57.249970057Z,10,2,38,A,A,1,233.91,200,130,166542,13398703,233.7,233.89,1200,7,1,1,233.66,233.91,1,200,1,1,233.61,234,400,17,1,2,233.58,234.1,505,100,2,1,233.53,234.13,10,400,1,1,233.5,234.17,100,1,1,1,233.45,234.25,15,100,1,1,233.4,234.41,110,500,2,1,233.39,234.43,10,105,1,2,233.31,234.5,110,63,2,4,GOOG
2024-10-21T12:30:59.735815684Z,2024-10-21T12:30:59.735648884Z,10,2,38,A,A,1,233.9,200,130,166800,13401350,233.7,233.89,1200,7,1,1,233.66,233.9,1,200,1,1,233.61,234,400,17,1,2,233.58,234.1,505,100,2,1,233.53,234.13,10,400,1,1,233.5,234.17,100,1,1,1,233.45,234.25,15,100,1,1,233.4,234.41,110,500,2,1,233.39,234.43,10,105,1,2,233.31,234.5,110,63,2,4,GOOG
2024-10-21T12:31:00.042044822Z,2024-10-21T12:31:00.041878233Z,10,2,38,A,A,0,233.88,200,130,166589,13402076,233.7,233.88,1200,200,1,1,233.66,233.89,1,7,1,1,233.61,234,400,17,1,2,233.58,234.1,505,100,2,1,233.53,234.13,10,400,1,1,233.5,234.17,100,1,1,1,233.45,234.25,15,100,1,1,233.4,234.41,110,500,2,1,233.39,234.43,10,105,1,2,233.31,234.5,110,63,2,4,GOOG
2024-10-21T12:31:00.098919227Z,2024-10-21T12:31:00.098753103Z,10,2,38,C,A,1,233.89,7,130,166124,13402444,233.7,233.88,1200,200,1,1,233.66,234,1,17,1,2,233.61,234.1,400,100,1,1,233.58,234.13,505,400,2,1,233.53,234.17,10,1,1,1,233.5,234.25,100,100,1,1,233.45,234.41,15,500,1,1,233.4,234.43,110,105,2,2,233.39,234.5,10,63,1,4,233.31,234.59,110,60,2,1,GOOG
2024-10-21T12:31:00.156853823Z,2024-10-21T12:31:00.156687698Z,10,2,38,C,A,0,233.88,200,130,166125,13402657,233.7,234,1200,17,1,2,233.66,234.1,1,100,1,1,233.61,234.13,400,400,1,1,233.58,234.17,505,1,2,1,233.53,234.25,10,100,1,1,233.5,234.41,100,500,1,1,233.45,234.43,15,105,1,2,233.4,234.5,110,63,2,4,233.39,234.59,10,60,1,1,233.31,234.75,110,1,2,1,GOOG
2024-10-21T12:31:00.156866735Z,2024-10-21T12:31:00.156700602Z,10,2,38,A,A,0,233.9,200,130,166133,13402658,233.7,233.9,1200,200,1,1,233.66,234,1,17,1,2,233.61,234.1,400,100,1,1,233.58,234.13,505,400,2,1,233.53,234.17,10,1,1,1,233.5,234.25,100,100,1,1,233.45,234.41,15,500,1,1,233.4,234.43,110,105,2,2,233.39,234.5,10,63,1,4,233.31,234.59,110,60,2,1,GOOG
2024-10-21T12:31:00.172792189Z,2024-10-21T12:31:00.172626181Z,10,2,38,C,A,0,233.9,200,130,166008,13402690,233.7,234,1200,17,1,2,233.66,234.1,1,100,1,1,233.61,234.13,400,400,1,1,233.58,234.17,505,1,2,1,233.53,234.25,10,100,1,1,233.5,234.41,100,500,1,1,233.45,234.43,15,105,1,2,233.4,234.5,110,63,2,4,233.39,234.59,10,60,1,1,233.31,234.75,110,1,2,1,GOOG
2024-10-21T12:31:00.172805116Z,2024-10-21T12:31:00.172638682Z,10,2,38,A,A,0,233.94,400,130,166434,13402691,233.7,233.94,1200,400,1,1,233.66,234,1,17,1,2,233.61,234.1,400,100,1,1,233.58,234.13,505,400,2,1,233.53,234.17,10,1,1,1,233.5,234.25,100,100,1,1,233.45,234.41,15,500,1,1,233.4,234.43,110,105,2,2,233.39,234.5,10,63,1,4,233.31,234.59,110,60,2,1,GOOG
2024-10-21T12:31:00.400399117Z,2024-10-21T12:31:00.400232797Z,10,2,38,A,A,0,233.92,200,130,166320,13403529,233.7,233.92,1200,200,1,1,233.66,234,1,17,1,2,233.61,234.1,400,100,1,1,233.58,234.13,505,400,2,1,233.53,234.17,10,1,1,1,233.5,234.25,100,100,1,1,233.45,234.41,15,500,1,1,233.4,234.43,110,105,2,2,233.39,234.5,10,63,1,4,233.31,234.59,110,60,2,1,GOOG
2024-10-21T12:31:00.881101502Z,2024-10-21T12:31:00.880934995Z,10,2,38,C,A,0,233.92,200,130,166507,13404357,233.7,234,1200,17,1,2,233.66,234.1,1,100,1,1,233.61,234.13,400,400,1,1,233.58,234.17,505,1,2,1,233.53,234.25,10,100,1,1,233.5,234.41,100,500,1,1,233.45,234.43,15,105,1,2,233.4,234.5,110,63,2,4,233.39,234.59,10,60,1,1,233.31,234.75,110,1,2,1,GOOG
2024-10-21T12:31:00.881114450Z,2024-10-21T12:31:00.880948262Z,10,2,38,A,A,0,233.94,400,130,166188,13404358,233.7,233.94,1200,400,1,1,233.66,234,1,17,1,2,233.61,234.1,400,100,1,1,233.58,234.13,505,400,2,1,233.53,234.17,10,1,1,1,233.5,234.25,100,100,1,1,233.45,234.41,15,500,1,1,233.4,234.43,110,105,2,2,233.39,234.5,10,63,1,4,233.31,234.59,110,60,2,1,GOOG
2024-10-21T12:31:01.118721679Z,2024-10-21T12:31:01.118555295Z,10,2,38,A,A,0,233.93,200,130,166384,13404633,233.7,233.93,1200,200,1,1,233.66,234,1,17,1,2,233.61,234.1,400,100,1,1,233.58,234.13,505,400,2,1,233.53,234.17,10,1,1,1,233.5,234.25,100,100,1,1,233.45,234.41,15,500,1,1,233.4,234.43,110,105,2,2,233.39,234.5,10,63,1,4,233.31,234.59,110,60,2,1,GOOG
2024-10-21T12:31:01.146763916Z,2024-10-21T12:31:01.146597464Z,10,2,38,A,A,0,233.9,200,130,166452,13404693,233.7,233.9,1200,200,1,1,233.66,234,1,17,1,2,233.61,234.1,400,100,1,1,233.58,234.13,505,400,2,1,233.53,234.17,10,1,1,1,233.5,234.25,100,100,1,1,233.45,234.41,15,500,1,1,233.4,234.43,110,105,2,2,233.39,234.5,10,63,1,4,233.31,234.59,110,60,2,1,GOOG
2024-10-21T12:31:01.698949935Z,2024-10-21T12:31:01.698782682Z,10,2,38,A,B,0,233.76,10,130,167253,13405476,233.76,233.9,10,200,1,1,233.7,234,1200,17,1,2,233.66,234.1,1,100,1,1,233.61,234.13,400,400,1,1,233.58,234.17,505,1,2,1,233.53,234.25,10,100,1,1,233.5,234.41,100,500,1,1,233.45,234.43,15,105,1,2,233.4,234.5,110,63,2,4,233.39,234.59,10,60,1,1,GOOG
2024-10-21T12:31:02.104766747Z,2024-10-21T12:31:02.104600327Z,10,2,38,A,A,0,233.89,7,130,166420,13405925,233.76,233.89,10,7,1,1,233.7,233.9,1200,200,1,1,233.66,234,1,17,1,2,233.61,234.1,400,100,1,1,233.58,234.13,505,400,2,1,233.53,234.17,10,1,1,1,233.5,234.25,100,100,1,1,233.45,234.41,15,500,1,1,233.4,234.43,110,105,2,2,233.39,234.5,10,63,1,4,GOOG
2024-10-21T12:31:02.286726124Z,2024-10-21T12:31:02.286559844Z,10,2,38,C,A,1,233.9,200,130,166280,13406135,233.76,233.89,10,7,1,1,233.7,234,1200,17,1,2,233.66,234.1,1,100,1,1,233.61,234.13,400,400,1,1,233.58,234.17,505,1,2,1,233.53,234.25,10,100,1,1,233.5,234.41,100,500,1,1,233.45,234.43,15,105,1,2,233.4,234.5,110,63,2,4,233.39,234.59,10,60,1,1,GOOG
2024-10-21T12:31:02.286738616Z,2024-10-21T12:31:02.286572345Z,10,2,38,A,A,1,233.92,200,130,166271,13406136,233.76,233.89,10,7,1,1,233.7,233.92,1200,200,1,1,233.66,234,1,17,1,2,233.61,234.1,400,100,1,1,233.58,234.13,505,400,2,1,233.53,234.17,10,1,1,1,233.5,234.25,100,100,1,1,233.45,234.41,15,500,1,1,233.4,234.43,110,105,2,2,233.39,234.5,10,63,1,4,GOOG
2024-10-21T12:31:02.297232093Z,2024-10-21T12:31:02.297066314Z,10,2,38,C,A,1,233.92,200,130,165779,13406143,233.76,233.89,10,7,1,1,233.7,234,1200,17,1,2,233.66,234.1,1,100,1,1,233.61,234.13,400,400,1,1,233.58,234.17,505,1,2,1,233.53,234.25,10,100,1,1,233.5,234.41,100,500,1,1,233.45,234.43,15,105,1,2,233.4,234.5,110,63,2,4,233.39,234.59,10,60,1,1,GOOG
2024-10-21T12:31:02.297245858Z,2024-10-21T12:31:02.297079450Z,10,2,38,A,A,1,233.94,400,130,166408,13406144,233.76,233.89,10,7,1,1,233.7,233.94,1200,400,1,1,233.66,234,1,17,1,2,233.61,234.1,400,100,1,1,233.58,234.13,505,400,2,1,233.53,234.17,10,1,1,1,233.5,234.25,100,100,1,1,233.45,234.41,15,500,1,1,233.4,234.43,110,105,2,2,233.39,234.5,10,63,1,4,GOOG
2024-10-21T12:31:02.321020744Z,2024-10-21T12:31:02.320854035Z,10,2,38,A,B,3,233.65,200,130,166709,13406162,233.76,233.89,10,7,1,1,233.7,233.94,1200,400,1,1,233.66,234,1,17,1,2,233.65,234.1,200,100,1,1,233.58,234.13,505,400,2,1,233.53,234.17,10,1,1,1,233.5,234.25,100,100,1,1,233.45,234.41,15,500,1,1,233.4,234.43,110,105,2,2,233.39,234.5,10,63,1,4,GOOG
2024-10-21T12:31:03.262141913Z,2024-10-21T12:31:03.261814629Z,10,2,38,A,B,3,233.65,200,130,327284,13406966,233.76,233.89,10,7,1,1,233.7,233.94,1200,400,1,1,233.66,234,1,17,1,2,233.65,234.1,400,100,2,1,233.58,234.13,505,400,2,1,233.53,234.17,10,1,1,1,233.5,234.25,100,100,1,1,233.45,234.41,15,500,1,1,233.4,234.43,110,105,2,2,233.39,234.5,10,63,1,4,GOOG
2024-10-21T12:31:03.314769469Z,2024-10-21T12:31:03.312554281Z,10,2,38,A,B,2,233.68,200,130,2215188,13407030,233.76,233.89,10,7,1,1,233.7,233.94,1200,400,1,1,233.68,234,200,17,1,2,233.66,234.1,1,100,1,1,233.58,234.13,505,400,2,1,233.53,234.17,10,1,1,1,233.5,234.25,100,100,1,1,233.45,234.41,15,500,1,1,233.4,234.43,110,105,2,2,233.39,234.5,10,63,1,4,GOOG
2024-10-21T12:31:05.971552774Z,2024-10-21T12:31:05.971386477Z,10,2,38,A,A,1,233.93,400,130,166297,13409309,233.76,233.89,10,7,1,1,233.7,233.93,1200,400,1,1,233.68,234,200,17,1,2,233.66,234.1,1,100,1,1,233.58,234.13,505,400,2,1,233.53,234.17,10,1,1,1,233.5,234.25,100,100,1,1,233.45,234.41,15,500,1,1,233.4,234.43,110,105,2,2,233.39,234.5,10,63,1,4,GOOG
2024-10-21T12:31:10.467597154Z,2024-10-21T12:31:10.467431005Z,10,2,38,A,A,0,233.81,55,130,166149,13412654,233.76,233.81,10,55,1,1,233.7,233.89,1200,7,1,1,233.68,233.93,200,400,1,1,233.66,234,1,17,1,2,233.58,234.1,505,100,2,1,233.53,234.13,10,400,1,1,233.5,234.17,100,1,1,1,233.45,234.25,15,100,1,1,233.4,234.41,110,500,2,1,233.39,234.43,10,105,1,2,GOOG
2024-10-21T12:31:10.467664679Z,2024-10-21T12:31:10.467497398Z,10,2,38,T,A,0,233.76,10,130,167281,13412655,233.76,233.81,10,55,1,1,233.7,233.89,1200,7,1,1,233.68,233.93,200,400,1,1,233.66,234,1,17,1,2,233.58,234.1,505,100,2,1,233.53,234.13,10,400,1,1,233.5,234.17,100,1,1,1,233.45,234.25,15,100,1,1,233.4,234.41,110,500,2,1,233.39,234.43,10,105,1,2,GOOG
2024-10-21T12:31:10.467664679Z,2024-10-21T12:31:10.467497398Z,10,2,38,C,B,0,233.76,10,130,167281,13412655,233.7,233.81,1200,55,1,1,233.68,233.89,200,7,1,1,233.66,233.93,1,400,1,1,233.58,234,505,17,2,2,233.53,234.1,10,100,1,1,233.5,234.13,100,400,1,1,233.45,234.17,15,1,1,1,233.4,234.25,110,100,2,1,233.39,234.41,10,500,1,1,233.31,234.43,110,105,2,2,GOOG
2024-10-21T12:31:10.467686549Z,2024-10-21T12:31:10.467519660Z,10,2,38,A,A,0,233.8,100,130,166889,13412656,233.7,233.8,1200,100,1,1,233.68,233.81,200,55,1,1,233.66,233.89,1,7,1,1,233.58,233.93,505,400,2,1,233.53,234,10,17,1,2,233.5,234.1,100,100,1,1,233.45,234.13,15,400,1,1,233.4,234.17,110,1,2,1,233.39,234.25,10,100,1,1,233.31,234.41,110,500,2,1,GOOG
2024-10-21T12:31:10.467688659Z,2024-10-21T12:31:10.467521772Z,10,2,38,A,A,0,233.79,7,130,166887,13412657,233.7,233.79,1200,7,1,1,233.68,233.8,200,100,1,1,233.66,233.81,1,55,1,1,233.58,233.89,505,7,2,1,233.53,233.93,10,400,1,1,233.5,234,100,17,1,2,233.45,234.1,15,100,1,1,233.4,234.13,110,400,2,1,233.39,234.17,10,1,1,1,233.31,234.25,110,100,2,1,GOOG
2024-10-21T12:31:10.467702771Z,2024-10-21T12:31:10.467536010Z,10,2,38,A,A,1,233.8,77,130,166761,13412661,233.7,233.79,1200,7,1,1,233.68,233.8,200,177,1,2,233.66,233.81,1,55,1,1,233.58,233.89,505,7,2,1,233.53,233.93,10,400,1,1,233.5,234,100,17,1,2,233.45,234.1,15,100,1,1,233.4,234.13,110,400,2,1,233.39,234.17,10,1,1,1,233.31,234.25,110,100,2,1,GOOG
2024-10-21T12:31:10.467720432Z,2024-10-21T12:31:10.467551632Z,10,2,38,C,A,1,233.8,100,130,168800,13412662,233.7,233.79,1200,7,1,1,233.68,233.8,200,77,1,1,233.66,233.81,1,55,1,1,233.58,233.89,505,7,2,1,233.53,233.93,10,400,1,1,233.5,234,100,17,1,2,233.45,234.1,15,100,1,1,233.4,234.13,110,400,2,1,233.39,234.17,10,1,1,1,233.31,234.25,110,100,2,1,GOOG
2024-10-21T12:31:10.467742671Z,2024-10-21T12:31:10.467575929Z,10,2,38,C,B,1,233.68,200,130,166742,13412663,233.7,233.79,1200,7,1,1,233.66,233.8,1,77,1,1,233.58,233.81,505,55,2,1,233.53,233.89,10,7,1,1,233.5,233.93,100,400,1,1,233.45,234,15,17,1,2,233.4,234.1,110,100,2,1,233.39,234.13,10,400,1,1,233.31,234.17,110,1,2,1,233.3,234.25,100,100,1,1,GOOG
2024-10-21T12:31:10.471339928Z,2024-10-21T12:31:10.471173647Z,10,2,38,C,A,3,233.89,7,130,166281,13412675,233.7,233.79,1200,7,1,1,233.66,233.8,1,77,1,1,233.58,233.81,505,55,2,1,233.53,233.93,10,400,1,1,233.5,234,100,17,1,2,233.45,234.1,15,100,1,1,233.4,234.13,110,400,2,1,233.39,234.17,10,1,1,1,233.31,234.25,110,100,2,1,233.3,234.41,100,500,1,1,GOOG
2024-10-21T12:31:10.471693079Z,2024-10-21T12:31:10.471527171Z,10,2,38,C,A,2,233.81,55,130,165908,13412676,233.7,233.79,1200,7,1,1,233.66,233.8,1,77,1,1,233.58,233.93,505,400,2,1,233.53,234,10,17,1,2,233.5,234.1,100,100,1,1,233.45,234.13,15,400,1,1,233.4,234.17,110,1,2,1,233.39,234.25,10,100,1,1,233.31,234.41,110,500,2,1,233.3,234.43,100,105,1,2,GOOG
2024-10-21T12:31:10.525592720Z,2024-10-21T12:31:10.525425470Z,10,2,38,A,B,1,233.67,200,130,167250,13412733,233.7,233.79,1200,7,1,1,233.67,233.8,200,77,1,1,233.66,233.93,1,400,1,1,233.58,234,505,17,2,2,233.53,234.1,10,100,1,1,233.5,234.13,100,400,1,1,233.45,234.17,15,1,1,1,233.4,234.25,110,100,2,1,233.39,234.41,10,500,1,1,233.31,234.43,110,105,2,2,GOOG
2024-10-21T12:31:10.538792744Z,2024-10-21T12:31:10.538626301Z,10,2,38,C,B,1,233.67,200,130,166443,13412756,233.7,233.79,1200,7,1,1,233.66,233.8,1,77,1,1,233.58,233.93,505,400,2,1,233.53,234,10,17,1,2,233.5,234.1,100,100,1,1,233.45,234.13,15,400,1,1,233.4,234.17,110,1,2,1,233.39,234.25,10,100,1,1,233.31,234.41,110,500,2,1,233.3,234.43,100,105,1,2,GOOG
2024-10-21T12:31:10.538805664Z,2024-10-21T12:31:10.538638966Z,10,2,38,A,B,2,233.64,400,130,166698,13412757,233.7,233.79,1200,7,1,1,233.66,233.8,1,77,1,1,233.64,233.93,400,400,1,1,233.58,234,505,17,2,2,233.53,234.1,10,100,1,1,233.5,234.13,100,400,1,1,233.45,234.17,15,1,1,1,233.4,234.25,110,100,2,1,233.39,234.41,10,500,1,1,233.31,234.43,110,105,2,2,GOOG
2024-10-21T12:31:10.567771491Z,2024-10-21T12:31:10.567605274Z,10,2,38,C,A,0,233.79,7,130,166217,13412834,233.7,233.8,1200,77,1,1,233.66,233.93,1,400,1,1,233.64,234,400,17,1,2,233.58,234.1,505,100,2,1,233.53,234.13,10,400,1,1,233.5,234.17,100,1,1,1,233.45,234.25,15,100,1,1,233.4,234.41,110,500,2,1,233.39,234.43,10,105,1,2,233.31,234.5,110,63,2,4,GOOG
2024-10-21T12:31:10.567797038Z,2024-10-21T12:31:10.567631078Z,10,2,38,C,A,0,233.8,77,130,165960,13412835,233.7,233.93,1200,400,1,1,233.66,234,1,17,1,2,233.64,234.1,400,100,1,1,233.58,234.13,505,400,2,1,233.53,234.17,10,1,1,1,233.5,234.25,100,100,1,1,233.45,234.41,15,500,1,1,233.4,234.43,110,105,2,2,233.39,234.5,10,63,1,4,233.31,234.59,110,60,2,1,GOOG
2024-10-21T12:31:12.174742395Z,2024-10-21T12:31:12.174575957Z,10,2,38,A,B,2,233.65,400,130,166438,13414627,233.7,233.93,1200,400,1,1,233.66,234,1,17,1,2,233.65,234.1,400,100,1,1,233.58,234.13,505,400,2,1,233.53,234.17,10,1,1,1,233.5,234.25,100,100,1,1,233.45,234.41,15,500,1,1,233.4,234.43,110,105,2,2,233.39,234.5,10,63,1,4,233.31,234.59,110,60,2,1,GOOG
2024-10-21T12:31:12.184756053Z,2024-10-21T12:31:12.184589806Z,10,2,38,A,B,1,233.66,400,130,166247,13414673,233.7,233.93,1200,400,1,1,233.66,234,401,17,2,2,233.58,234.1,505,100,2,1,233.53,234.13,10,400,1,1,233.5,234.17,100,1,1,1,233.45,234.25,15,100,1,1,233.4,234.41,110,500,2,1,233.39,234.43,10,105,1,2,233.31,234.5,110,63,2,4,233.3,234.59,100,60,1,1,GOOG
2024-10-21T12:31:12.475596469Z,2024-10-21T12:31:12.475429772Z,10,2,38,A,A,0,233.89,7,130,166697,13415225,233.7,233.89,1200,7,1,1,233.66,233.93,401,400,2,1,233.58,234,505,17,2,2,233.53,234.1,10,100,1,1,233.5,234.13,100,400,1,1,233.45,234.17,15,1,1,1,233.4,234.25,110,100,2,1,233.39,234.41,10,500,1,1,233.31,234.43,110,105,2,2,233.3,234.5,100,63,1,4,GOOG
2024-10-21T12:31:12.508296194Z,2024-10-21T12:31:12.508130141Z,10,2,38,C,B,1,233.66,400,130,166053,13415248,233.7,233.89,1200,7,1,1,233.66,233.93,1,400,1,1,233.58,234,505,17,2,2,233.53,234.1,10,100,1,1,233.5,234.13,100,400,1,1,233.45,234.17,15,1,1,1,233.4,234.25,110,100,2,1,233.39,234.41,10,500,1,1,233.31,234.43,110,105,2,2,233.3,234.5,100,63,1,4,GOOG
2024-10-21T12:31:12.508309583Z,2024-10-21T12:31:12.508143118Z,10,2,38,A,B,2,233.6,400,130,166465,13415249,233.7,233.89,1200,7,1,1,233.66,233.93,1,400,1,1,233.6,234,400,17,1,2,233.58,234.1,505,100,2,1,233.53,234.13,10,400,1,1,233.5,234.17,100,1,1,1,233.45,234.25,15,100,1,1,233.4,234.41,110,500,2,1,233.39,234.43,10,105,1,2,233.31,234.5,110,63,2,4,GOOG
2024-10-21T12:31:12.564190508Z,2024-10-21T12:31:12.564024144Z,10,2,38,A,B,2,233.63,200,130,166364,13415268,233.7,233.89,1200,7,1,1,233.66,233.93,1,400,1,1,233.63,234,200,17,1,2,233.58,234.1,505,100,2,1,233.53,234.13,10,400,1,1,233.5,234.17,100,1,1,1,233.45,234.25,15,100,1,1,233.4,234.41,110,500,2,1,233.39,234.43,10,105,1,2,233.31,234.5,110,63,2,4,GOOG
2024-10-21T12:31:13.593768894Z,2024-10-21T12:31:13.593602346Z,10,2,38,A,B,1,233.66,200,130,166548,13415924,233.7,233.89,1200,7,1,1,233.66,233.93,201,400,2,1,233.58,234,505,17,2,2,233.53,234.1,10,100,1,1,233.5,234.13,100,400,1,1,233.45,234.17,15,1,1,1,233.4,234.25,110,100,2,1,233.39,234.41,10,500,1,1,233.31,234.43,110,105,2,2,233.3,234.5,100,63,1,4,GOOG
2024-10-21T12:31:15.015635368Z,2024-10-21T12:31:15.015468720Z,10,2,38,C,B,1,233.66,200,130,166648,13416688,233.7,233.89,1200,7,1,1,233.66,233.93,1,400,1,1,233.58,234,505,17,2,2,233.53,234.1,10,100,1,1,233.5,234.13,100,400,1,1,233.45,234.17,15,1,1,1,233.4,234.25,110,100,2,1,233.39,234.41,10,500,1,1,233.31,234.43,110,105,2,2,233.3,234.5,100,63,1,4,GOOG
2024-10-21T12:31:15.015647832Z,2024-10-21T12:31:15.015480988Z,10,2,38,A,B,2,233.63,200,130,166844,13416689,233.7,233.89,1200,7,1,1,233.66,233.93,1,400,1,1,233.63,234,200,17,1,2,233.58,234.1,505,100,2,1,233.53,234.13,10,400,1,1,233.5,234.17,100,1,1,1,233.45,234.25,15,100,1,1,233.4,234.41,110,500,2,1,233.39,234.43,10,105,1,2,233.31,234.5,110,63,2,4,GOOG
2024-10-21T12:31:16.945858054Z,2024-10-21T12:31:16.945691674Z,10,2,38,A,A,0,233.86,10,130,166380,13419085,233.7,233.86,1200,10,1,1,233.66,233.89,1,7,1,1,233.63,233.93,200,400,1,1,233.58,234,505,17,2,2,233.53,234.1,10,100,1,1,233.5,234.13,100,400,1,1,233.45,234.17,15,1,1,1,233.4,234.25,110,100,2,1,233.39,234.41,10,500,1,1,233.31,234.43,110,105,2,2,GOOG
2024-10-21T12:31:18.603225169Z,2024-10-21T12:31:18.603058995Z,10,2,38,C,A,2,233.93,400,130,166174,13420831,233.7,233.86,1200,10,1,1,233.66,233.89,1,7,1,1,233.63,234,200,17,1,2,233.58,234.1,505,100,2,1,233.53,234.13,10,400,1,1,233.5,234.17,100,1,1,1,233.45,234.25,15,100,1,1,233.4,234.41,110,500,2,1,233.39,234.43,10,105,1,2,233.31,234.5,110,63,2,4,GOOG
2024-10-21T12:31:18.603237751Z,2024-10-21T12:31:18.603071495Z,10,2,38,A,A,2,233.95,400,130,166256,13420832,233.7,233.86,1200,10,1,1,233.66,233.89,1,7,1,1,233.63,233.95,200,400,1,1,233.58,234,505,17,2,2,233.53,234.1,10,100,1,1,233.5,234.13,100,400,1,1,233.45,234.17,15,1,1,1,233.4,234.25,110,100,2,1,233.39,234.41,10,500,1,1,233.31,234.43,110,105,2,2,GOOG
2024-10-21T12:31:18.660627687Z,2024-10-21T12:31:18.660460803Z,10,2,38,A,B,2,233.64,200,130,166884,13421076,233.7,233.86,1200,10,1,1,233.66,233.89,1,7,1,1,233.64,233.95,200,400,1,1,233.58,234,505,17,2,2,233.53,234.1,10,100,1,1,233.5,234.13,100,400,1,1,233.45,234.17,15,1,1,1,233.4,234.25,110,100,2,1,233.39,234.41,10,500,1,1,233.31,234.43,110,105,2,2,GOOG
2024-10-21T12:31:18.670072270Z,2024-10-21T12:31:18.669906311Z,10,2,38,C,B,2,233.64,200,130,165959,13421139,233.7,233.86,1200,10,1,1,233.66,233.89,1,7,1,1,233.58,233.95,505,400,2,1,233.53,234,10,17,1,2,233.5,234.1,100,100,1,1,233.45,234.13,15,400,1,1,233.4,234.17,110,1,2,1,233.39,234.25,10,100,1,1,233.31,234.41,110,500,2,1,233.3,234.43,100,105,1,2,GOOG
2024-10-21T12:31:18.670084477Z,2024-10-21T12:31:18.669917997Z,10,2,38,A,B,2,233.61,400,130,166480,13421140,233.7,233.86,1200,10,1,1,233.66,233.89,1,7,1,1,233.61,233.95,400,400,1,1,233.58,234,505,17,2,2,233.53,234.1,10,100,1,1,233.5,234.13,100,400,1,1,233.45,234.17,15,1,1,1,233.4,234.25,110,100,2,1,233.39,234.41,10,500,1,1,233.31,234.43,110,105,2,2,GOOG
2024-10-21T12:31:19.089717374Z,2024-10-21T12:31:19.089550857Z,10,2,38,A,A,0,233.86,10,130,166517,13421861,233.7,233.86,1200,20,1,2,233.66,233.89,1,7,1,1,233.61,233.95,400,400,1,1,233.58,234,505,17,2,2,233.53,234.1,10,100,1,1,233.5,234.13,100,400,1,1,233.45,234.17,15,1,1,1,233.4,234.25,110,100,2,1,233.39,234.41,10,500,1,1,233.31,234.43,110,105,2,2,GOOG
2024-10-21T12:31:20.603475788Z,2024-10-21T12:31:20.603309467Z,10,2,38,C,A,1,233.89,7,130,166321,13423385,233.7,233.86,1200,20,1,2,233.66,233.95,1,400,1,1,233.61,234,400,17,1,2,233.58,234.1,505,100,2,1,233.53,234.13,10,400,1,1,233.5,234.17,100,1,1,1,233.45,234.25,15,100,1,1,233.4,234.41,110,500,2,1,233.39,234.43,10,105,1,2,233.31,234.5,110,63,2,4,GOOG
2024-10-21T12:31:22.606747140Z,2024-10-21T12:31:22.606580635Z,10,2,38,A,A,2,233.97,7,130,166505,13425539,233.7,233.86,1200,20,1,2,233.66,233.95,1,400,1,1,233.61,233.97,400,7,1,1,233.58,234,505,17,2,2,233.53,234.1,10,100,1,1,233.5,234.13,100,400,1,1,233.45,234.17,15,1,1,1,233.4,234.25,110,100,2,1,233.39,234.41,10,500,1,1,233.31,234.43,110,105,2,2,GOOG
2024-10-21T12:31:27.506180312Z,2024-10-21T12:31:27.506013569Z,10,2,38,A,A,1,233.9,200,130,166743,13430294,233.7,233.86,1200,20,1,2,233.66,233.9,1,200,1,1,233.61,233.97,400,7,1,1,233.58,234,505,17,2,2,233.53,234.1,10,100,1,1,233.5,234.13,100,400,1,1,233.45,234.17,15,1,1,1,233.4,234.25,110,100,2,1,233.39,234.41,10,500,1,1,233.31,234.43,110,105,2,2,GOOG
2024-10-21T12:31:31.003813869Z,2024-10-21T12:31:31.003647553Z,10,2,38,A,A,0,233.77,5,130,166316,13433591,233.7,233.77,1200,5,1,1,233.66,233.86,1,20,1,2,233.61,233.9,400,200,1,1,233.58,233.97,505,7,2,1,233.53,234,10,17,1,2,233.5,234.1,100,100,1,1,233.45,234.13,15,400,1,1,233.4,234.17,110,1,2,1,233.39,234.25,10,100,1,1,233.31,234.41,110,500,2,1,GOOG
2024-10-21T12:31:31.007917250Z,2024-10-21T12:31:31.007751363Z,10,2,38,C,A,0,233.77,5,130,165887,13433594,233.7,233.86,1200,20,1,2,233.66,233.9,1,200,1,1,233.61,233.97,400,7,1,1,233.58,234,505,17,2,2,233.53,234.1,10,100,1,1,233.5,234.13,100,400,1,1,233.45,234.17,15,1,1,1,233.4,234.25,110,100,2,1,233.39,234.41,10,500,1,1,233.31,234.43,110,105,2,2,GOOG
2024-10-21T12:31:33.219452608Z,2024-10-21T12:31:33.219286515Z,10,2,38,C,A,1,233.9,200,130,166093,13435891,233.7,233.86,1200,20,1,2,233.66,233.97,1,7,1,1,233.61,234,400,17,1,2,233.58,234.1,505,100,2,1,233.53,234.13,10,400,1,1,233.5,234.17,100,1,1,1,233.45,234.25,15,100,1,1,233.4,234.41,110,500,2,1,233.39,234.43,10,105,1,2,233.31,234.5,110,63,2,4,GOOG
2024-10-21T12:31:33.219465330Z,2024-10-21T12:31:33.219299014Z,10,2,38,A,A,1,233.93,200,130,166316,13435892,233.7,233.86,1200,20,1,2,233.66,233.93,1,200,1,1,233.61,233.97,400,7,1,1,233.58,234,505,17,2,2,233.53,234.1,10,100,1,1,233.5,234.13,100,400,1,1,233.45,234.17,15,1,1,1,233.4,234.25,110,100,2,1,233.39,234.41,10,500,1,1,233.31,234.43,110,105,2,2,GOOG
2024-10-21T12:31:33.219550796Z,2024-10-21T12:31:33.219384692Z,10,2,38,C,A,1,233.93,200,130,166104,13435893,233.7,233.86,1200,20,1,2,233.66,233.97,1,7,1,1,233.61,234,400,17,1,2,233.58,234.1,505,100,2,1,233.53,234.13,10,400,1,1,233.5,234.17,100,1,1,1,233.45,234.25,15,100,1,1,233.4,234.41,110,500,2,1,233.39,234.43,10,105,1,2,233.31,234.5,110,63,2,4,GOOG
2024-10-21T12:31:33.219562711Z,2024-10-21T12:31:33.219396602Z,10,2,38,A,A,1,233.95,400,130,166109,13435894,233.7,233.86,1200,20,1,2,233.66,233.95,1,400,1,1,233.61,233.97,400,7,1,1,233.58,234,505,17,2,2,233.53,234.1,10,100,1,1,233.5,234.13,100,400,1,1,233.45,234.17,15,1,1,1,233.4,234.25,110,100,2,1,233.39,234.41,10,500,1,1,233.31,234.43,110,105,2,2,GOOG
2024-10-21T12:31:33.283845863Z,2024-10-21T12:31:33.283679402Z,10,2,38,A,A,1,233.91,200,130,166461,13435939,233.7,233.86,1200,20,1,2,233.66,233.91,1,200,1,1,233.61,233.97,400,7,1,1,233.58,234,505,17,2,2,233.53,234.1,10,100,1,1,233.5,234.13,100,400,1,1,233.45,234.17,15,1,1,1,233.4,234.25,110,100,2,1,233.39,234.41,10,500,1,1,233.31,234.43,110,105,2,2,GOOG
2024-10-21T12:31:36.129204699Z,2024-10-21T12:31:36.129038634Z,10,2,38,C,A,2,233.97,7,130,166065,13438502,233.7,233.86,1200,20,1,2,233.66,233.91,1,200,1,1,233.61,234,400,17,1,2,233.58,234.1,505,100,2,1,233.53,234.13,10,400,1,1,233.5,234.17,100,1,1,1,233.45,234.25,15,100,1,1,233.4,234.41,110,500,2,1,233.39,234.43,10,105,1,2,233.31,234.5,110,63,2,4,GOOG
2024-10-21T12:31:38.015720503Z,2024-10-21T12:31:38.015553779Z,10,2,38,C,B,2,233.61,200,130,166724,13439793,233.7,233.86,1200,20,1,2,233.66,233.91,1,200,1,1,233.61,234,200,17,1,2,233.58,234.1,505,100,2,1,233.53,234.13,10,400,1,1,233.5,234.17,100,1,1,1,233.45,234.25,15,100,1,1,233.4,234.41,110,500,2,1,233.39,234.43,10,105,1,2,233.31,234.5,110,63,2,4,GOOG
2024-10-21T12:31:38.132126432Z,2024-10-21T12:31:38.131960021Z,10,2,38,A,A,2,233.97,7,130,166411,13439823,233.7,233.86,1200,20,1,2,233.66,233.91,1,200,1,1,233.61,233.97,200,7,1,1,233.58,234,505,17,2,2,233.53,234.1,10,100,1,1,233.5,234.13,100,400,1,1,233.45,234.17,15,1,1,1,233.4,234.25,110,100,2,1,233.39,234.41,10,500,1,1,233.31,234.43,110,105,2,2,GOOG
2024-10-21T12:31:39.148018166Z,2024-10-21T12:31:39.147851742Z,10,2,38,A,B,2,233.61,200,130,166424,13440517,233.7,233.86,1200,20,1,2,233.66,233.91,1,200,1,1,233.61,233.97,400,7,2,1,233.58,234,505,17,2,2,233.53,234.1,10,100,1,1,233.5,234.13,100,400,1,1,233.45,234.17,15,1,1,1,233.4,234.25,110,100,2,1,233.39,234.41,10,500,1,1,233.31,234.43,110,105,2,2,GOOG
2024-10-21T12:31:39.834325275Z,2024-10-21T12:31:39.834158320Z,10,2,38,C,B,2,233.61,200,130,166955,13441045,233.7,233.86,1200,20,1,2,233.66,233.91,1,200,1,1,233.61,233.97,200,7,1,1,233.58,234,505,17,2,2,233.53,234.1,10,100,1,1,233.5,234.13,100,400,1,1,233.45,234.17,15,1,1,1,233.4,234.25,110,100,2,1,233.39,234.41,10,500,1,1,233.31,234.43,110,105,2,2,GOOG
2024-10-21T12:31:39.834335325Z,2024-10-21T12:31:39.834169303Z,10,2,38,C,B,2,233.61,200,130,166022,13441046,233.7,233.86,1200,20,1,2,233.66,233.91,1,200,1,1,233.58,233.97,505,7,2,1,233.53,234,10,17,1,2,233.5,234.1,100,100,1,1,233.45,234.13,15,400,1,1,233.4,234.17,110,1,2,1,233.39,234.25,10,100,1,1,233.31,234.41,110,500,2,1,233.3,234.43,100,105,1,2,GOOG
2024-10-21T12:31:39.834347966Z,2024-10-21T12:31:39.834181341Z,10,2,38,A,B,2,233.59,200,130,166625,13441047,233.7,233.86,1200,20,1,2,233.66,233.91,1,200,1,1,233.59,233.97,200,7,1,1,233.58,234,505,17,2,2,233.53,234.1,10,100,1,1,233.5,234.13,100,400,1,1,233.45,234.17,15,1,1,1,233.4,234.25,110,100,2,1,233.39,234.41,10,500,1,1,233.31,234.43,110,105,2,2,GOOG
2024-10-21T12:31:40.908163062Z,2024-10-21T12:31:40.907996076Z,10,2,38,A,B,2,233.59,200,130,166986,13442396,233.7,233.86,1200,20,1,2,233.66,233.91,1,200,1,1,233.59,233.97,400,7,2,1,233.58,234,505,17,2,2,233.53,234.1,10,100,1,1,233.5,234.13,100,400,1,1,233.45,234.17,15,1,1,1,233.4,234.25,110,100,2,1,233.39,234.41,10,500,1,1,233.31,234.43,110,105,2,2,GOOG
2024-10-21T12:31:40.962805083Z,2024-10-21T12:31:40.962639115Z,10,2,38,C,B,2,233.59,200,130,165968,13442418,233.7,233.86,1200,20,1,2,233.66,233.91,1,200,1,1,233.59,233.97,200,7,1,1,233.58,234,505,17,2,2,233.53,234.1,10,100,1,1,233.5,234.13,100,400,1,1,233.45,234.17,15,1,1,1,233.4,234.25,110,100,2,1,233.39,234.41,10,500,1,1,233.31,234.43,110,105,2,2,GOOG
2024-10-21T12:31:40.962818614Z,2024-10-21T12:31:40.962651822Z,10,2,38,A,B,2,233.61,400,130,166792,13442419,233.7,233.86,1200,20,1,2,233.66,233.91,1,200,1,1,233.61,233.97,400,7,1,1,233.58,234,505,17,2,2,233.53,234.1,10,100,1,1,233.5,234.13,100,400,1,1,233.45,234.17,15,1,1,1,233.4,234.25,110,100,2,1,233.39,234.41,10,500,1,1,233.31,234.43,110,105,2,2,GOOG
2024-10-21T12:31:41.070900757Z,2024-10-21T12:31:41.070734248Z,10,2,38,A,B,2,233.65,200,130,166509,13442470,233.7,233.86,1200,20,1,2,233.66,233.91,1,200,1,1,233.65,233.97,200,7,1,1,233.58,234,505,17,2,2,233.53,234.1,10,100,1,1,233.5,234.13,100,400,1,1,233.45,234.17,15,1,1,1,233.4,234.25,110,100,2,1,233.39,234.41,10,500,1,1,233.31,234.43,110,105,2,2,GOOG
2024-10-21T12:31:45.869999875Z,2024-10-21T12:31:45.869832455Z,10,2,38,A,B,0,233.76,15,130,167420,13446443,233.76,233.86,15,20,1,2,233.7,233.91,1200,200,1,1,233.66,233.97,1,7,1,1,233.65,234,200,17,1,2,233.58,234.1,505,100,2,1,233.53,234.13,10,400,1,1,233.5,234.17,100,1,1,1,233.45,234.25,15,100,1,1,233.4,234.41,110,500,2,1,233.39,234.43,10,105,1,2,GOOG
2024-10-21T12:31:45.874105729Z,2024-10-21T12:31:45.873939488Z,10,2,38,C,B,0,233.76,15,130,166241,13446446,233.7,233.86,1200,20,1,2,233.66,233.91,1,200,1,1,233.65,233.97,200,7,1,1,233.58,234,505,17,2,2,233.53,234.1,10,100,1,1,233.5,234.13,100,400,1,1,233.45,234.17,15,1,1,1,233.4,234.25,110,100,2,1,233.39,234.41,10,500,1,1,233.31,234.43,110,105,2,2,GOOG
2024-10-21T12:31:45.941935800Z,2024-10-21T12:31:45.941769646Z,10,2,38,C,B,2,233.65,200,130,166154,13446467,233.7,233.86,1200,20,1,2,233.66,233.91,1,200,1,1,233.58,233.97,505,7,2,1,233.53,234,10,17,1,2,233.5,234.1,100,100,1,1,233.45,234.13,15,400,1,1,233.4,234.17,110,1,2,1,233.39,234.25,10,100,1,1,233.31,234.41,110,500,2,1,233.3,234.43,100,105,1,2,GOOG
2024-10-21T12:31:45.941948137Z,2024-10-21T12:31:45.941781796Z,10,2,38,A,B,2,233.61,400,130,166341,13446468,233.7,233.86,1200,20,1,2,233.66,233.91,1,200,1,1,233.61,233.97,400,7,1,1,233.58,234,505,17,2,2,233.53,234.1,10,100,1,1,233.5,234.13,100,400,1,1,233.45,234.17,15,1,1,1,233.4,234.25,110,100,2,1,233.39,234.41,10,500,1,1,233.31,234.43,110,105,2,2,GOOG
2024-10-21T12:31:48.996833357Z,2024-10-21T12:31:48.996666200Z,10,2,38,A,B,0,233.7,200,130,167157,13448959,233.7,233.86,1400,20,2,2,233.66,233.91,1,200,1,1,233.58,233.97,505,7,2,1,233.53,234,10,17,1,2,233.5,234.1,100,100,1,1,233.45,234.13,15,400,1,1,233.4,234.17,110,1,2,1,233.39,234.25,10,100,1,1,233.31,234.41,110,500,2,1,233.3,234.43,100,105,1,2,GOOG
2024-10-21T12:31:49.143903611Z,2024-10-21T12:31:49.143737320Z,10,2,38,C,A,2,233.97,7,130,166291,13449037,233.7,233.86,1400,20,2,2,233.66,233.91,1,200,1,1,233.58,234,505,17,2,2,233.53,234.1,10,100,1,1,233.5,234.13,100,400,1,1,233.45,234.17,15,1,1,1,233.4,234.25,110,100,2,1,233.39,234.41,10,500,1,1,233.31,234.43,110,105,2,2,233.3,234.5,100,63,1,4,GOOG
2024-10-21T12:31:51.146671405Z,2024-10-21T12:31:51.146504844Z,10,2,38,A,A,2,233.97,7,130,166561,13451541,233.7,233.86,1400,20,2,2,233.66,233.91,1,200,1,1,233.58,233.97,505,7,2,1,233.53,234,10,17,1,2,233.5,234.1,100,100,1,1,233.45,234.13,15,400,1,1,233.4,234.17,110,1,2,1,233.39,234.25,10,100,1,1,233.31,234.41,110,500,2,1,233.3,234.43,100,105,1,2,GOOG
2024-10-21T12:31:52.622332472Z,2024-10-21T12:31:52.622166042Z,10,2,38,A,A,1,233.9,200,130,166430,13453377,233.7,233.86,1400,20,2,2,233.66,233.9,1,200,1,1,233.58,233.97,505,7,2,1,233.53,234,10,17,1,2,233.5,234.1,100,100,1,1,233.45,234.13,15,400,1,1,233.4,234.17,110,1,2,1,233.39,234.25,10,100,1,1,233.31,234.41,110,500,2,1,233.3,234.43,100,105,1,2,GOOG
2024-10-21T12:31:55.540513136Z,2024-10-21T12:31:55.540346724Z,10,2,38,A,B,0,233.7,7,130,166412,13457388,233.7,233.86,1407,20,3,2,233.66,233.9,1,200,1,1,233.58,233.97,505,7,2,1,233.53,234,10,17,1,2,233.5,234.1,100,100,1,1,233.45,234.13,15,400,1,1,233.4,234.17,110,1,2,1,233.39,234.25,10,100,1,1,233.31,234.41,110,500,2,1,233.3,234.43,100,105,1,2,GOOG
2024-10-21T12:32:04.030169413Z,2024-10-21T12:32:04.030002963Z,10,2,38,C,A,2,233.97,7,130,166450,13466439,233.7,233.86,1407,20,3,2,233.66,233.9,1,200,1,1,233.58,234,505,17,2,2,233.53,234.1,10,100,1,1,233.5,234.13,100,400,1,1,233.45,234.17,15,1,1,1,233.4,234.25,110,100,2,1,233.39,234.41,10,500,1,1,233.31,234.43,110,105,2,2,233.3,234.5,100,63,1,4,GOOG
2024-10-21T12:32:05.348249023Z,2024-10-21T12:32:05.348083000Z,10,2,38,C,B,0,233.7,200,130,166023,13468073,233.7,233.86,1207,20,2,2,233.66,233.9,1,200,1,1,233.58,234,505,17,2,2,233.53,234.1,10,100,1,1,233.5,234.13,100,400,1,1,233.45,234.17,15,1,1,1,233.4,234.25,110,100,2,1,233.39,234.41,10,500,1,1,233.31,234.43,110,105,2,2,233.3,234.5,100,63,1,4,GOOG
2024-10-21T12:32:05.348261484Z,2024-10-21T12:32:05.348095069Z,10,2,38,A,B,2,233.61,400,130,166415,13468074,233.7,233.86,1207,20,2,2,233.66,233.9,1,200,1,1,233.61,234,400,17,1,2,233.58,234.1,505,100,2,1,233.53,234.13,10,400,1,1,233.5,234.17,100,1,1,1,233.45,234.25,15,100,1,1,233.4,234.41,110,500,2,1,233.39,234.43,10,105,1,2,233.31,234.5,110,63,2,4,GOOG
2024-10-21T12:32:05.979354735Z,2024-10-21T12:32:05.979188085Z,10,2,38,A,B,0,233.8,40,130,166650,13468626,233.8,233.86,40,20,1,2,233.7,233.9,1207,200,2,1,233.66,234,1,17,1,2,233.61,234.1,400,100,1,1,233.58,234.13,505,400,2,1,233.53,234.17,10,1,1,1,233.5,234.25,100,100,1,1,233.45,234.41,15,500,1,1,233.4,234.43,110,105,2,2,233.39,234.5,10,63,1,4,GOOG
2024-10-21T12:32:06.032972256Z,2024-10-21T12:32:06.032805816Z,10,2,38,A,A,7,234.32,7,130,166440,13468663,233.8,233.86,40,20,1,2,233.7,233.9,1207,200,2,1,233.66,234,1,17,1,2,233.61,234.1,400,100,1,1,233.58,234.13,505,400,2,1,233.53,234.17,10,1,1,1,233.5,234.25,100,100,1,1,233.45,234.32,15,7,1,1,233.4,234.41,110,500,2,1,233.39,234.43,10,105,1,2,GOOG
2024-10-21T12:32:07.542237037Z,2024-10-21T12:32:07.542071110Z,10,2,38,C,A,1,233.9,200,130,165927,13470422,233.8,233.86,40,20,1,2,233.7,234,1207,17,2,2,233.66,234.1,1,100,1,1,233.61,234.13,400,400,1,1,233.58,234.17,505,1,2,1,233.53,234.25,10,100,1,1,233.5,234.32,100,7,1,1,233.45,234.41,15,500,1,1,233.4,234.43,110,105,2,2,233.39,234.5,10,63,1,4,GOOG
2024-10-21T12:32:07.542249604Z,2024-10-21T12:32:07.542083244Z,10,2,38,A,A,1,233.92,200,130,166360,13470423,233.8,233.86,40,20,1,2,233.7,233.92,1207,200,2,1,233.66,234,1,17,1,2,233.61,234.1,400,100,1,1,233.58,234.13,505,400,2,1,233.53,234.17,10,1,1,1,233.5,234.25,100,100,1,1,233.45,234.32,15,7,1,1,233.4,234.41,110,500,2,1,233.39,234.43,10,105,1,2,GOOG
2024-10-21T12:32:07.598815691Z,2024-10-21T12:32:07.598649034Z,10,2,38,A,B,3,233.62,400,130,166657,13470579,233.8,233.86,40,20,1,2,233.7,233.92,1207,200,2,1,233.66,234,1,17,1,2,233.62,234.1,400,100,1,1,233.58,234.13,505,400,2,1,233.53,234.17,10,1,1,1,233.5,234.25,100,100,1,1,233.45,234.32,15,7,1,1,233.4,234.41,110,500,2,1,233.39,234.43,10,105,1,2,GOOG
2024-10-21T12:32:07.665648450Z,2024-10-21T12:32:07.665482103Z,10,2,38,A,A,1,233.91,200,130,166347,13470737,233.8,233.86,40,20,1,2,233.7,233.91,1207,200,2,1,233.66,234,1,17,1,2,233.62,234.1,400,100,1,1,233.58,234.13,505,400,2,1,233.53,234.17,10,1,1,1,233.5,234.25,100,100,1,1,233.45,234.32,15,7,1,1,233.4,234.41,110,500,2,1,233.39,234.43,10,105,1,2,GOOG
2024-10-21T12:32:08.403402527Z,2024-10-21T12:32:08.403235695Z,10,2,38,A,B,2,233.66,200,130,166832,13471380,233.8,233.86,40,20,1,2,233.7,233.91,1207,200,2,1,233.66,234,201,17,2,2,233.58,234.1,505,100,2,1,233.53,234.13,10,400,1,1,233.5,234.17,100,1,1,1,233.45,234.25,15,100,1,1,233.4,234.32,110,7,2,1,233.39,234.41,10,500,1,1,233.31,234.43,110,105,2,2,GOOG
2024-10-21T12:32:11.089090978Z,2024-10-21T12:32:11.088924820Z,10,2,38,C,A,0,233.86,10,130,166158,13473926,233.8,233.86,40,10,1,1,233.7,233.91,1207,200,2,1,233.66,234,201,17,2,2,233.58,234.1,505,100,2,1,233.53,234.13,10,400,1,1,233.5,234.17,100,1,1,1,233.45,234.25,15,100,1,1,233.4,234.32,110,7,2,1,233.39,234.41,10,500,1,1,233.31,234.43,110,105,2,2,GOOG
2024-10-21T12:32:11.127495366Z,2024-10-21T12:32:11.127329051Z,10,2,38,A,B,2,233.67,200,130,166315,13473989,233.8,233.86,40,10,1,1,233.7,233.91,1207,200,2,1,233.67,234,200,17,1,2,233.66,234.1,1,100,1,1,233.58,234.13,505,400,2,1,233.53,234.17,10,1,1,1,233.5,234.25,100,100,1,1,233.45,234.32,15,7,1,1,233.4,234.41,110,500,2,1,233.39,234.43,10,105,1,2,GOOG
2024-10-21T12:32:11.560512233Z,2024-10-21T12:32:11.560345813Z,10,2,38,A,B,2,233.67,200,130,166420,13474559,233.8,233.86,40,10,1,1,233.7,233.91,1207,200,2,1,233.67,234,400,17,2,2,233.66,234.1,1,100,1,1,233.58,234.13,505,400,2,1,233.53,234.17,10,1,1,1,233.5,234.25,100,100,1,1,233.45,234.32,15,7,1,1,233.4,234.41,110,500,2,1,233.39,234.43,10,105,1,2,GOOG
2024-10-21T12:32:11.562375984Z,2024-10-21T12:32:11.562209891Z,10,2,38,C,A,1,233.91,200,130,166093,13474560,233.8,233.86,40,10,1,1,233.7,234,1207,17,2,2,233.67,234.1,400,100,2,1,233.66,234.13,1,400,1,1,233.58,234.17,505,1,2,1,233.53,234.25,10,100,1,1,233.5,234.32,100,7,1,1,233.45,234.41,15,500,1,1,233.4,234.43,110,105,2,2,233.39,234.5,10,63,1,4,GOOG
2024-10-21T12:32:11.562390698Z,2024-10-21T12:32:11.562224326Z,10,2,38,A,A,1,233.96,400,130,166372,13474561,233.8,233.86,40,10,1,1,233.7,233.96,1207,400,2,1,233.67,234,400,17,2,2,233.66,234.1,1,100,1,1,233.58,234.13,505,400,2,1,233.53,234.17,10,1,1,1,233.5,234.25,100,100,1,1,233.45,234.32,15,7,1,1,233.4,234.41,110,500,2,1,233.39,234.43,10,105,1,2,GOOG
2024-10-21T12:32:11.611134548Z,2024-10-21T12:32:11.610968597Z,10,2,38,C,B,2,233.67,200,130,165951,13474618,233.8,233.86,40,10,1,1,233.7,233.96,1207,400,2,1,233.67,234,200,17,1,2,233.66,234.1,1,100,1,1,233.58,234.13,505,400,2,1,233.53,234.17,10,1,1,1,233.5,234.25,100,100,1,1,233.45,234.32,15,7,1,1,233.4,234.41,110,500,2,1,233.39,234.43,10,105,1,2,GOOG
2024-10-21T12:32:11.611147919Z,2024-10-21T12:32:11.610981426Z,10,2,38,A,B,1,233.71,200,130,166493,13474620,233.8,233.86,40,10,1,1,233.71,233.96,200,400,1,1,233.7,234,1207,17,2,2,233.66,234.1,1,100,1,1,233.58,234.13,505,400,2,1,233.53,234.17,10,1,1,1,233.5,234.25,100,100,1,1,233.45,234.32,15,7,1,1,233.4,234.41,110,500,2,1,233.39,234.43,10,105,1,2,GOOG
2024-10-21T12:32:11.648237295Z,2024-10-21T12:32:11.648070870Z,10,2,38,A,A,1,233.94,200,130,166425,13474689,233.8,233.86,40,10,1,1,233.71,233.94,200,200,1,1,233.7,234,1207,17,2,2,233.66,234.1,1,100,1,1,233.58,234.13,505,400,2,1,233.53,234.17,10,1,1,1,233.5,234.25,100,100,1,1,233.45,234.32,15,7,1,1,233.4,234.41,110,500,2,1,233.39,234.43,10,105,1,2,GOOG
2024-10-21T12:32:14.797391948Z,2024-10-21T12:32:14.797225568Z,10,2,38,C,A,0,233.86,10,130,166380,13478065,233.8,233.94,40,200,1,1,233.71,234,200,17,1,2,233.7,234.1,1207,100,2,1,233.66,234.13,1,400,1,1,233.58,234.17,505,1,2,1,233.53,234.25,10,100,1,1,233.5,234.32,100,7,1,1,233.45,234.41,15,500,1,1,233.4,234.43,110,105,2,2,233.39,234.5,10,63,1,4,GOOG
2024-10-21T12:32:14.798258984Z,2024-10-21T12:32:14.798092831Z,10,2,38,A,A,0,233.82,10,130,166153,13478070,233.8,233.82,40,10,1,1,233.71,233.94,200,200,1,1,233.7,234,1207,17,2,2,233.66,234.1,1,100,1,1,233.58,234.13,505,400,2,1,233.53,234.17,10,1,1,1,233.5,234.25,100,100,1,1,233.45,234.32,15,7,1,1,233.4,234.41,110,500,2,1,233.39,234.43,10,105,1,2,GOOG
2024-10-21T12:32:18.141637621Z,2024-10-21T12:32:18.141468975Z,10,2,38,T,A,0,233.8,40,130,168646,13481121,233.8,233.82,40,10,1,1,233.71,233.94,200,200,1,1,233.7,234,1207,17,2,2,233.66,234.1,1,100,1,1,233.58,234.13,505,400,2,1,233.53,234.17,10,1,1,1,233.5,234.25,100,100,1,1,233.45,234.32,15,7,1,1,233.4,234.41,110,500,2,1,233.39,234.43,10,105,1,2,GOOG
2024-10-21T12:32:18.141637621Z,2024-10-21T12:32:18.141468975Z,10,2,38,C,B,0,233.8,40,130,168646,13481121,233.71,233.82,200,10,1,1,233.7,233.94,1207,200,2,1,233.66,234,1,17,1,2,233.58,234.1,505,100,2,1,233.53,234.13,10,400,1,1,233.5,234.17,100,1,1,1,233.45,234.25,15,100,1,1,233.4,234.32,110,7,2,1,233.39,234.41,10,500,1,1,233.31,234.43,110,105,2,2,GOOG
2024-10-21T12:32:18.141657842Z,2024-10-21T12:32:18.141491360Z,10,2,38,A,A,0,233.81,100,130,166482,13481122,233.71,233.81,200,100,1,1,233.7,233.82,1207,10,2,1,233.66,233.94,1,200,1,1,233.58,234,505,17,2,2,233.53,234.1,10,100,1,1,233.5,234.13,100,400,1,1,233.45,234.17,15,1,1,1,233.4,234.25,110,100,2,1,233.39,234.32,10,7,1,1,233.31,234.41,110,500,2,1,GOOG
2024-10-21T12:32:18.141699570Z,2024-10-21T12:32:18.141532732Z,10,2,38,C,A,0,233.81,100,130,166838,13481123,233.71,233.82,200,10,1,1,233.7,233.94,1207,200,2,1,233.66,234,1,17,1,2,233.58,234.1,505,100,2,1,233.53,234.13,10,400,1,1,233.5,234.17,100,1,1,1,233.45,234.25,15,100,1,1,233.4,234.32,110,7,2,1,233.39,234.41,10,500,1,1,233.31,234.43,110,105,2,2,GOOG
2024-10-21T12:32:18.141704945Z,2024-10-21T12:32:18.141539068Z,10,2,38,C,B,0,233.71,200,130,165877,13481124,233.7,233.82,1207,10,2,1,233.66,233.94,1,200,1,1,233.58,234,505,17,2,2,233.53,234.1,10,100,1,1,233.5,234.13,100,400,1,1,233.45,234.17,15,1,1,1,233.4,234.25,110,100,2,1,233.39,234.32,10,7,1,1,233.31,234.41,110,500,2,1,233.3,234.43,100,105,1,2,GOOG
2024-10-21T12:32:18.152988421Z,2024-10-21T12:32:18.152822419Z,10,2,38,A,A,0,233.81,2,130,166002,13481140,233.7,233.81,1207,2,2,1,233.66,233.82,1,10,1,1,233.58,233.94,505,200,2,1,233.53,234,10,17,1,2,233.5,234.1,100,100,1,1,233.45,234.13,15,400,1,1,233.4,234.17,110,1,2,1,233.39,234.25,10,100,1,1,233.31,234.32,110,7,2,1,233.3,234.41,100,500,1,1,GOOG
2024-10-21T12:32:18.152998282Z,2024-10-21T12:32:18.152831190Z,10,2,38,A,A,0,233.8,100,130,167092,13481141,233.7,233.8,1207,100,2,1,233.66,233.81,1,2,1,1,233.58,233.82,505,10,2,1,233.53,233.94,10,200,1,1,233.5,234,100,17,1,2,233.45,234.1,15,100,1,1,233.4,234.13,110,400,2,1,233.39,234.17,10,1,1,1,233.31,234.25,110,100,2,1,233.3,234.32,100,7,1,1,GOOG
2024-10-21T12:32:18.153421159Z,2024-10-21T12:32:18.153255214Z,10,2,38,C,A,0,233.8,100,130,165945,13481143,233.7,233.81,1207,2,2,1,233.66,233.82,1,10,1,1,233.58,233.94,505,200,2,1,233.53,234,10,17,1,2,233.5,234.1,100,100,1,1,233.45,234.13,15,400,1,1,233.4,234.17,110,1,2,1,233.39,234.25,10,100,1,1,233.31,234.32,110,7,2,1,233.3,234.41,100,500,1,1,GOOG
2024-10-21T12:32:18.153536665Z,2024-10-21T12:32:18.153370459Z,10,2,38,C,A,0,233.81,2,130,166206,13481144,233.7,233.82,1207,10,2,1,233.66,233.94,1,200,1,1,233.58,234,505,17,2,2,233.53,234.1,10,100,1,1,233.5,234.13,100,400,1,1,233.45,234.17,15,1,1,1,233.4,234.25,110,100,2,1,233.39,234.32,10,7,1,1,233.31,234.41,110,500,2,1,233.3,234.43,100,105,1,2,GOOG
2024-10-21T12:32:18.161851936Z,2024-10-21T12:32:18.161685578Z,10,2,38,C,A,7,234.32,7,130,166358,13481150,233.7,233.82,1207,10,2,1,233.66,233.94,1,200,1,1,233.58,234,505,17,2,2,233.53,234.1,10,100,1,1,233.5,234.13,100,400,1,1,233.45,234.17,15,1,1,1,233.4,234.25,110,100,2,1,233.39,234.41,10,500,1,1,233.31,234.43,110,105,2,2,233.3,234.5,100,63,1,4,GOOG
2024-10-21T12:32:18.224184111Z,2024-10-21T12:32:18.224017456Z,10,2,38,A,B,2,233.62,400,130,166655,13481183,233.7,233.82,1207,10,2,1,233.66,233.94,1,200,1,1,233.62,234,400,17,1,2,233.58,234.1,505,100,2,1,233.53,234.13,10,400,1,1,233.5,234.17,100,1,1,1,233.45,234.25,15,100,1,1,233.4,234.41,110,500,2,1,233.39,234.43,10,105,1,2,233.31,234.5,110,63,2,4,GOOG
2024-10-21T12:32:18.224289085Z,2024-10-21T12:32:18.224122852Z,10,2,38,A,A,1,233.94,200,130,166233,13481184,233.7,233.82,1207,10,2,1,233.66,233.94,1,400,1,2,233.62,234,400,17,1,2,233.58,234.1,505,100,2,1,233.53,234.13,10,400,1,1,233.5,234.17,100,1,1,1,233.45,234.25,15,100,1,1,233.4,234.41,110,500,2,1,233.39,234.43,10,105,1,2,233.31,234.5,110,63,2,4,GOOG
2024-10-21T12:32:18.276336318Z,2024-10-21T12:32:18.276169768Z,10,2,38,C,A,1,233.94,200,130,166550,13481217,233.7,233.82,1207,10,2,1,233.66,233.94,1,200,1,1,233.62,234,400,17,1,2,233.58,234.1,505,100,2,1,233.53,234.13,10,400,1,1,233.5,234.17,100,1,1,1,233.45,234.25,15,100,1,1,233.4,234.41,110,500,2,1,233.39,234.43,10,105,1,2,233.31,234.5,110,63,2,4,GOOG
2024-10-21T12:32:18.276350830Z,2024-10-21T12:32:18.276183899Z,10,2,38,A,A,1,233.91,200,130,166931,13481218,233.7,233.82,1207,10,2,1,233.66,233.91,1,200,1,1,233.62,234,400,17,1,2,233.58,234.1,505,100,2,1,233.53,234.13,10,400,1,1,233.5,234.17,100,1,1,1,233.45,234.25,15,100,1,1,233.4,234.41,110,500,2,1,233.39,234.43,10,105,1,2,233.31,234.5,110,63,2,4,GOOG
2024-10-21T12:32:20.168575081Z,2024-10-21T12:32:20.168408031Z,10,2,38,A,A,7,234.3,7,130,167050,13482471,233.7,233.82,1207,10,2,1,233.66,233.91,1,200,1,1,233.62,234,400,17,1,2,233.58,234.1,505,100,2,1,233.53,234.13,10,400,1,1,233.5,234.17,100,1,1,1,233.45,234.25,15,100,1,1,233.4,234.3,110,7,2,1,233.39,234.41,10,500,1,1,233.31,234.43,110,105,2,2,GOOG
2024-10-21T12:32:23.901550923Z,2024-10-21T12:32:23.901384194Z,10,2,38,A,A,1,233.91,200,130,166729,13485795,233.7,233.82,1207,10,2,1,233.66,233.91,1,400,1,2,233.62,234,400,17,1,2,233.58,234.1,505,100,2,1,233.53,234.13,10,400,1,1,233.5,234.17,100,1,1,1,233.45,234.25,15,100,1,1,233.4,234.3,110,7,2,1,233.39,234.41,10,500,1,1,233.31,234.43,110,105,2,2,GOOG
2024-10-21T12:32:27.277607962Z,2024-10-21T12:32:27.277441455Z,10,2,38,A,B,0,233.74,35,130,166507,13488000,233.74,233.82,35,10,1,1,233.7,233.91,1207,400,2,2,233.66,234,1,17,1,2,233.62,234.1,400,100,1,1,233.58,234.13,505,400,2,1,233.53,234.17,10,1,1,1,233.5,234.25,100,100,1,1,233.45,234.3,15,7,1,1,233.4,234.41,110,500,2,1,233.39,234.43,10,105,1,2,GOOG
2024-10-21T12:32:27.281701280Z,2024-10-21T12:32:27.281535445Z,10,2,38,C,B,0,233.74,35,130,165835,13488011,233.7,233.82,1207,10,2,1,233.66,233.91,1,400,1,2,233.62,234,400,17,1,2,233.58,234.1,505,100,2,1,233.53,234.13,10,400,1,1,233.5,234.17,100,1,1,1,233.45,234.25,15,100,1,1,233.4,234.3,110,7,2,1,233.39,234.41,10,500,1,1,233.31,234.43,110,105,2,2,GOOG
2024-10-21T12:32:27.945808839Z,2024-10-21T12:32:27.945642504Z,10,2,38,C,B,2,233.62,200,130,166335,13488656,233.7,233.82,1207,10,2,1,233.66,233.91,1,400,1,2,233.62,234,200,17,1,2,233.58,234.1,505,100,2,1,233.53,234.13,10,400,1,1,233.5,234.17,100,1,1,1,233.45,234.25,15,100,1,1,233.4,234.3,110,7,2,1,233.39,234.41,10,500,1,1,233.31,234.43,110,105,2,2,GOOG
2024-10-21T12:32:35.505146810Z,2024-10-21T12:32:35.504980540Z,10,2,38,A,B,0,233.76,106,130,166270,13495134,233.76,233.82,106,10,1,1,233.7,233.91,1207,400,2,2,233.66,234,1,17,1,2,233.62,234.1,200,100,1,1,233.58,234.13,505,400,2,1,233.53,234.17,10,1,1,1,233.5,234.25,100,100,1,1,233.45,234.3,15,7,1,1,233.4,234.41,110,500,2,1,233.39,234.43,10,105,1,2,GOOG
2024-10-21T12:32:35.505228376Z,2024-10-21T12:32:35.505060728Z,10,2,38,T,B,0,233.82,10,130,167648,13495137,233.76,233.82,106,10,1,1,233.7,233.91,1207,400,2,2,233.66,234,1,17,1,2,233.62,234.1,200,100,1,1,233.58,234.13,505,400,2,1,233.53,234.17,10,1,1,1,233.5,234.25,100,100,1,1,233.45,234.3,15,7,1,1,233.4,234.41,110,500,2,1,233.39,234.43,10,105,1,2,GOOG
2024-10-21T12:32:35.505228376Z,2024-10-21T12:32:35.505060728Z,10,2,38,C,A,0,233.82,10,130,167648,13495137,233.76,233.91,106,400,1,2,233.7,234,1207,17,2,2,233.66,234.1,1,100,1,1,233.62,234.13,200,400,1,1,233.58,234.17,505,1,2,1,233.53,234.25,10,100,1,1,233.5,234.3,100,7,1,1,233.45,234.41,15,500,1,1,233.4,234.43,110,105,2,2,233.39,234.5,10,63,1,4,GOOG
2024-10-21T12:32:35.505249014Z,2024-10-21T12:32:35.505082570Z,10,2,38,A,B,0,233.78,100,130,166444,13495138,233.78,233.91,100,400,1,2,233.76,234,106,17,1,2,233.7,234.1,1207,100,2,1,233.66,234.13,1,400,1,1,233.62,234.17,200,1,1,1,233.58,234.25,505,100,2,1,233.53,234.3,10,7,1,1,233.5,234.41,100,500,1,1,233.45,234.43,15,105,1,2,233.4,234.5,110,63,2,4,GOOG
2024-10-21T12:32:35.505254580Z,2024-10-21T12:32:35.505087722Z,10,2,38,A,B,0,233.79,5,130,166858,13495140,233.79,233.91,5,400,1,2,233.78,234,100,17,1,2,233.76,234.1,106,100,1,1,233.7,234.13,1207,400,2,1,233.66,234.17,1,1,1,1,233.62,234.25,200,100,1,1,233.58,234.3,505,7,2,1,233.53,234.41,10,500,1,1,233.5,234.43,100,105,1,2,233.45,234.5,15,63,1,4,GOOG
2024-10-21T12:32:35.505263982Z,2024-10-21T12:32:35.505097774Z,10,2,38,A,B,1,233.78,100,130,166208,13495141,233.79,233.91,5,400,1,2,233.78,234,200,17,2,2,233.76,234.1,106,100,1,1,233.7,234.13,1207,400,2,1,233.66,234.17,1,1,1,1,233.62,234.25,200,100,1,1,233.58,234.3,505,7,2,1,233.53,234.41,10,500,1,1,233.5,234.43,100,105,1,2,233.45,234.5,15,63,1,4,GOOG
2024-10-21T12:32:35.505276316Z,2024-10-21T12:32:35.505110083Z,10,2,38,A,B,2,233.77,97,130,166233,13495142,233.79,233.91,5,400,1,2,233.78,234,200,17,2,2,233.77,234.1,97,100,1,1,233.76,234.13,106,400,1,1,233.7,234.17,1207,1,2,1,233.66,234.25,1,100,1,1,233.62,234.3,200,7,1,1,233.58,234.41,505,500,2,1,233.53,234.43,10,105,1,2,233.5,234.5,100,63,1,4,GOOG
2024-10-21T12:32:35.505283825Z,2024-10-21T12:32:35.505118236Z,10,2,38,C,A,0,233.91,200,130,165589,13495143,233.79,233.91,5,200,1,1,233.78,234,200,17,2,2,233.77,234.1,97,100,1,1,233.76,234.13,106,400,1,1,233.7,234.17,1207,1,2,1,233.66,234.25,1,100,1,1,233.62,234.3,200,7,1,1,233.58,234.41,505,500,2,1,233.53,234.43,10,105,1,2,233.5,234.5,100,63,1,4,GOOG
2024-10-21T12:32:35.505299048Z,2024-10-21T12:32:35.505132160Z,10,2,38,C,B,1,233.78,100,130,166888,13495144,233.79,233.91,5,200,1,1,233.78,234,100,17,1,2,233.77,234.1,97,100,1,1,233.76,234.13,106,400,1,1,233.7,234.17,1207,1,2,1,233.66,234.25,1,100,1,1,233.62,234.3,200,7,1,1,233.58,234.41,505,500,2,1,233.53,234.43,10,105,1,2,233.5,234.5,100,63,1,4,GOOG
2024-10-21T12:32:35.505305381Z,2024-10-21T12:32:35.505139710Z,10,2,38,C,B,1,233.78,100,130,165671,13495145,233.79,233.91,5,200,1,1,233.77,234,97,17,1,2,233.76,234.1,106,100,1,1,233.7,234.13,1207,400,2,1,233.66,234.17,1,1,1,1,233.62,234.25,200,100,1,1,233.58,234.3,505,7,2,1,233.53,234.41,10,500,1,1,233.5,234.43,100,105,1,2,233.45,234.5,15,63,1,4,GOOG
2024-10-21T12:32:35.509239987Z,2024-10-21T12:32:35.509073618Z,10,2,38,C,B,2,233.76,106,130,166369,13495161,233.79,233.91,5,200,1,1,233.77,234,97,17,1,2,233.7,234.1,1207,100,2,1,233.66,234.13,1,400,1,1,233.62,234.17,200,1,1,1,233.58,234.25,505,100,2,1,233.53,234.3,10,7,1,1,233.5,234.41,100,500,1,1,233.45,234.43,15,105,1,2,233.4,234.5,110,63,2,4,GOOG
2024-10-21T12:32:35.605331832Z,2024-10-21T12:32:35.605165948Z,10,2,38,C,B,0,233.79,5,130,165884,13495731,233.77,233.91,97,200,1,1,233.7,234,1207,17,2,2,233.66,234.1,1,100,1,1,233.62,234.13,200,400,1,1,233.58,234.17,505,1,2,1,233.53,234.25,10,100,1,1,233.5,234.3,100,7,1,1,233.45,234.41,15,500,1,1,233.4,234.43,110,105,2,2,233.39,234.5,10,63,1,4,GOOG
2024-10-21T12:32:35.605360522Z,2024-10-21T12:32:35.605194517Z,10,2,38,C,B,0,233.77,97,130,166005,13495732,233.7,233.91,1207,200,2,1,233.66,234,1,17,1,2,233.62,234.1,200,100,1,1,233.58,234.13,505,400,2,1,233.53,234.17,10,1,1,1,233.5,234.25,100,100,1,1,233.45,234.3,15,7,1,1,233.4,234.41,110,500,2,1,233.39,234.43,10,105,1,2,233.31,234.5,110,63,2,4,GOOG
2024-10-21T12:32:37.670513856Z,2024-10-21T12:32:37.670347240Z,10,2,38,A,B,2,233.62,200,130,166616,13497731,233.7,233.91,1207,200,2,1,233.66,234,1,17,1,2,233.62,234.1,400,100,2,1,233.58,234.13,505,400,2,1,233.53,234.17,10,1,1,1,233.5,234.25,100,100,1,1,233.45,234.3,15,7,1,1,233.4,234.41,110,500,2,1,233.39,234.43,10,105,1,2,233.31,234.5,110,63,2,4,GOOG
2024-10-21T12:32:38.041507846Z,2024-10-21T12:32:38.041341719Z,10,2,38,A,A,0,233.91,200,130,166127,13498518,233.7,233.91,1207,400,2,2,233.66,234,1,17,1,2,233.62,234.1,400,100,2,1,233.58,234.13,505,400,2,1,233.53,234.17,10,1,1,1,233.5,234.25,100,100,1,1,233.45,234.3,15,7,1,1,233.4,234.41,110,500,2,1,233.39,234.43,10,105,1,2,233.31,234.5,110,63,2,4,GOOG
2024-10-21T12:32:38.101021570Z,2024-10-21T12:32:38.100855625Z,10,2,38,C,A,0,233.91,200,130,165945,13498654,233.7,233.91,1207,200,2,1,233.66,234,1,17,1,2,233.62,234.1,400,100,2,1,233.58,234.13,505,400,2,1,233.53,234.17,10,1,1,1,233.5,234.25,100,100,1,1,233.45,234.3,15,7,1,1,233.4,234.41,110,500,2,1,233.39,234.43,10,105,1,2,233.31,234.5,110,63,2,4,GOOG
2024-10-21T12:32:38.101034379Z,2024-10-21T12:32:38.100868142Z,10,2,38,A,A,0,233.9,400,130,166237,13498655,233.7,233.9,1207,400,2,1,233.66,234,1,17,1,2,233.62,234.1,400,100,2,1,233.58,234.13,505,400,2,1,233.53,234.17,10,1,1,1,233.5,234.25,100,100,1,1,233.45,234.3,15,7,1,1,233.4,234.41,110,500,2,1,233.39,234.43,10,105,1,2,233.31,234.5,110,63,2,4,GOOG
2024-10-21T12:32:48.253218217Z,2024-10-21T12:32:48.253052117Z,10,2,38,C,B,2,233.62,200,130,166100,13508734,233.7,233.9,1207,400,2,1,233.66,234,1,17,1,2,233.62,234.1,200,100,1,1,233.58,234.13,505,400,2,1,233.53,234.17,10,1,1,1,233.5,234.25,100,100,1,1,233.45,234.3,15,7,1,1,233.4,234.41,110,500,2,1,233.39,234.43,10,105,1,2,233.31,234.5,110,63,2,4,GOOG
2024-10-21T12:32:48.253229614Z,2024-10-21T12:32:48.253063227Z,10,2,38,C,B,2,233.62,200,130,166387,13508735,233.7,233.9,1207,400,2,1,233.66,234,1,17,1,2,233.58,234.1,505,100,2,1,233.53,234.13,10,400,1,1,233.5,234.17,100,1,1,1,233.45,234.25,15,100,1,1,233.4,234.3,110,7,2,1,233.39,234.41,10,500,1,1,233.31,234.43,110,105,2,2,233.3,234.5,100,63,1,4,GOOG
2024-10-21T12:32:48.253241560Z,2024-10-21T12:32:48.253074967Z,10,2,38,A,B,2,233.6,400,130,166593,13508736,233.7,233.9,1207,400,2,1,233.66,234,1,17,1,2,233.6,234.1,400,100,1,1,233.58,234.13,505,400,2,1,233.53,234.17,10,1,1,1,233.5,234.25,100,100,1,1,233.45,234.3,15,7,1,1,233.4,234.41,110,500,2,1,233.39,234.43,10,105,1,2,233.31,234.5,110,63,2,4,GOOG
2024-10-21T12:32:48.306887357Z,2024-10-21T12:32:48.306721177Z,10,2,38,A,A,0,233.89,400,130,166180,13508952,233.7,233.89,1207,400,2,1,233.66,234,1,17,1,2,233.6,234.1,400,100,1,1,233.58,234.13,505,400,2,1,233.53,234.17,10,1,1,1,233.5,234.25,100,100,1,1,233.45,234.3,15,7,1,1,233.4,234.41,110,500,2,1,233.39,234.43,10,105,1,2,233.31,234.5,110,63,2,4,GOOG
2024-10-21T12:32:55.953900894Z,2024-10-21T12:32:55.953734385Z,10,2,38,A,B,2,233.64,200,130,166509,13515293,233.7,233.89,1207,400,2,1,233.66,234,1,17,1,2,233.64,234.1,200,100,1,1,233.58,234.13,505,400,2,1,233.53,234.17,10,1,1,1,233.5,234.25,100,100,1,1,233.45,234.3,15,7,1,1,233.4,234.41,110,500,2,1,233.39,234.43,10,105,1,2,233.31,234.5,110,63,2,4,GOOG
2024-10-21T12:33:01.303381631Z,2024-10-21T12:33:01.303215240Z,10,2,38,A,A,0,233.84,5,130,166391,13521554,233.7,233.84,1207,5,2,1,233.66,233.89,1,400,1,1,233.64,234,200,17,1,2,233.58,234.1,505,100,2,1,233.53,234.13,10,400,1,1,233.5,234.17,100,1,1,1,233.45,234.25,15,100,1,1,233.4,234.3,110,7,2,1,233.39,234.41,10,500,1,1,233.31,234.43,110,105,2,2,GOOG
2024-10-21T12:33:05.793688776Z,2024-10-21T12:33:05.793522393Z,10,2,38,A,A,0,233.84,24,130,166383,13524828,233.7,233.84,1207,29,2,2,233.66,233.89,1,400,1,1,233.64,234,200,17,1,2,233.58,234.1,505,100,2,1,233.53,234.13,10,400,1,1,233.5,234.17,100,1,1,1,233.45,234.25,15,100,1,1,233.4,234.3,110,7,2,1,233.39,234.41,10,500,1,1,233.31,234.43,110,105,2,2,GOOG
2024-10-21T12:33:05.794673179Z,2024-10-21T12:33:05.794507041Z,10,2,38,C,A,7,234.3,7,130,166138,13524831,233.7,233.84,1207,29,2,2,233.66,233.89,1,400,1,1,233.64,234,200,17,1,2,233.58,234.1,505,100,2,1,233.53,234.13,10,400,1,1,233.5,234.17,100,1,1,1,233.45,234.25,15,100,1,1,233.4,234.41,110,500,2,1,233.39,234.43,10,105,1,2,233.31,234.5,110,63,2,4,GOOG
2024-10-21T12:33:06.321223237Z,2024-10-21T12:33:06.321056918Z,10,2,38,A,B,0,233.76,14,130,166319,13525485,233.76,233.84,14,29,1,2,233.7,233.89,1207,400,2,1,233.66,234,1,17,1,2,233.64,234.1,200,100,1,1,233.58,234.13,505,400,2,1,233.53,234.17,10,1,1,1,233.5,234.25,100,100,1,1,233.45,234.41,15,500,1,1,233.4,234.43,110,105,2,2,233.39,234.5,10,63,1,4,GOOG
2024-10-21T12:33:06.321248960Z,2024-10-21T12:33:06.321081410Z,10,2,38,A,B,0,233.78,36,130,167550,13525487,233.78,233.84,36,29,1,2,233.76,233.89,14,400,1,1,233.7,234,1207,17,2,2,233.66,234.1,1,100,1,1,233.64,234.13,200,400,1,1,233.58,234.17,505,1,2,1,233.53,234.25,10,100,1,1,233.5,234.41,100,500,1,1,233.45,234.43,15,105,1,2,233.4,234.5,110,63,2,4,GOOG
2024-10-21T12:33:06.321284693Z,2024-10-21T12:33:06.321117671Z,10,2,38,T,N,0,233.83,29,130,167022,13525492,233.78,233.84,36,29,1,2,233.76,233.89,14,400,1,1,233.7,234,1207,17,2,2,233.66,234.1,1,100,1,1,233.64,234.13,200,400,1,1,233.58,234.17,505,1,2,1,233.53,234.25,10,100,1,1,233.5,234.41,100,500,1,1,233.45,234.43,15,105,1,2,233.4,234.5,110,63,2,4,GOOG
2024-10-21T12:33:06.325317654Z,2024-10-21T12:33:06.325151716Z,10,2,38,C,B,1,233.76,14,130,165938,13525511,233.78,233.84,36,29,1,2,233.7,233.89,1207,400,2,1,233.66,234,1,17,1,2,233.64,234.1,200,100,1,1,233.58,234.13,505,400,2,1,233.53,234.17,10,1,1,1,233.5,234.25,100,100,1,1,233.45,234.41,15,500,1,1,233.4,234.43,110,105,2,2,233.39,234.5,10,63,1,4,GOOG
2024-10-21T12:33:06.325353396Z,2024-10-21T12:33:06.325187400Z,10,2,38,C,B,0,233.78,36,130,165996,13525512,233.7,233.84,1207,29,2,2,233.66,233.89,1,400,1,1,233.64,234,200,17,1,2,233.58,234.1,505,100,2,1,233.53,234.13,10,400,1,1,233.5,234.17,100,1,1,1,233.45,234.25,15,100,1,1,233.4,234.41,110,500,2,1,233.39,234.43,10,105,1,2,233.31,234.5,110,63,2,4,GOOG
2024-10-21T12:33:07.427792991Z,2024-10-21T12:33:07.427626768Z,10,2,38,C,A,0,233.84,24,130,166223,13527091,233.7,233.84,1207,5,2,1,233.66,233.89,1,400,1,1,233.64,234,200,17,1,2,233.58,234.1,505,100,2,1,233.53,234.13,10,400,1,1,233.5,234.17,100,1,1,1,233.45,234.25,15,100,1,1,233.4,234.41,110,500,2,1,233.39,234.43,10,105,1,2,233.31,234.5,110,63,2,4,GOOG
2024-10-21T12:33:07.802046100Z,2024-10-21T12:33:07.801879861Z,10,2,38,A,A,7,234.31,7,130,166239,13527410,233.7,233.84,1207,5,2,1,233.66,233.89,1,400,1,1,233.64,234,200,17,1,2,233.58,234.1,505,100,2,1,233.53,234.13,10,400,1,1,233.5,234.17,100,1,1,1,233.45,234.25,15,100,1,1,233.4,234.31,110,7,2,1,233.39,234.41,10,500,1,1,233.31,234.43,110,105,2,2,GOOG
2024-10-21T12:33:09.053411027Z,2024-10-21T12:33:09.053244732Z,10,2,38,A,A,0,233.82,24,130,166295,13528078,233.7,233.82,1207,24,2,1,233.66,233.84,1,5,1,1,233.64,233.89,200,400,1,1,233.58,234,505,17,2,2,233.53,234.1,10,100,1,1,233.5,234.13,100,400,1,1,233.45,234.17,15,1,1,1,233.4,234.25,110,100,2,1,233.39,234.31,10,7,1,1,233.31,234.41,110,500,2,1,GOOG
2024-10-21T12:33:09.156419715Z,2024-10-21T12:33:09.156252110Z,10,2,38,T,B,0,233.82,1,130,167605,13528171,233.7,233.82,1207,24,2,1,233.66,233.84,1,5,1,1,233.64,233.89,200,400,1,1,233.58,234,505,17,2,2,233.53,234.1,10,100,1,1,233.5,234.13,100,400,1,1,233.45,234.17,15,1,1,1,233.4,234.25,110,100,2,1,233.39,234.31,10,7,1,1,233.31,234.41,110,500,2,1,GOOG
2024-10-21T12:33:09.156419715Z,2024-10-21T12:33:09.156252110Z,10,2,38,C,A,0,233.82,1,130,167605,13528171,233.7,233.82,1207,23,2,1,233.66,233.84,1,5,1,1,233.64,233.89,200,400,1,1,233.58,234,505,17,2,2,233.53,234.1,10,100,1,1,233.5,234.13,100,400,1,1,233.45,234.17,15,1,1,1,233.4,234.25,110,100,2,1,233.39,234.31,10,7,1,1,233.31,234.41,110,500,2,1,GOOG
2024-10-21T12:33:12.169911606Z,2024-10-21T12:33:12.169745303Z,10,2,38,C,A,8,234.31,7,130,166303,13529825,233.7,233.82,1207,23,2,1,233.66,233.84,1,5,1,1,233.64,233.89,200,400,1,1,233.58,234,505,17,2,2,233.53,234.1,10,100,1,1,233.5,234.13,100,400,1,1,233.45,234.17,15,1,1,1,233.4,234.25,110,100,2,1,233.39,234.41,10,500,1,1,233.31,234.43,110,105,2,2,GOOG
2024-10-21T12:33:14.175390219Z,2024-10-21T12:33:14.175223557Z,10,2,38,A,A,8,234.3,7,130,166662,13530741,233.7,233.82,1207,23,2,1,233.66,233.84,1,5,1,1,233.64,233.89,200,400,1,1,233.58,234,505,17,2,2,233.53,234.1,10,100,1,1,233.5,234.13,100,400,1,1,233.45,234.17,15,1,1,1,233.4,234.25,110,100,2,1,233.39,234.3,10,7,1,1,233.31,234.41,110,500,2,1,GOOG
2024-10-21T12:33:14.283718557Z,2024-10-21T12:33:14.283552259Z,10,2,38,C,A,1,233.84,5,130,166298,13530784,233.7,233.82,1207,23,2,1,233.66,233.89,1,400,1,1,233.64,234,200,17,1,2,233.58,234.1,505,100,2,1,233.53,234.13,10,400,1,1,233.5,234.17,100,1,1,1,233.45,234.25,15,100,1,1,233.4,234.3,110,7,2,1,233.39,234.41,10,500,1,1,233.31,234.43,110,105,2,2,GOOG
2024-10-21T12:33:15.381676312Z,2024-10-21T12:33:15.381509806Z,10,2,38,C,A,1,233.89,200,130,166506,13531808,233.7,233.82,1207,23,2,1,233.66,233.89,1,200,1,1,233.64,234,200,17,1,2,233.58,234.1,505,100,2,1,233.53,234.13,10,400,1,1,233.5,234.17,100,1,1,1,233.45,234.25,15,100,1,1,233.4,234.3,110,7,2,1,233.39,234.41,10,500,1,1,233.31,234.43,110,105,2,2,GOOG
2024-10-21T12:33:15.434778176Z,2024-10-21T12:33:15.434611774Z,10,2,38,A,B,2,233.65,200,130,166402,13531917,233.7,233.82,1207,23,2,1,233.66,233.89,1,200,1,1,233.65,234,200,17,1,2,233.58,234.1,505,100,2,1,233.53,234.13,10,400,1,1,233.5,234.17,100,1,1,1,233.45,234.25,15,100,1,1,233.4,234.3,110,7,2,1,233.39,234.41,10,500,1,1,233.31,234.43,110,105,2,2,GOOG
2024-10-21T12:33:21.206742513Z,2024-10-21T12:33:21.206576211Z,10,2,38,A,A,1,233.85,32,130,166302,13537508,233.7,233.82,1207,23,2,1,233.66,233.85,1,32,1,1,233.65,233.89,200,200,1,1,233.58,234,505,17,2,2,233.53,234.1,10,100,1,1,233.5,234.13,100,400,1,1,233.45,234.17,15,1,1,1,233.4,234.25,110,100,2,1,233.39,234.3,10,7,1,1,233.31,234.41,110,500,2,1,GOOG
2024-10-21T12:33:21.206778516Z,2024-10-21T12:33:21.206611882Z,10,2,38,C,B,2,233.65,200,130,166634,13537509,233.7,233.82,1207,23,2,1,233.66,233.85,1,32,1,1,233.58,233.89,505,200,2,1,233.53,234,10,17,1,2,233.5,234.1,100,100,1,1,233.45,234.13,15,400,1,1,233.4,234.17,110,1,2,1,233.39,234.25,10,100,1,1,233.31,234.3,110,7,2,1,233.3,234.41,100,500,1,1,GOOG
2024-10-21T12:33:21.210847558Z,2024-10-21T12:33:21.210681542Z,10,2,38,C,A,1,233.85,32,130,166016,13537514,233.7,233.82,1207,23,2,1,233.66,233.89,1,200,1,1,233.58,234,505,17,2,2,233.53,234.1,10,100,1,1,233.5,234.13,100,400,1,1,233.45,234.17,15,1,1,1,233.4,234.25,110,100,2,1,233.39,234.3,10,7,1,1,233.31,234.41,110,500,2,1,233.3,234.43,100,105,1,2,GOOG
2024-10-21T12:33:21.285416313Z,2024-10-21T12:33:21.285249933Z,10,2,38,A,B,2,233.6,400,130,166380,13537538,233.7,233.82,1207,23,2,1,233.66,233.89,1,200,1,1,233.6,234,400,17,1,2,233.58,234.1,505,100,2,1,233.53,234.13,10,400,1,1,233.5,234.17,100,1,1,1,233.45,234.25,15,100,1,1,233.4,234.3,110,7,2,1,233.39,234.41,10,500,1,1,233.31,234.43,110,105,2,2,GOOG
2024-10-21T12:33:22.875172209Z,2024-10-21T12:33:22.875006113Z,10,2,38,C,A,7,234.3,7,130,166096,13538739,233.7,233.82,1207,23,2,1,233.66,233.89,1,200,1,1,233.6,234,400,17,1,2,233.58,234.1,505,100,2,1,233.53,234.13,10,400,1,1,233.5,234.17,100,1,1,1,233.45,234.25,15,100,1,1,233.4,234.41,110,500,2,1,233.39,234.43,10,105,1,2,233.31,234.5,110,63,2,4,GOOG
2024-10-21T12:33:24.340914552Z,2024-10-21T12:33:24.340747933Z,10,2,38,A,B,2,233.64,200,130,166619,13539543,233.7,233.82,1207,23,2,1,233.66,233.89,1,200,1,1,233.64,234,200,17,1,2,233.58,234.1,505,100,2,1,233.53,234.13,10,400,1,1,233.5,234.17,100,1,1,1,233.45,234.25,15,100,1,1,233.4,234.41,110,500,2,1,233.39,234.43,10,105,1,2,233.31,234.5,110,63,2,4,GOOG
2024-10-21T12:33:24.880971677Z,2024-10-21T12:33:24.880805430Z,10,2,38,A,A,2,233.98,7,130,166247,13539855,233.7,233.82,1207,23,2,1,233.66,233.89,1,200,1,1,233.64,233.98,200,7,1,1,233.58,234,505,17,2,2,233.53,234.1,10,100,1,1,233.5,234.13,100,400,1,1,233.45,234.17,15,1,1,1,233.4,234.25,110,100,2,1,233.39,234.41,10,500,1,1,233.31,234.43,110,105,2,2,GOOG
2024-10-21T12:33:26.285588783Z,2024-10-21T12:33:26.285422898Z,10,2,38,C,B,2,233.64,200,130,165885,13540562,233.7,233.82,1207,23,2,1,233.66,233.89,1,200,1,1,233.58,233.98,505,7,2,1,233.53,234,10,17,1,2,233.5,234.1,100,100,1,1,233.45,234.13,15,400,1,1,233.4,234.17,110,1,2,1,233.39,234.25,10,100,1,1,233.31,234.41,110,500,2,1,233.3,234.43,100,105,1,2,GOOG
2024-10-21T12:33:26.285601335Z,2024-10-21T12:33:26.285434922Z,10,2,38,A,B,2,233.6,400,130,166413,13540563,233.7,233.82,1207,23,2,1,233.66,233.89,1,200,1,1,233.6,233.98,400,7,1,1,233.58,234,505,17,2,2,233.53,234.1,10,100,1,1,233.5,234.13,100,400,1,1,233.45,234.17,15,1,1,1,233.4,234.25,110,100,2,1,233.39,234.41,10,500,1,1,233.31,234.43,110,105,2,2,GOOG
2024-10-21T12:33:26.288683656Z,2024-10-21T12:33:26.288517312Z,10,2,38,A,A,1,233.89,200,130,166344,13540564,233.7,233.82,1207,23,2,1,233.66,233.89,1,400,1,2,233.6,233.98,400,7,1,1,233.58,234,505,17,2,2,233.53,234.1,10,100,1,1,233.5,234.13,100,400,1,1,233.45,234.17,15,1,1,1,233.4,234.25,110,100,2,1,233.39,234.41,10,500,1,1,233.31,234.43,110,105,2,2,GOOG
2024-10-21T12:33:28.839787314Z,2024-10-21T12:33:28.839620575Z,10,2,38,C,A,1,233.89,200,130,166739,13542107,233.7,233.82,1207,23,2,1,233.66,233.89,1,200,1,1,233.6,233.98,400,7,1,1,233.58,234,505,17,2,2,233.53,234.1,10,100,1,1,233.5,234.13,100,400,1,1,233.45,234.17,15,1,1,1,233.4,234.25,110,100,2,1,233.39,234.41,10,500,1,1,233.31,234.43,110,105,2,2,GOOG
2024-10-21T12:33:28.839800219Z,2024-10-21T12:33:28.839633521Z,10,2,38,A,A,1,233.88,400,130,166698,13542108,233.7,233.82,1207,23,2,1,233.66,233.88,1,400,1,1,233.6,233.98,400,7,1,1,233.58,234,505,17,2,2,233.53,234.1,10,100,1,1,233.5,234.13,100,400,1,1,233.45,234.17,15,1,1,1,233.4,234.25,110,100,2,1,233.39,234.41,10,500,1,1,233.31,234.43,110,105,2,2,GOOG
2024-10-21T12:33:29.340318637Z,2024-10-21T12:33:29.340151844Z,10,2,38,A,B,2,233.63,200,130,166793,13542527,233.7,233.82,1207,23,2,1,233.66,233.88,1,400,1,1,233.63,233.98,200,7,1,1,233.58,234,505,17,2,2,233.53,234.1,10,100,1,1,233.5,234.13,100,400,1,1,233.45,234.17,15,1,1,1,233.4,234.25,110,100,2,1,233.39,234.41,10,500,1,1,233.31,234.43,110,105,2,2,GOOG
2024-10-21T12:33:36.906685078Z,2024-10-21T12:33:36.906518675Z,10,2,38,C,A,1,233.88,200,130,166403,13547756,233.7,233.82,1207,23,2,1,233.66,233.88,1,200,1,1,233.63,233.98,200,7,1,1,233.58,234,505,17,2,2,233.53,234.1,10,100,1,1,233.5,234.13,100,400,1,1,233.45,234.17,15,1,1,1,233.4,234.25,110,100,2,1,233.39,234.41,10,500,1,1,233.31,234.43,110,105,2,2,GOOG
2024-10-21T12:33:39.988199552Z,2024-10-21T12:33:39.988033229Z,10,2,38,A,B,0,233.75,5,130,166323,13550081,233.75,233.82,5,23,1,1,233.7,233.88,1207,200,2,1,233.66,233.98,1,7,1,1,233.63,234,200,17,1,2,233.58,234.1,505,100,2,1,233.53,234.13,10,400,1,1,233.5,234.17,100,1,1,1,233.45,234.25,15,100,1,1,233.4,234.41,110,500,2,1,233.39,234.43,10,105,1,2,GOOG
2024-10-21T12:33:41.899400277Z,2024-10-21T12:33:41.899233441Z,10,2,38,A,B,3,233.64,200,130,166836,13551266,233.75,233.82,5,23,1,1,233.7,233.88,1207,200,2,1,233.66,233.98,1,7,1,1,233.64,234,200,17,1,2,233.58,234.1,505,100,2,1,233.53,234.13,10,400,1,1,233.5,234.17,100,1,1,1,233.45,234.25,15,100,1,1,233.4,234.41,110,500,2,1,233.39,234.43,10,105,1,2,GOOG
2024-10-21T12:33:48.686750573Z,2024-10-21T12:33:48.686584626Z,10,2,38,A,B,0,233.77,100,130,165947,13557698,233.77,233.82,100,23,1,1,233.75,233.88,5,200,1,1,233.7,233.98,1207,7,2,1,233.66,234,1,17,1,2,233.64,234.1,200,100,1,1,233.58,234.13,505,400,2,1,233.53,234.17,10,1,1,1,233.5,234.25,100,100,1,1,233.45,234.41,15,500,1,1,233.4,234.43,110,105,2,2,GOOG
2024-10-21T12:33:48.686812699Z,2024-10-21T12:33:48.686646314Z,10,2,38,A,B,0,233.77,15,130,166385,13557700,233.77,233.82,115,23,2,1,233.75,233.88,5,200,1,1,233.7,233.98,1207,7,2,1,233.66,234,1,17,1,2,233.64,234.1,200,100,1,1,233.58,234.13,505,400,2,1,233.53,234.17,10,1,1,1,233.5,234.25,100,100,1,1,233.45,234.41,15,500,1,1,233.4,234.43,110,105,2,2,GOOG
2024-10-21T12:33:48.687169772Z,2024-10-21T12:33:48.687003945Z,10,2,38,C,B,0,233.77,100,130,165827,13557702,233.77,233.82,15,23,1,1,233.75,233.88,5,200,1,1,233.7,233.98,1207,7,2,1,233.66,234,1,17,1,2,233.64,234.1,200,100,1,1,233.58,234.13,505,400,2,1,233.53,234.17,10,1,1,1,233.5,234.25,100,100,1,1,233.45,234.41,15,500,1,1,233.4,234.43,110,105,2,2,GOOG
2024-10-21T12:33:48.690916965Z,2024-10-21T12:33:48.690751022Z,10,2,38,C,B,0,233.77,15,130,165943,13557706,233.75,233.82,5,23,1,1,233.7,233.88,1207,200,2,1,233.66,233.98,1,7,1,1,233.64,234,200,17,1,2,233.58,234.1,505,100,2,1,233.53,234.13,10,400,1,1,233.5,234.17,100,1,1,1,233.45,234.25,15,100,1,1,233.4,234.41,110,500,2,1,233.39,234.43,10,105,1,2,GOOG
2024-10-21T12:33:49.477347127Z,2024-10-21T12:33:49.477179785Z,10,2,38,T,B,0,233.82,2,130,167342,13558736,233.75,233.82,5,23,1,1,233.7,233.88,1207,200,2,1,233.66,233.98,1,7,1,1,233.64,234,200,17,1,2,233.58,234.1,505,100,2,1,233.53,234.13,10,400,1,1,233.5,234.17,100,1,1,1,233.45,234.25,15,100,1,1,233.4,234.41,110,500,2,1,233.39,234.43,10,105,1,2,GOOG
2024-10-21T12:33:49.477347127Z,2024-10-21T12:33:49.477179785Z,10,2,38,C,A,0,233.82,2,130,167342,13558736,233.75,233.82,5,21,1,1,233.7,233.88,1207,200,2,1,233.66,233.98,1,7,1,1,233.64,234,200,17,1,2,233.58,234.1,505,100,2,1,233.53,234.13,10,400,1,1,233.5,234.17,100,1,1,1,233.45,234.25,15,100,1,1,233.4,234.41,110,500,2,1,233.39,234.43,10,105,1,2,GOOG
2024-10-21T12:33:49.544998118Z,2024-10-21T12:33:49.544831228Z,10,2,38,A,B,3,233.64,200,130,166890,13558796,233.75,233.82,5,21,1,1,233.7,233.88,1207,200,2,1,233.66,233.98,1,7,1,1,233.64,234,400,17,2,2,233.58,234.1,505,100,2,1,233.53,234.13,10,400,1,1,233.5,234.17,100,1,1,1,233.45,234.25,15,100,1,1,233.4,234.41,110,500,2,1,233.39,234.43,10,105,1,2,GOOG
2024-10-21T12:33:49.545096502Z,2024-10-21T12:33:49.544930382Z,10,2,38,C,A,1,233.88,200,130,166120,13558797,233.75,233.82,5,21,1,1,233.7,233.98,1207,7,2,1,233.66,234,1,17,1,2,233.64,234.1,400,100,2,1,233.58,234.13,505,400,2,1,233.53,234.17,10,1,1,1,233.5,234.25,100,100,1,1,233.45,234.41,15,500,1,1,233.4,234.43,110,105,2,2,233.39,234.5,10,63,1,4,GOOG
2024-10-21T12:33:49.545108513Z,2024-10-21T12:33:49.544942069Z,10,2,38,A,A,1,233.94,400,130,166444,13558798,233.75,233.82,5,21,1,1,233.7,233.94,1207,400,2,1,233.66,233.98,1,7,1,1,233.64,234,400,17,2,2,233.58,234.1,505,100,2,1,233.53,234.13,10,400,1,1,233.5,234.17,100,1,1,1,233.45,234.25,15,100,1,1,233.4,234.41,110,500,2,1,233.39,234.43,10,105,1,2,GOOG
